Workbook
Name CEUmbria: #REF!
Name Inizio_progetto: #REF!
Name prevWBS: 'Project Plan'!$A1048576
Name Visualizza_settimana: #REF!

Sheet Riepilogo Contratto
B2: Pianificato | D2: IV TRIM 2023 | E2: 2024 | F2: I SEM 2025 | H2: TOTALE PIANIFICATO | J2: TOTALE PdF
B4: Servizi Applicativi | D4: =SUM(D5,D6:D7) -> #REF! | E4: =SUM(E5,E6:E7) -> #REF! | F4: =SUM(F5,F6:F7) -> #REF! | H4: =SUM(H5,H6:H7) -> #REF!
B5: Sviluppo Software gg/persona | D5: =SUMIF(Gantt!#REF!,"Sviluppo software",Gantt!#REF!) -> #REF! | E5: =SUMIF(Gantt!#REF!,"Sviluppo software",Gantt!#REF!) -> #REF! | F5: =SUMIF(Gantt!#REF!,"Sviluppo software",Gantt!#REF!) -> #REF! | H5: =SUM(D5:F5) -> #REF! | J5: 360008
B6: MEV/MAD | D6: =SUMIF(Gantt!#REF!,"MEV",Gantt!#REF!) -> #REF! | E6: =SUMIF(Gantt!#REF!,"MEV",Gantt!#REF!) -> #REF! | F6: =SUMIF(Gantt!#REF!,"MEV",Gantt!#REF!) -> #REF! | H6: =SUM(D6:F6) -> #REF! | J6: 489486
B7: Conduzione Applicativa | D7: =SUMIF(Gantt!#REF!,"Conduzione Applicativa(Consumo)",Gantt!#REF!) -> #REF! | E7: =SUMIF(Gantt!#REF!,"Conduzione Applicativa(Consumo)",Gantt!#REF!) -> #REF! | F7: =SUMIF(Gantt!#REF!,"Conduzione Applicativa(Consumo)",Gantt!#REF!) -> #REF! | H7: =SUM(D7:F7) -> #REF! | J7: =887592-236881.5 -> 650710.5
B8: Supporto Specialistico Applicativo | D8: =SUMIF(Gantt!#REF!,"Supp. Spec. App. (Consumo)",Gantt!#REF!) -> #REF! | E8: =SUMIF(Gantt!#REF!,"Supp. Spec. App. (Consumo)",Gantt!#REF!) -> #REF! | F8: =SUMIF(Gantt!#REF!,"Supp. Spec. App. (Consumo)",Gantt!#REF!) -> #REF! | H8: =SUM(D8:F8) -> #REF! | J8: 91094
B9: Servizi di Call Center | D9: =SUMIF(Gantt!#REF!,"Servizi Desk(Canone)",Gantt!#REF!) -> #REF! | E9: =SUMIF(Gantt!#REF!,"Servizi Desk(Canone)",Gantt!#REF!) -> #REF! | F9: =SUMIF(Gantt!#REF!,"Servizi Desk(Canone)",Gantt!#REF!) -> #REF! | H9: =SUM(D9:F9) -> #REF! | J9: 84997.5
B11: Totale Pianificato | D11: =D4+D8+D9 -> #REF! | E11: =E4+E8+E9 -> #REF! | F11: =F4+F8+F9 -> #REF! | H11: =SUM(D11:F11) -> #REF! | J11: =SUM(J5:J9) -> 1676296
J12: =H13-H11 -> #REF! | K12: Residuo da Pianificare
B13: TOTALI DA PDF | D13: 484872 | E13: 788379 | F13: 403045 | H13: =SUM(D13:F13) -> 1676296
B17: PdF
B18: Sviluppo | D18: 180000 | E18: 150012 | F18: 29996 | H18: =SUM(D18:F18) -> 360008 | J18: =H18-H5 -> #REF!
B19: MEV | D19: 200000 | E19: 209997 | F19: 79489 | H19: =SUM(D19:F19) -> 489486 | J19: =H19-H6 -> #REF!
B20: Conduzione Applicativa | D20: 104872 | E20: 350452 | F20: 220268 | H20: =SUM(D20:F20) -> 675592 | J20: =H20-H7 -> #REF!
B21: Assistenza spec | D21: 0 | E21: 42918 | F21: 38292 | H21: =SUM(D21:F21) -> 81210 | J21: =H21-H8 -> #REF!
B22: Call center | D22: 0 | E22: 35000 | F22: 35000 | H22: =SUM(D22:F22) -> 70000 | J22: =H22-H9 -> #REF!
D24: =SUM(D18:D22) -> 484872 | E24: =SUM(E18:E22) -> 788379 | F24: =SUM(F18:F22) -> 403045 | H24: =SUM(D24:F24) -> 1676296
D27: IV TRIM 2023 | E27: I TRIM 2024 | F27: II TRIM 2024 | G27: III TRIM 2024 | H27: IV TRIM 2024 | I27: I TRIM 2025 | J27: II TRIM 2025
B29: Servizi Applicativi | D29: =SUM(D30,D31:D32) -> #REF! | E29: =SUM(E30,E31:E32) -> #REF! | F29: =SUM(F30,F31:F32) -> #REF! | G29: =SUM(G30,G31:G32) -> #REF! | H29: =SUM(H30,H31:H32) -> #REF! | I29: =SUM(I30,I31:I32) -> #REF! | J29: =SUM(J30,J31:J32) -> #REF!
B30: Sviluppo Software gg/persona | D30: =SUMIFS(Gantt!#REF!,Gantt!#REF!,"Sviluppo software",Gantt!#REF!,"IV TRIMESTRE 2023") -> #REF! | E30: =SUMIFS(Gantt!#REF!,Gantt!#REF!,"Sviluppo software",Gantt!#REF!,"I TRIMESTRE 2024") -> #REF! | F30: =SUMIFS(Gantt!#REF!,Gantt!#REF!,"Sviluppo software",Gantt!#REF!,"II TRIMESTRE 2024") -> #REF! | G30: =SUMIFS(Gantt!#REF!,Gantt!#REF!,"Sviluppo software",Gantt!#REF!,"III TRIMESTRE 2024") -> #REF! | H30: =SUMIFS(Gantt!#REF!,Gantt!#REF!,"Sviluppo software",Gantt!#REF!,"IV TRIMESTRE 2024") -> #REF! | I30: =SUMIFS(Gantt!#REF!,Gantt!#REF!,"Sviluppo software",Gantt!#REF!,"I TRIMESTRE 2025") -> #REF! | J30: =SUMIFS(Gantt!#REF!,Gantt!#REF!,"Sviluppo software",Gantt!#REF!,"II TRIMESTRE 2025") -> #REF!
B31: MEV/MAD | D31: =SUMIFS(Gantt!#REF!,Gantt!#REF!,"MEV",Gantt!#REF!,"IV TRIMESTRE 2023") -> #REF! | E31: =SUMIFS(Gantt!#REF!,Gantt!#REF!,"MEV",Gantt!#REF!,"I TRIMESTRE 2024") -> #REF! | F31: =SUMIFS(Gantt!#REF!,Gantt!#REF!,"MEV",Gantt!#REF!,"II TRIMESTRE 2024") -> #REF! | G31: =SUMIFS(Gantt!#REF!,Gantt!#REF!,"MEV",Gantt!#REF!,"III TRIMESTRE 2024") -> #REF! | H31: =SUMIFS(Gantt!#REF!,Gantt!#REF!,"MEV",Gantt!#REF!,"IV TRIMESTRE 2024") -> #REF! | I31: =SUMIFS(Gantt!#REF!,Gantt!#REF!,"MEV",Gantt!#REF!,"I TRIMESTRE 2025") -> #REF! | J31: =SUMIFS(Gantt!#REF!,Gantt!#REF!,"MEV",Gantt!#REF!,"II TRIMESTRE 2025") -> #REF!
B32: Conduzione Applicativa | D32: =SUMIFS(Gantt!#REF!,Gantt!#REF!,"Conduzione applicativa(consumo)",Gantt!#REF!,"2023") -> #REF! | E32: =SUMIFS(Gantt!#REF!,Gantt!#REF!,"Conduzione applicativa(consumo)",Gantt!#REF!,"I TRIMESTRE 2024") -> #REF! | F32: =SUMIFS(Gantt!#REF!,Gantt!#REF!,"Conduzione applicativa(consumo)",Gantt!#REF!,"II TRIMESTRE 2024") -> #REF! | G32: =SUMIFS(Gantt!#REF!,Gantt!#REF!,"Conduzione applicativa(consumo)",Gantt!#REF!,"III TRIMESTRE 2024") -> #REF! | H32: =SUMIFS(Gantt!#REF!,Gantt!#REF!,"Conduzione applicativa(consumo)",Gantt!#REF!,"IV TRIMESTRE 2024") -> #REF! | I32: =SUMIFS(Gantt!#REF!,Gantt!#REF!,"Conduzione applicativa(consumo)",Gantt!#REF!,"I TRIMESTRE 2025") -> #REF! | J32: =SUMIFS(Gantt!#REF!,Gantt!#REF!,"Conduzione applicativa(consumo)",Gantt!#REF!,"II TRIMESTRE 2025") -> #REF!
B33: Supporto specialistico Applicativo | D33: =SUMIFS(Gantt!#REF!,Gantt!#REF!,"Supp. Spec. App. (Consumo)",Gantt!#REF!,"2023") -> #REF! | E33: =SUMIFS(Gantt!#REF!,Gantt!#REF!,"Supp. Spec. App. (Consumo)",Gantt!#REF!,"I TRIMESTRE 2024") -> #REF! | F33: =SUMIFS(Gantt!#REF!,Gantt!#REF!,"Supp. Spec. App. (Consumo)",Gantt!#REF!,"II TRIMESTRE 2024") -> #REF! | G33: =SUMIFS(Gantt!#REF!,Gantt!#REF!,"Supp. Spec. App. (Consumo)",Gantt!#REF!,"III TRIMESTRE 2024") -> #REF! | H33: =SUMIFS(Gantt!#REF!,Gantt!#REF!,"Supp. Spec. App. (Consumo)",Gantt!#REF!,"IV TRIMESTRE 2024") -> #REF! | I33: =SUMIFS(Gantt!#REF!,Gantt!#REF!,"Supp. Spec. App. (Consumo)",Gantt!#REF!,"I TRIMESTRE 2025") -> #REF! | J33: =SUMIFS(Gantt!#REF!,Gantt!#REF!,"Supp. Spec. App. (Consumo)",Gantt!#REF!,"II TRIMESTRE 2025") -> #REF!
B34: Servizi di Call Center | D34: =SUMIFS(Gantt!#REF!,Gantt!#REF!,"Servizi Desk(Canone)",Gantt!#REF!,"IV TRIMESTRE 2023") -> #REF! | E34: =SUMIFS(Gantt!#REF!,Gantt!#REF!,"Servizi Desk(Canone)",Gantt!#REF!,"I TRIMESTRE 2024") -> #REF! | F34: =SUMIFS(Gantt!#REF!,Gantt!#REF!,"Servizi Desk(Canone)",Gantt!#REF!,"II TRIMESTRE 2024") -> #REF! | G34: =SUMIFS(Gantt!#REF!,Gantt!#REF!,"Servizi Desk(Canone)",Gantt!#REF!,"III TRIMESTRE 2024") -> #REF! | H34: =SUMIFS(Gantt!#REF!,Gantt!#REF!,"Servizi Desk(Canone)",Gantt!#REF!,"IV TRIMESTRE 2024") -> #REF! | I34: =SUMIFS(Gantt!#REF!,Gantt!#REF!,"Servizi Desk(Canone)",Gantt!#REF!,"I TRIMESTRE 2025") -> #REF! | J34: =SUMIFS(Gantt!#REF!,Gantt!#REF!,"Servizi Desk(Canone)",Gantt!#REF!,"II TRIMESTRE 2025") -> #REF!
B36: Totale Collaudato | D36: =D29+D33+D34 -> #REF! | E36: =E29+E33+E34 -> #REF! | F36: =F29+F33+F34 -> #REF! | G36: =G29+G33+G34 -> #REF! | H36: =H29+H33+H34 -> #REF! | I36: =I29+I33+I34 -> #REF! | J36: =J29+J33+J34 -> #REF! | K36: TOTALE | L36: =SUM(D36:J36) -> #REF!

Sheet Project Plan
A1: Regione Umbria - GARI | K1: Gantt Chart Template © 2006-2018 by Vertex42.com.
B4: Data Inizio Progetto | C4: 45231 | G4: Display Week | H4: 54 | K4: ="Week "&(K6-($C$4-WEEKDAY($C$4,1)+2))/7+1 -> Week 54 | R4: ="Week "&(R6-($C$4-WEEKDAY($C$4,1)+2))/7+1 -> Week 55 | Y4: ="Week "&(Y6-($C$4-WEEKDAY($C$4,1)+2))/7+1 -> Week 56 | AF4: ="Week "&(AF6-($C$4-WEEKDAY($C$4,1)+2))/7+1 -> Week 57 | AM4: ="Week "&(AM6-($C$4-WEEKDAY($C$4,1)+2))/7+1 -> Week 58 | AT4: ="Week "&(AT6-($C$4-WEEKDAY($C$4,1)+2))/7+1 -> Week 59 | BA4: ="Week "&(BA6-($C$4-WEEKDAY($C$4,1)+2))/7+1 -> Week 60 | BH4: ="Week "&(BH6-($C$4-WEEKDAY($C$4,1)+2))/7+1 -> Week 61 | BO4: ="Week "&(BO6-($C$4-WEEKDAY($C$4,1)+2))/7+1 -> Week 62
B5: Project Lead | K5: =K6 -> 45600 | R5: =R6 -> 45607 | Y5: =Y6 -> 45614 | AF5: =AF6 -> 45621 | AM5: =AM6 -> 45628 | AT5: =AT6 -> 45635 | BA5: =BA6 -> 45642 | BH5: =BH6 -> 45649 | BO5: =BO6 -> 45656
K6: =C4-WEEKDAY(C4,1)+2+7*(H4-1) -> 45600 | L6: =K6+1 -> 45601 | M6: =L6+1 -> 45602 | N6: =M6+1 -> 45603 | O6: =N6+1 -> 45604 | P6: =O6+1 -> 45605 | Q6: =P6+1 -> 45606 | R6: =Q6+1 -> 45607 | S6: =R6+1 -> 45608 | ... BU6: =BT6+1 -> 45662
A7: WBS | B7: TASK | C7: LEAD | D7: PREDECESSORI | E7: INIZIO | F7: FINE | G7: Durata gg | H7: % COMPLETAMENTO | I7: GIORNI Lavorativi | K7: =CHOOSE(WEEKDAY(K6,1),"S","M","T","W","T","F","S") -> M | L7: =CHOOSE(WEEKDAY(L6,1),"S","M","T","W","T","F","S") -> T | M7: =CHOOSE(WEEKDAY(M6,1),"S","M","T","W","T","F","S") -> W | N7: =CHOOSE(WEEKDAY(N6,1),"S","M","T","W","T","F","S") -> T | O7: =CHOOSE(WEEKDAY(O6,1),"S","M","T","W","T","F","S") -> F | P7: =CHOOSE(WEEKDAY(P6,1),"S","M","T","W","T","F","S") -> S | Q7: =CHOOSE(WEEKDAY(Q6,1),"S","M","T","W","T","F","S") -> S | R7: =CHOOSE(WEEKDAY(R6,1),"S","M","T","W","T","F","S") -> M | ... BU7: =CHOOSE(WEEKDAY(BU6,1),"S","M","T","W","T","F","S") -> S
A8: =IF(ISERROR(VALUE(SUBSTITUTE(prevWBS,".",""))),"1",IF(ISERROR(FIND("`",SUBSTITUTE(prevWBS,".","`",1))),TEXT(VALUE(prevWBS)+1,"#"),TEXT(VALUE(LEFT(prevWBS,FIND("`",SUBSTITUTE(prevWBS,".","`",1))-1))+1,"#"))) -> 1 | B8: =Gantt!C9 -> SERVIZI APPLICATIVI - ATTIVITA' DI CARATTERE PROGETTUALE (Sviluppo SW + MEV+Supporto Specialistico Operativo) | F8: =IF(ISBLANK(E8)," - ",IF(G8=0,E8,E8+G8-1)) -> - | I8: =IF(OR(F8=0,E8=0)," - ",NETWORKDAYS(E8,F8)) -> -
A9: =Gantt!A10 -> 0 | B9: =Gantt!C10 -> MEV GARI-PA per porting (IV TRIM 23) su nuovo ambiente di tutti i moduli (BASE, PUA, QDCA, UMA) | E9: =Gantt!#REF! -> #REF! | F9: =Gantt!#REF! -> #REF! | G9: =F9-E9 -> #REF! | H9: =Gantt!#REF! -> #REF! | I9: =IF(OR(F9=0,E9=0)," - ",NETWORKDAYS(E9,F9)) -> #REF!
A10: =Gantt!A11 -> 1 | B10: =Gantt!C11 -> GARI BASE
A11: =Gantt!A12 -> 1.1 | B11: =Gantt!C12 -> GARI-BASE Re-ingegnerizzazione della piattaforma GIAS per implementare la nuova piattaforma GARI su nuove tecnologie ( i.e tecnologia Angular) | E11: =Gantt!#REF! -> #REF! | F11: =Gantt!#REF! -> #REF! | G11: =F11-E11 -> #REF! | H11: =Gantt!#REF! -> #REF! | I11: =IF(OR(F11=0,E11=0)," - ",NETWORKDAYS(E11,F11)) -> #REF!
A12: =Gantt!A13 -> 1.2 | B12: =Gantt!C13 -> Sviluppo funzionalità di Interlavoro con il sistema SIAN per importare il Piano colturale Grafico AGEA, compendiato dagli attributi catastali alfanumerici e altre informazioni legate alle consistenze aziendali funzionali alla gestione GARI Con acquisizione dei dati di fascicolo necessari ai procedimenti del GARI se e come esposti da AGEA. | E12: =Gantt!#REF! -> #REF! | F12: =Gantt!#REF! -> #REF! | G12: =F12-E12 -> #REF! | H12: =Gantt!#REF! -> #REF! | I12: =IF(OR(F12=0,E12=0)," - ",NETWORKDAYS(E12,F12)) -> #REF!
A13: =Gantt!A14 -> 1.3 | B13: =Gantt!C14 -> Implementazione del modulo GARI-GIS per la gestione( nel contesto GIS) i dati importati dal SIAN relativi al PCG (nuovo sistema di riferimento wgs84) | E13: =Gantt!#REF! -> #REF! | F13: =Gantt!#REF! -> #REF! | G13: =F13-E13 -> #REF! | H13: =Gantt!#REF! -> #REF! | I13: =IF(OR(F13=0,E13=0)," - ",NETWORKDAYS(E13,F13)) -> #REF!
A14: =Gantt!A15 -> 1.4 | B14: =Gantt!C15 -> Gestione delle Anagrafiche (risorse , macchine, analisi terreno etc) | E14: =Gantt!#REF! -> #REF! | F14: =Gantt!#REF! -> #REF! | G14: =F14-E14 -> #REF! | H14: =Gantt!#REF! -> #REF! | I14: =IF(OR(F14=0,E14=0)," - ",NETWORKDAYS(E14,F14)) -> #REF!
A15: =Gantt!A16 -> 1.5 | B15: =Gantt!C16 -> Implementazione del Modulo di Gestione dei documenti funzionale ai moduli GARI (Evolutive, installazione, configurazione/setting e profilazione utenza) | E15: =Gantt!#REF! -> #REF! | F15: =Gantt!#REF! -> #REF! | G15: =F15-E15 -> #REF! | H15: =Gantt!#REF! -> #REF! | I15: =IF(OR(F15=0,E15=0)," - ",NETWORKDAYS(E15,F15)) -> #REF!
A16: =Gantt!A17 -> 2 | B16: =Gantt!C17 -> GARI PA - UMA
A17: =Gantt!A18 -> 2.1 | B17: =Gantt!C18 -> RILASCIO 1 - Rif. Doc. fase unica PT000849TECH001 | E17: =Gantt!#REF! -> #REF! | F17: =Gantt!#REF! -> #REF! | G17: =F17-E17 -> #REF! | H17: =Gantt!#REF! -> #REF! | I17: =IF(OR(F17=0,E17=0)," - ",NETWORKDAYS(E17,F17)) -> #REF!
A18: =Gantt!A19 -> 2.2 | B18: =Gantt!C19 -> RILASCIO 2 - Rif. Doc. fase unica PT000849TECH001 | E18: =Gantt!#REF! -> #REF! | F18: =Gantt!#REF! -> #REF! | G18: =F18-E18 -> #REF! | H18: =Gantt!#REF! -> #REF! | I18: =IF(OR(F18=0,E18=0)," - ",NETWORKDAYS(E18,F18)) -> #REF!
A19: =Gantt!A20 -> 2.3 | B19: =Gantt!C20 -> RILASCIO 3 - Rif. Doc. fase unica PT000849TECH001 | E19: =Gantt!#REF! -> #REF! | F19: =Gantt!#REF! -> #REF! | G19: =F19-E19 -> #REF! | H19: =Gantt!#REF! -> #REF! | I19: =IF(OR(F19=0,E19=0)," - ",NETWORKDAYS(E19,F19)) -> #REF!
A20: =Gantt!A21 -> 2.4 | B20: =Gantt!C21 -> RILASCIO 4 - Rif. Doc. fase unica PT000849TECH001 | E20: =Gantt!#REF! -> #REF! | F20: =Gantt!#REF! -> #REF! | G20: =F20-E20 -> #REF! | H20: =Gantt!#REF! -> #REF! | I20: =IF(OR(F20=0,E20=0)," - ",NETWORKDAYS(E20,F20)) -> #REF!
A21: =Gantt!A22 -> 2.5 | B21: =Gantt!C22 -> RILASCIO 5 - Rif. Doc. fase unica PT000849TECH001 | E21: =Gantt!#REF! -> #REF! | F21: =Gantt!#REF! -> #REF! | G21: =F21-E21 -> #REF! | H21: =Gantt!#REF! -> #REF! | I21: =IF(OR(F21=0,E21=0)," - ",NETWORKDAYS(E21,F21)) -> #REF!
A22: =Gantt!A23 -> 2.6 | B22: =Gantt!C23 -> UMA Re-ingegnerizzazione della piattaforma GIAS per implementare la nuova piattaforma GARI su nuove tecnologie introdotte con il paradigma PCG | E22: =Gantt!#REF! -> #REF! | F22: =Gantt!#REF! -> #REF! | G22: =F22-E22 -> #REF! | H22: =Gantt!#REF! -> #REF! | I22: =IF(OR(F22=0,E22=0)," - ",NETWORKDAYS(E22,F22)) -> #REF!
A23: =Gantt!A24 -> 3 | B23: =Gantt!C24 -> GARI PUA
A24: =Gantt!A25 -> 3.1 | B24: =Gantt!C25 -> GARI-PUA Re-ingegnerizzazione della piattaforma GIAS per implementare la nuova piattaforma GARI su nuove tecnologie ( i.e tecnologia Angular) | E24: =Gantt!#REF! -> #REF! | F24: =Gantt!#REF! -> #REF! | G24: =F24-E24 -> #REF! | H24: =Gantt!#REF! -> #REF! | I24: =IF(OR(F24=0,E24=0)," - ",NETWORKDAYS(E24,F24)) -> #REF!
A25: =Gantt!A26 -> 3.2 | B25: =Gantt!C26 -> Nuovo Modulo PUA incluso la interoperabilità con ACA per le 04 13 e 24 - Fase1 | E25: =Gantt!#REF! -> #REF! | F25: =Gantt!#REF! -> #REF! | G25: =F25-E25 -> #REF! | H25: =Gantt!#REF! -> #REF! | I25: =IF(OR(F25=0,E25=0)," - ",NETWORKDAYS(E25,F25)) -> #REF!
A26: =Gantt!A27 -> 3.3 | B26: =Gantt!C27 -> Nuovo Modulo PUA collegamento e funzionamento su base PCG - Fase2 | E26: =Gantt!#REF! -> #REF! | F26: =Gantt!#REF! -> #REF! | G26: =F26-E26 -> #REF! | H26: =Gantt!#REF! -> #REF! | I26: =IF(OR(F26=0,E26=0)," - ",NETWORKDAYS(E26,F26)) -> #REF!
A27: =Gantt!A28 -> 4 | B27: =Gantt!C28 -> GARI - QDCA
A28: =Gantt!A29 -> 4.1 | B28: =Gantt!C29 -> QCDA-Re-ingegnerizzazione della piattaforma GIAS per implementare la nuova piattaforma GARI su nuove tecnologie ( i.e tecnologia Angular) | E28: =Gantt!#REF! -> #REF! | F28: =Gantt!#REF! -> #REF! | G28: =F28-E28 -> #REF! | H28: =Gantt!#REF! -> #REF! | I28: =IF(OR(F28=0,E28=0)," - ",NETWORKDAYS(E28,F28)) -> #REF!
A29: =Gantt!A30 -> 4.2 | B29: =Gantt!C30 -> Sviluppo SW GARI - Misure ACA | E29: =Gantt!#REF! -> #REF! | F29: =Gantt!#REF! -> #REF! | G29: =F29-E29 -> #REF! | H29: =Gantt!#REF! -> #REF! | I29: =IF(OR(F29=0,E29=0)," - ",NETWORKDAYS(E29,F29)) -> #REF!
A30: =Gantt!A31 -> 4.3 | B30: =Gantt!C31 -> Sviluppo SW GARI - DSS per misure ACA | E30: =Gantt!#REF! -> #REF! | F30: =Gantt!#REF! -> #REF! | G30: =F30-E30 -> #REF! | H30: =Gantt!#REF! -> #REF! | I30: =IF(OR(F30=0,E30=0)," - ",NETWORKDAYS(E30,F30)) -> #REF!
A31: =Gantt!A32 -> 4.4 | B31: =Gantt!C32 -> MEV - GARI QDCA - DSS - solo front-end (no algoritmi /API) + adeguamento salvataggio su GARI degli output relativi ai consigli dei Modelli Previsionali difesa e Irrigazione + Meteo (DSS) | E31: =Gantt!#REF! -> #REF! | F31: =Gantt!#REF! -> #REF! | G31: =F31-E31 -> #REF! | H31: =Gantt!#REF! -> #REF! | I31: =IF(OR(F31=0,E31=0)," - ",NETWORKDAYS(E31,F31)) -> #REF!
A32: =Gantt!A33 -> 4.5 | B32: =Gantt!C33 -> Acquisizione, raccordo e verifica dei dati Meteo/DSS da sorgenti esterne | E32: =Gantt!#REF! -> #REF! | F32: =Gantt!#REF! -> #REF! | G32: =F32-E32 -> #REF! | H32: =Gantt!#REF! -> #REF! | I32: =IF(OR(F32=0,E32=0)," - ",NETWORKDAYS(E32,F32)) -> #REF!
A33: =Gantt!A34 -> 4.6 | B33: =Gantt!C34 -> Acquisizione ,raccordo e verifica dei dati Meteo/DSS da sorgenti esterne | E33: =Gantt!#REF! -> #REF! | F33: =Gantt!#REF! -> #REF! | G33: =F33-E33 -> #REF! | H33: =Gantt!#REF! -> #REF! | I33: =IF(OR(F33=0,E33=0)," - ",NETWORKDAYS(E33,F33)) -> #REF!
A34: =Gantt!A35 -> 4.7 | B34: =Gantt!C35 -> Report ARPA: dati di impiego dei prodotti fitosanitari | E34: =Gantt!#REF! -> #REF! | F34: =Gantt!#REF! -> #REF! | G34: =F34-E34 -> #REF! | H34: =Gantt!#REF! -> #REF! | I34: =IF(OR(F34=0,E34=0)," - ",NETWORKDAYS(E34,F34)) -> #REF!
A35: =Gantt!A36 -> 4.8 | B35: =Gantt!C36 -> Revisione dei moduli QUADERNO SQNPI e BIO per essere utilizzabili e integrabili sulle nuove tecnologie introdotte con il paradigma PCG | E35: =Gantt!#REF! -> #REF! | F35: =Gantt!#REF! -> #REF! | G35: =F35-E35 -> #REF! | H35: =Gantt!#REF! -> #REF! | I35: =IF(OR(F35=0,E35=0)," - ",NETWORKDAYS(E35,F35)) -> #REF!
A36: =Gantt!A37 -> 4.9 | B36: =Gantt!C37 -> Attivazione registri bio nel contesto del QDCA GARI, setting, configurazioni, profilazioni utenti, ecc. | E36: =Gantt!#REF! -> #REF! | F36: =Gantt!#REF! -> #REF! | G36: =F36-E36 -> #REF! | H36: =Gantt!#REF! -> #REF! | I36: =IF(OR(F36=0,E36=0)," - ",NETWORKDAYS(E36,F36)) -> #REF!
B37: =Gantt!C38 -> ATTIVITA' DI CARATTERE CONTINUATIVO (NON PROGETTUALE) | I37: =IF(OR(F37=0,E37=0)," - ",NETWORKDAYS(E37,F37)) -> -
A38: =Gantt!A39 -> 5 | B38: =Gantt!C39 -> SERVIZI DI SUPPORTO SPECIALISTICO APPLICATIVO | I38: =IF(OR(F38=0,E38=0)," - ",NETWORKDAYS(E38,F38)) -> -
A39: =Gantt!A40 -> 5.1 | B39: =Gantt!C40 -> Supporto Specialistico 2024
A40: =Gantt!A41 -> 5.1.1 | B40: =Gantt!C41 -> Supporto Specialistico - I TRIM 2024 | E40: =Gantt!#REF! -> #REF! | F40: =Gantt!#REF! -> #REF! | G40: =F40-E40 -> #REF! | H40: =Gantt!#REF! -> #REF! | I40: =IF(OR(F40=0,E40=0)," - ",NETWORKDAYS(E40,F40)) -> #REF!
A41: =Gantt!A42 -> 5.1.2 | B41: =Gantt!C42 -> Supporto Specialistico - II TRIM 2024 | E41: =Gantt!#REF! -> #REF! | F41: =Gantt!#REF! -> #REF! | G41: =F41-E41 -> #REF! | H41: =Gantt!#REF! -> #REF! | I41: =IF(OR(F41=0,E41=0)," - ",NETWORKDAYS(E41,F41)) -> #REF!
A42: =Gantt!A43 -> 5.1.3 | B42: =Gantt!C43 -> Supporto Specialistico - III TRIM 2024 | E42: =Gantt!#REF! -> #REF! | F42: =Gantt!#REF! -> #REF! | G42: =F42-E42 -> #REF! | H42: =Gantt!#REF! -> #REF! | I42: =IF(OR(F42=0,E42=0)," - ",NETWORKDAYS(E42,F42)) -> #REF!
...

Sheet Sintesi Rendiconti
B1: LEONARDO | C1: DXC | D1: ABACO | E1: E-GEOS | F1: GREEN-AUS
A3: ANNO 2023 | J3: STATO
A4: IV Trimestre 2023
H5: TOTALE
A6: Servizi Applicativi | B6: 0 | C6: 0 | E6: 0 | F6: ='Riepilogo Contratto'!D4 -> #REF! | H6: =SUM(B6:F6) -> #REF!
A7: Servzi Infrastrutturali | B7: 0 | C7: 0 | E7: 0 | F7: 0 | H7: =SUM(B7:F7) -> 0
A8: Servizi di supporto specialistico | B8: ='Riepilogo Contratto'!D8 -> #REF! | C8: 0 | E8: 0 | F8: 0 | H8: =SUM(B8:F8) -> #REF!
A9: Call Center | B9: ='Riepilogo Contratto'!D9 -> #REF! | C9: 0 | E9: 0 | F9: 0 | H9: 0
A11: TOTALI | B11: =SUM(B6:B9) -> #REF! | C11: 0 | D11: =SUM(D6:D9) -> 0 | E11: =SUM(E6:E9) -> 0 | F11: =SUM(F6:F9) -> #REF! | H11: =SUM(H6:H9) -> #REF! | J11: Compilati
A13: TOTALE ANNO 2023 | B13: =B11 -> #REF! | C13: =C11 -> 0 | D13: =D11 -> 0 | E13: =E11 -> 0 | F13: =F11 -> #REF! | H13: =H11 -> #REF! | J13: Compilati
A15: ANNO 2024
A16: I Trimestre 2024
H17: TOTALE
A18: Servizi Applicativi | B18: ='Riepilogo Contratto'!E29 -> #REF! | C18: 0 | D18: 0 | E18: 0 | F18: 0 | H18: 0
A19: Servzi Infrastrutturali | B19: 0 | C19: 0 | D19: 0 | E19: 0 | F19: 0 | H19: 0
A20: Servizi di supporto specialistico | B20: =Gantt!#REF! -> #REF! | C20: 0 | D20: 0 | E20: 0 | F20: 0 | H20: 0
A21: Call Center | B21: =Gantt!#REF! -> #REF! | C21: 0 | D21: 0 | E21: 0 | F21: 0 | H21: 0
A23: TOTALI | B23: =SUM(B18:B21) -> #REF! | C23: =SUM(C18:C21) -> 0 | D23: =SUM(D18:D21) -> 0 | E23: 0 | F23: 0 | H23: =SUM(B23:F23) -> #REF! | J23: Compilati
A24: II Trimestre 2024
H25: TOTALE
A26: Servizi Applicativi | B26: ='Riepilogo Contratto'!F29 -> #REF! | C26: 0 | E26: 0 | F26: 0 | H26: 0
A27: Servzi Infrastrutturali | B27: 0 | C27: 0 | E27: 0 | F27: 0 | H27: 0
A28: Servizi di supporto specialistico | B28: ='Riepilogo Contratto'!F33 -> #REF! | C28: 0 | E28: 0 | F28: 0 | H28: 0
A29: Call Center | B29: ='Riepilogo Contratto'!F34 -> #REF! | C29: 0 | D29: 0 | E29: 0 | F29: 0 | H29: 0
A31: TOTALI | B31: =SUM(B26:B29) -> #REF! | C31: =SUM(C26:C29) -> 0 | D31: =SUM(D26:D29) -> 0 | E31: =SUM(E26:E29) -> 0 | F31: =SUM(F26:F29) -> 0 | H31: =SUM(B31:F31) -> #REF! | J31: Compilati
A32: III Trimestre 2024
H33: TOTALE
A34: Servizi Applicativi | B34: ='Riepilogo Contratto'!G29 -> #REF! | C34: 0 | D34: 0 | E34: 0 | F34: 0 | H34: 78296.75
A35: Servzi Infrastrutturali | B35: 0 | C35: 0 | D35: 0 | E35: 0 | F35: 0 | H35: 6406.2
A36: Servizi di supporto specialistico | B36: ='Riepilogo Contratto'!G33 -> #REF! | C36: 0 | D36: 0 | E36: 0 | F36: 0 | H36: 23550.75
A37: Call Center | B37: ='Riepilogo Contratto'!G34 -> #REF! | C37: 0 | D37: 0 | E37: 0 | F37: 0 | H37: 0
A39: TOTALI | B39: =SUM(B34:B37) -> #REF! | C39: =SUM(C34:C37) -> 0 | D39: =SUM(D34:D37) -> 0 | E39: =SUM(E34:E37) -> 0 | F39: =SUM(F34:F37) -> 0 | H39: =SUM(B39:F39) -> #REF!
A40: IV Trimestre 2024
B41: LEONARDO | C41: DXC | D41: ABACO | E41: E-GEOS | F41: GREEN-AUS | H41: TOTALE
A42: Servizi Applicativi | B42: 0 | C42: 0 | D42: 0 | E42: 0 | F42: 0 | H42: =SUM(B42:F42) -> 0
A43: Servzi Infrastrutturali | B43: 0 | C43: 0 | E43: 0 | F43: 0 | H43: =SUM(B43:F43) -> 0
A44: Servizi di supporto specialistico | B44: 0 | C44: 0 | D44: 0 | E44: 0 | F44: 0 | H44: =SUM(B44:F44) -> 0
A45: Call Center | B45: 0 | C45: 0 | D45: 0 | E45: 0 | F45: 0 | H45: 0
A47: TOTALI | B47: 0 | C47: 0 | D47: 0 | E47: =SUM(E42:E45) -> 0 | F47: =SUM(F42:F45) -> 0 | H47: =SUM(H42:H45) -> 0
A49: TOTALE ANNO 2024 | B49: =SUM(B23,B31,B39,B47) -> #REF! | C49: =SUM(C23,C31,C39,C47) -> 0 | D49: =SUM(D23,D31,D39,D47) -> 0 | E49: =SUM(E23,E31,E39,E47) -> 0 | F49: =SUM(F23,F31,F39,F47) -> 0 | H49: =SUM(H23,H31,H39,H47) -> #REF!

Sheet Gantt
C1: Indicazioni operative ed amministrative su cui operare per dare seguito al Piano di lavoro secondo lo stato dell'arte delle atttività disucsso e rivisto nella riunione del 13 novembre 2024
A2: ID | B2: Predecessore /vincoli | C2: Titolo attività | D2: Indicazioni e impegni attesi da parte del RTI
C3: Definizione precondizioni operative | D3: nessuno
C4: Disponibilità Piattaforma GARI BASE
C5: PRESA IN CARICO
C6: Incontri con Amministrazione
C7: Knowledge Transfer
C8: Consegna e Convalida
C9: SERVIZI APPLICATIVI - ATTIVITA' DI CARATTERE PROGETTUALE (Sviluppo SW + MEV+Supporto Specialistico Operativo)
A10: 0 | C10: MEV GARI-PA per porting (IV TRIM 23) su nuovo ambiente di tutti i moduli (BASE, PUA, QDCA, UMA) | D10: Per chiudere questa operazione e, consenguentemente poter vagliare l'attività di cui al punto 1.1 occorre: • rivedere la documentazione della ver.02.02 GARI che deve prevedere le sole non conformità sollevate con il collaudo ufficiale del 22 gennaio 2024; • Risistemazione di tutti i documenti già trasmessi secondo le indicazioni ricevute dopo la lettura degli stessi da parte della Regione e delle indicazioni inviate con le mail e le PEC in cui sono stati trasmessi i documenti di osservazione; • rilascio nell’ambiente cloud test/collaudo e nel Repository del codice Sorgente, del codice compilato e della documentazione già prodotta e sistemata versionata come 01.01, come consegna del prodotto Open source commissionato da Regione ad RTI per la continuità di servizio dell’ex GIAS e collaudato il 22 gennaio 2024 con verbale registrato. Per i documenti vedi la nota già trasmessa nei giorni passati con i tipi di documenti previsti per i rilascio del software GARI. secondo le linee guid agid e L'appendice 6 della Convenzione CONSIP Agea; • predisposizione del Verbale della presa d’atto finale del rilascio della versione 01.01 con le non conformità risolte attraverso la versione 02.02
A11: 1 | C11: GARI BASE
A12: 1.1 | C12: GARI-BASE Re-ingegnerizzazione della piattaforma GIAS per implementare la nuova piattaforma GARI su nuove tecnologie ( i.e tecnologia Angular) | D12: Produzione del documento architetturale comprensivo di tutte le caratteristiche del GARI discusse, presentate e condivise tra le parti a seguito dell' analisi dei documenti Agea e delle schede richiesta intervento presentate dalla Regione, nonchè delle decisioni di carattere tecnologico prese dal RTI nel passaggio di trasformazione dell'open Socurce consegnato in quello che sarà a fine contratto il GARI della Regione dell'Umbria.
A13: 1.2 | C13: Sviluppo funzionalità di Interlavoro con il sistema SIAN per importare il Piano colturale Grafico AGEA, compendiato dagli attributi catastali alfanumerici e altre informazioni legate alle consistenze aziendali funzionali alla gestione GARI Con acquisizione dei dati di fascicolo necessari ai procedimenti del GARI se e come esposti da AGEA. | D13: Produzione del documento con appositi capitoli delle specifiche tecniche e funzionali del GARI per la parte relativa allo scambio dati (flussi) tra Regione ed Agea, compreso OP (attività 1.2 e 1.3). Ad oggi, infatti, non è stato rilasciato dal RTI alcun documento tecnico a corredo che consente una approvazione a procedere da parte della Regione o comunque che ne testimonia la conoscenza. Analogamente, per l'attività 1.4 è necessario produrre un documento un capitolo di specifiche delle anagrafiche di Sistema (collegate ai fascicoli Aziendali) di aggiornamento e revisione della anagrafiche già presenti e delle eventuali nuove, evinte dalle richieste delle schede intervento e dal progetto del nuovo SIAN di Agea. Anche per l'attività 1.5 è necessario produrre nel documento un capitolo a riguardo con la descrizione del sistema di gestione e collegamento dei documenti alle informazioni a corredo degli impegni e delle anagrafiche inserite degli utenti. In relazione a questo aspetto è necessario introdurre nel Progetto evolutivo del GARI BASE la presenza esplicita nel documento richiesto dal Fascicolo Aziendale GARI come contesto popolato a partire dal SIAN, superando come concordato nelle riunioni tra le parti l'interazione ad oggi con il contesto del Fascicolo di Agea Coordinamento, presente nell'Open Source 01.01 del 22 gennaio. Quanto qui espresso è ESSENZIALE per poter approvare le attività qui descritte ed è importante che il tutto sia disponibile quanto prima per poter arrivare a poter disporre di una prima release del GARI grafico entro i tempi previsti dal Piano di lavoro generale
A14: 1.3 | C14: Implementazione del modulo GARI-GIS per la gestione( nel contesto GIS) i dati importati dal SIAN relativi al PCG (nuovo sistema di riferimento wgs84)
A15: 1.4 | C15: Gestione delle Anagrafiche (risorse , macchine, analisi terreno etc)
A16: 1.5 | C16: Implementazione del Modulo di Gestione dei documenti funzionale ai moduli GARI (Evolutive, installazione, configurazione/setting e profilazione utenza)
A17: 2 | C17: GARI PA - UMA
A18: 2.1 | C18: RILASCIO 1 - Rif. Doc. fase unica PT000849TECH001 | D18: Per chiudere e chiudere questa attività di progetto e trasferire l'output in esercizio è necessario produrre: • Comunicazione e certificazione della installazione del modulo UMA 2024 finale nel Cloud di Esercizio; • Disponibilità del manuale uso utente rilasciato per gli utilizzatori; • inserimento nel Repository regionale della documentazione finale di rilascio prevista per i software posti in esercizio, con verbale congiunto di constatazione e presa in carico del gruppo di lavoro dell’Help Desk di primo livello; • Definizione e verifica dei documenti amministrativi di chiusura, presa in carico del prodotto per la liquidazione dell’importo complessivo UMA previsto dal progetto 2023/2024; • Predisposizione e rilascio del Piano di Assistenza per l’UMA in esercizio da rendicontare nell’assistenza applicativa prevista dal contratto.
A19: 2.2 | C19: RILASCIO 2 - Rif. Doc. fase unica PT000849TECH001
A20: 2.3 | C20: RILASCIO 3 - Rif. Doc. fase unica PT000849TECH001
A21: 2.4 | C21: RILASCIO 4 - Rif. Doc. fase unica PT000849TECH001
A22: 2.5 | C22: RILASCIO 5 - Rif. Doc. fase unica PT000849TECH001
A23: 2.6 | C23: UMA Re-ingegnerizzazione della piattaforma GIAS per implementare la nuova piattaforma GARI su nuove tecnologie introdotte con il paradigma PCG | D23: Questa attività va descritta come capitolo del documento delle evoluzioni UMA 2025
A24: 3 | C24: GARI PUA
A25: 3.1 | C25: GARI-PUA Re-ingegnerizzazione della piattaforma GIAS per implementare la nuova piattaforma GARI su nuove tecnologie ( i.e tecnologia Angular) | D25: Quanto illustrato in tutte queste attività va descritto in un documento di proposta tecnico economica unico dell'attività prevista per il PUA. Come concordato si tratta di predisporre un documento descrittivo completando e integrando quello già presentato, ponendo in allegato il Piano di lavoro obiettivo nella forma discussa in questo periodo tra le parti. L'attività 3.1 può essere descritta e presentata con un documento esterno allegato alla proposta già trasmessa dal RTI, a completamento delle richieste presenti nella Scheda intervento regionale sulla parte grafica
A26: 3.2 | C26: Nuovo Modulo PUA incluso la interoperabilità con ACA per le 04 13 e 24 - Fase1
A27: 3.3 | C27: Nuovo Modulo PUA collegamento e funzionamento su base PCG - Fase2
A28: 4 | C28: GARI - QDCA
A29: 4.1 | C29: QCDA-Re-ingegnerizzazione della piattaforma GIAS per implementare la nuova piattaforma GARI su nuove tecnologie ( i.e tecnologia Angular) | D29: Questa attività va descritta come integrazione (anche allegato separato) al documento di proposta già trasmesso da RTI per l'ACA (4.2. e 4.3) , a completamento delle richieste presenti nella Scheda intervento regionale sulla parte grafica
A30: 4.2 | C30: Sviluppo SW GARI - Misure ACA | D30: Come da documento presentato e approvato tecnicamente e per cui occorre procedere con: • Piano degli interventi di sviluppo software e dei rilasci previsti per rispondere alle esigenze • Piano di installazione del modulo/servizi SQNPI nel cloud di esercizio del GARI, secondo il processo di attivazione dell’uso della funzionalità concordato nelle riunioni del 4 e del 5 novembre • Quadro del dettaglio dei costi gli interventi complessivi previsti per gli sviluppi e per l’attivazione del modulo/servizi • Piano di formazione degli utenti e di rilascio della documentazione d’uso del prodotto • Elenco degli output complessivi previsti dall’attività della proposta (sorgente, compilato, documenti)
A31: 4.3 | C31: Sviluppo SW GARI - DSS per misure ACA
A32: 4.4 | C32: MEV - GARI QDCA - DSS - solo front-end (no algoritmi /API) + adeguamento salvataggio su GARI degli output relativi ai consigli dei Modelli Previsionali difesa e Irrigazione + Meteo (DSS) | D32: DA PREVEDERE NEL PIANO LAVORO OBIETTIVO 1. documento tecniconell'ultima versione del RTI come valutazione tecnico funzionale del modello di servizio rilasciato nel GARI. A riguardo è essenziale che il GARI / DSS abbia strumenti e canali digitali di richiesta partendo dai dati delle Aziende, in grado di assumere, registrare e conservare elaborati/ documentali; 2. A compendio dovrà essere previsto un contesto professionale del RTI a supporto e in grado di assicurare il change management ad una struttura composta da personale di uffici regionale del fitosanitario e/o dei colleghi referenti ACA (fertilizzazione e irrigazione) sull'utilizzo dell'ambiente e dei relativi servizi in assistenza dell'utenza territoriale
A33: 4.5 | C33: Acquisizione, raccordo e verifica dei dati Meteo/DSS da sorgenti esterne
A34: 4.6 | C34: Acquisizione ,raccordo e verifica dei dati Meteo/DSS da sorgenti esterne
A35: 4.7 | C35: Report ARPA: dati di impiego dei prodotti fitosanitari | D35: Al momento sospeso in corso di verfica da parte di Regione la possibilità di un uso del prodotto/servizio più esteso e pertanto è necessario verificare la completezza e rispondenza rispetto alla richiesta fatta dalla Regione specifica per l'ARPA. Visto il prodotto software proposto dal RTI si è ritenuto di verificare la possibilità di poter estendere l'uso a altri uffici.
A36: 4.8 | C36: Revisione dei moduli QUADERNO SQNPI e BIO per essere utilizzabili e integrabili sulle nuove tecnologie introdotte con il paradigma PCG | D36: la descrizione di questa attività va inserita nel documento complessivo SQNPI / ACA di cui ai punti 31. 3.2 3.3
A37: 4.9 | C37: Attivazione registri bio nel contesto del QDCA GARI, setting, configurazioni, profilazioni utenti, ecc.
C38: ATTIVITA' DI CARATTERE CONTINUATIVO (NON PROGETTUALE) | D38: Per questa sezione di progetto deve essere previsto un vero e proprio PIANO di LAVORO OBIETTIVO in cui siano descritti e aggiornati, a seguito di rilasci del software incrementale, i servizi resi e le modalità di erogazione. Il termine corretto per questa fattispecie di attività sarebbe "Piano di esercizio del Sistema GaRI" Questo piano trimestralmente come indicato nelle righe sotto va rendicontato con un documento apposito che possiamo condividere ci sono modelli usati a riguardo in altri progetti, semplici ed efficaci.
A39: 5 | C39: SERVIZI DI SUPPORTO SPECIALISTICO APPLICATIVO
A40: 5.1 | C40: Supporto Specialistico 2024
...

Sheet Valori per liste a discesa
C1: Stati | D1: Priorità | E1: Attori | F1: Referenti | G1: Tipologia attività | H1: Servizio
C2: PIANIFICATO | D2: 1-Alta | G2: Progettuale | H2: Supporto Specialistico (a consumo)
C3: IN CORSO | D3: 2-Media | G3: Continuativa
C4: COMPLETATO | D4: 3-Bassa
C5: CANCELLATO
C6: DA RIPIANIFICARE
C7: NECESSARI APPROFONDIMENTI PER AVVIO
C8: DA PIANIFICARE
C9: DA AVVIARE
C10: RILASCIATO IN COLLAUDO
C11: ESITO POSITIVO AL COLLAUDO
C12: RILASCIATO IN ESERCIZIO

Sheet Settore
A1: CODICE PIANO LDCSIN / CODICE COMPUTO | B1: denominazione Piano / descrizione computo
A2: 001 | B2: Fascicolo Aziendale OC
A3: 002 | B3: Fascicolo Aziendale OP
A4: 003 | B4: Condizionalità (SICC - Sistema integrato di controllo e condizionalità)
A5: 006 | B5: Miele
A6: 007 | B6: Domanda Unica
A7: 008 | B7: Tabacco
A8: 009 | B8: Latte
A9: 010 | B9: Aiuti nazionali filiere zootecniche
A10: 011 | B10: Ortofrutta fresca (programmi operativi)
A11: 012 | B11: PIANO PER LA RIGENERAZIONE OLIVICOLA DELLA PUGLIA DM 2484/2020 -INTERVENTI COMPENSATIVI A FAVORE DEI FRANTOI OLEARI
A12: 014 | B12: Registro titoli
... A89: CODICE PIANO LDCSIN / CODICE COMPUTO | B89: SETTORI AGGIUNTI

Sheet Legende
A1: PIANIFICATO
A2: IN CORSO
A3: COMPLETATO
A4: CANCELLATO
A5: NECESSARI APPROFONDIMENTI PER L'AVVIO
A6: RIPIANIFICATA
A10: Sviluppo software
A11: MEV
A12: Conduzione applicativa(Consumo)
A13: Supp. Spec. App. (Consumo)
A14: Servizi Desk(Canone)
A17: III TRIMESTRE 2023
... A26: IV TRIMESTRE 2025
