Workbook
Name CEUmbria: #REF!
Name Inizio_progetto: #REF!
Name prevWBS: 'Project Plan'!$A1048576
Name Visualizza_settimana: #REF!

Sheet Riepilogo Contratto
B2: Pianificato | D2: IV TRIM 2023 | E2: 2024 | F2: I SEM 2025 | H2: TOTALE PIANIFICATO | J2: TOTALE PdF
B4: Servizi Applicativi | D4: =SUM(D5,D6:D7) -> 174540 | E4: =SUM(E5,E6:E7) -> 873360 | F4: =SUM(F5,F6:F7) -> 370000 | H4: =SUM(H5,H6:H7) -> 1417900
B5: Sviluppo Software gg/persona | D5: =SUMIF(Gantt!$N$10:$N$55,"Sviluppo software",Gantt!I10:I55) -> 74688 | E5: =SUMIF(Gantt!$N$10:$N$55,"Sviluppo software",Gantt!J10:J55) -> 415860 | F5: =SUMIF(Gantt!$N$10:$N$55,"Sviluppo software",Gantt!K10:K55) -> 175000 | H5: =SUM(D5:F5) -> 665548 | J5: 360008
B6: MEV/MAD | D6: =SUMIF(Gantt!$N$10:$N$55,"MEV",Gantt!I10:I55) -> 99852 | E6: =SUMIF(Gantt!$N$10:$N$55,"MEV",Gantt!J10:J55) -> 222500 | F6: =SUMIF(Gantt!$N$10:$N$55,"MEV",Gantt!K10:K55) -> 165000 | H6: =SUM(D6:F6) -> 487352 | J6: 489486
B7: Conduzione Applicativa | D7: =SUMIF(Gantt!$N$10:$N$55,"Conduzione Applicativa(Consumo)",Gantt!I10:I55) -> 0 | E7: =SUMIF(Gantt!$N$10:$N$55,"Conduzione Applicativa(Consumo)",Gantt!J10:J55) -> 235000 | F7: =SUMIF(Gantt!$N$10:$N$55,"Conduzione Applicativa(Consumo)",Gantt!K10:K55) -> 30000 | H7: =SUM(D7:F7) -> 265000 | J7: =887592-236881.5 -> 650710.5
B8: Supporto Specialistico Applicativo | D8: =SUMIF(Gantt!$N$10:$N$55,"Supp. Spec. App. (Consumo)",Gantt!I10:I55) -> 0 | E8: =SUMIF(Gantt!$N$10:$N$55,"Supp. Spec. App. (Consumo)",Gantt!J10:J55) -> 42918 | F8: =SUMIF(Gantt!$N$10:$N$55,"Supp. Spec. App. (Consumo)",Gantt!K10:K55) -> 48176 | H8: =SUM(D8:F8) -> 91094 | J8: 91094
B9: Servizi di Call Center | D9: =SUMIF(Gantt!$N$10:$N$55,"Servizi Desk(Canone)",Gantt!I10:I55) -> 0 | E9: =SUMIF(Gantt!$N$10:$N$55,"Servizi Desk(Canone)",Gantt!J10:J55) -> 35000 | F9: =SUMIF(Gantt!$N$10:$N$55,"Servizi Desk(Canone)",Gantt!K10:K55) -> 35000 | H9: =SUM(D9:F9) -> 70000 | J9: 84997.5
B11: Totale Pianificato | D11: =D4+D8+D9 -> 174540 | E11: =E4+E8+E9 -> 951278 | F11: =F4+F8+F9 -> 453176 | H11: =SUM(D11:F11) -> 1578994 | J11: =SUM(J5:J9) -> 1676296
J12: =H13-H11 -> 97302 | K12: Residuo da Pianificare
B13: TOTALI DA PDF | D13: 484872 | E13: 788379 | F13: 403045 | H13: =SUM(D13:F13) -> 1676296
B17: PdF
B18: Sviluppo | D18: 180000 | E18: 150012 | F18: 29996 | H18: =SUM(D18:F18) -> 360008 | J18: =H18-H5 -> -305540
B19: MEV | D19: 200000 | E19: 209997 | F19: 79489 | H19: =SUM(D19:F19) -> 489486 | J19: =H19-H6 -> 2134
B20: Conduzione Applicativa | D20: 104872 | E20: 350452 | F20: 220268 | H20: =SUM(D20:F20) -> 675592 | J20: =H20-H7 -> 410592
B21: Assistenza spec | D21: 0 | E21: 42918 | F21: 38292 | H21: =SUM(D21:F21) -> 81210 | J21: =H21-H8 -> -9884
B22: Call center | D22: 0 | E22: 35000 | F22: 35000 | H22: =SUM(D22:F22) -> 70000 | J22: =H22-H9 -> 0
D24: =SUM(D18:D22) -> 484872 | E24: =SUM(E18:E22) -> 788379 | F24: =SUM(F18:F22) -> 403045 | H24: =SUM(D24:F24) -> 1676296
D27: IV TRIM 2023 | E27: I TRIM 2024 | F27: II TRIM 2024 | G27: III TRIM 2024 | H27: IV TRIM 2024 | I27: I TRIM 2025 | J27: II TRIM 2025
B29: Servizi Applicativi | D29: =SUM(D30,D31:D32) -> 174540 | E29: =SUM(E30,E31:E32) -> 229483 | F29: =SUM(F30,F31:F32) -> 21074 | G29: =SUM(G30,G31:G32) -> 0 | H29: =SUM(H30,H31:H32) -> 622803 | I29: =SUM(I30,I31:I32) -> 355000 | J29: =SUM(J30,J31:J32) -> 15000
B30: Sviluppo Software gg/persona | D30: =SUMIFS(Gantt!$I$10:$I$55,Gantt!$N$10:$N$55,"Sviluppo software",Gantt!$O$10:$O$55,"IV TRIMESTRE 2023") -> 74688 | E30: =SUMIFS(Gantt!$J$10:$J$55,Gantt!$N$10:$N$55,"Sviluppo software",Gantt!$O$10:$O$55,"I TRIMESTRE 2024") -> 29483 | F30: =SUMIFS(Gantt!$J$10:$J$55,Gantt!$N$10:$N$55,"Sviluppo software",Gantt!$O$10:$O$55,"II TRIMESTRE 2024") -> 21074 | G30: =SUMIFS(Gantt!$J$10:$J$55,Gantt!$N$10:$N$55,"Sviluppo software",Gantt!$O$10:$O$55,"III TRIMESTRE 2024") -> 0 | H30: =SUMIFS(Gantt!$J$10:$J$55,Gantt!$N$10:$N$55,"Sviluppo software",Gantt!$O$10:$O$55,"IV TRIMESTRE 2024") -> 365303 | I30: =SUMIFS(Gantt!$K$10:$K$55,Gantt!$N$10:$N$55,"Sviluppo software",Gantt!$O$10:$O$55,"I TRIMESTRE 2025") -> 175000 | J30: =SUMIFS(Gantt!$K$10:$K$55,Gantt!$N$10:$N$55,"Sviluppo software",Gantt!$O$10:$O$55,"II TRIMESTRE 2025") -> 0
B31: MEV/MAD | D31: =SUMIFS(Gantt!$I$10:$I$55,Gantt!$N$10:$N$55,"MEV",Gantt!$O$10:$O$55,"IV TRIMESTRE 2023") -> 99852 | E31: =SUMIFS(Gantt!$J$10:$J$55,Gantt!$N$10:$N$55,"MEV",Gantt!$O$10:$O$55,"I TRIMESTRE 2024") -> 0 | F31: =SUMIFS(Gantt!$J$10:$J$55,Gantt!$N$10:$N$55,"MEV",Gantt!$O$10:$O$55,"II TRIMESTRE 2024") -> 0 | G31: =SUMIFS(Gantt!$J$10:$J$55,Gantt!$N$10:$N$55,"MEV",Gantt!$O$10:$O$55,"III TRIMESTRE 2024") -> 0 | H31: =SUMIFS(Gantt!$J$10:$J$55,Gantt!$N$10:$N$55,"MEV",Gantt!$O$10:$O$55,"IV TRIMESTRE 2024") -> 222500 | I31: =SUMIFS(Gantt!$K$10:$K$55,Gantt!$N$10:$N$55,"MEV",Gantt!$O$10:$O$55,"I TRIMESTRE 2025") -> 165000 | J31: =SUMIFS(Gantt!$K$10:$K$55,Gantt!$N$10:$N$55,"MEV",Gantt!$O$10:$O$55,"II TRIMESTRE 2025") -> 0
B32: Conduzione Applicativa | D32: =SUMIFS(Gantt!$I$10:$I$55,Gantt!$N$10:$N$55,"Conduzione applicativa(consumo)",Gantt!$P$10:$P$55,"2023") -> 0 | E32: =SUMIFS(Gantt!$J$10:$J$55,Gantt!$N$10:$N$55,"Conduzione applicativa(consumo)",Gantt!$O$10:$O$55,"I TRIMESTRE 2024") -> 200000 | F32: =SUMIFS(Gantt!$J$10:$J$55,Gantt!$N$10:$N$55,"Conduzione applicativa(consumo)",Gantt!$O$10:$O$55,"II TRIMESTRE 2024") -> 0 | G32: =SUMIFS(Gantt!$J$10:$J$55,Gantt!$N$10:$N$55,"Conduzione applicativa(consumo)",Gantt!$O$10:$O$55,"III TRIMESTRE 2024") -> 0 | H32: =SUMIFS(Gantt!$J$10:$J$55,Gantt!$N$10:$N$55,"Conduzione applicativa(consumo)",Gantt!$O$10:$O$55,"IV TRIMESTRE 2024") -> 35000 | I32: =SUMIFS(Gantt!$K$10:$K$55,Gantt!$N$10:$N$55,"Conduzione applicativa(consumo)",Gantt!$O$10:$O$55,"I TRIMESTRE 2025") -> 15000 | J32: =SUMIFS(Gantt!$K$10:$K$55,Gantt!$N$10:$N$55,"Conduzione applicativa(consumo)",Gantt!$O$10:$O$55,"II TRIMESTRE 2025") -> 15000
B33: Supporto specialistico Applicativo | D33: =SUMIFS(Gantt!$I$10:$I$55,Gantt!$N$10:$N$55,"Supp. Spec. App. (Consumo)",Gantt!$P$10:$P$55,"2023") -> 0 | E33: =SUMIFS(Gantt!$J$10:$J$55,Gantt!$N$10:$N$55,"Supp. Spec. App. (Consumo)",Gantt!$O$10:$O$55,"I TRIMESTRE 2024") -> 10729.5 | F33: =SUMIFS(Gantt!$J$10:$J$55,Gantt!$N$10:$N$55,"Supp. Spec. App. (Consumo)",Gantt!$O$10:$O$55,"II TRIMESTRE 2024") -> 10729.5 | G33: =SUMIFS(Gantt!$J$10:$J$55,Gantt!$N$10:$N$55,"Supp. Spec. App. (Consumo)",Gantt!$O$10:$O$55,"III TRIMESTRE 2024") -> 10729.5 | H33: =SUMIFS(Gantt!$J$10:$J$55,Gantt!$N$10:$N$55,"Supp. Spec. App. (Consumo)",Gantt!$O$10:$O$55,"IV TRIMESTRE 2024") -> 10729.5 | I33: =SUMIFS(Gantt!$K$10:$K$55,Gantt!$N$10:$N$55,"Supp. Spec. App. (Consumo)",Gantt!$O$10:$O$55,"I TRIMESTRE 2025") -> 24088 | J33: =SUMIFS(Gantt!$K$10:$K$55,Gantt!$N$10:$N$55,"Supp. Spec. App. (Consumo)",Gantt!$O$10:$O$55,"II TRIMESTRE 2025") -> 24088
B34: Servizi di Call Center | D34: =SUMIFS(Gantt!$I$10:$I$55,Gantt!$N$10:$N$55,"Servizi Desk(Canone)",Gantt!$O$10:$O$55,"IV TRIMESTRE 2023") -> 0 | E34: =SUMIFS(Gantt!$J$10:$J$55,Gantt!$N$10:$N$55,"Servizi Desk(Canone)",Gantt!$O$10:$O$55,"I TRIMESTRE 2024") -> 8750 | F34: =SUMIFS(Gantt!$J$10:$J$55,Gantt!$N$10:$N$55,"Servizi Desk(Canone)",Gantt!$O$10:$O$55,"II TRIMESTRE 2024") -> 8750 | G34: =SUMIFS(Gantt!$J$10:$J$55,Gantt!$N$10:$N$55,"Servizi Desk(Canone)",Gantt!$O$10:$O$55,"III TRIMESTRE 2024") -> 8750 | H34: =SUMIFS(Gantt!$J$10:$J$55,Gantt!$N$10:$N$55,"Servizi Desk(Canone)",Gantt!$O$10:$O$55,"IV TRIMESTRE 2024") -> 8750 | I34: =SUMIFS(Gantt!$K$10:$K$55,Gantt!$N$10:$N$55,"Servizi Desk(Canone)",Gantt!$O$10:$O$55,"I TRIMESTRE 2025") -> 17500 | J34: =SUMIFS(Gantt!$K$10:$K$55,Gantt!$N$10:$N$55,"Servizi Desk(Canone)",Gantt!$O$10:$O$55,"II TRIMESTRE 2025") -> 17500
B36: Totale Collaudato | D36: =D29+D33+D34 -> 174540 | E36: =E29+E33+E34 -> 248962.5 | F36: =F29+F33+F34 -> 40553.5 | G36: =G29+G33+G34 -> 19479.5 | H36: =H29+H33+H34 -> 642282.5 | I36: =I29+I33+I34 -> 396588 | J36: =J29+J33+J34 -> 56588 | K36: TOTALE | L36: =SUM(D36:J36) -> 1578994

Sheet Project Plan
A1: Regione Umbria - GARI | K1: Gantt Chart Template © 2006-2018 by Vertex42.com.
B4: Data Inizio Progetto | C4: 45231 | G4: Display Week | H4: 54 | K4: ="Week "&(K6-($C$4-WEEKDAY($C$4,1)+2))/7+1 -> Week 54 | R4: ="Week "&(R6-($C$4-WEEKDAY($C$4,1)+2))/7+1 -> Week 55 | Y4: ="Week "&(Y6-($C$4-WEEKDAY($C$4,1)+2))/7+1 -> Week 56 | AF4: ="Week "&(AF6-($C$4-WEEKDAY($C$4,1)+2))/7+1 -> Week 57 | AM4: ="Week "&(AM6-($C$4-WEEKDAY($C$4,1)+2))/7+1 -> Week 58 | AT4: ="Week "&(AT6-($C$4-WEEKDAY($C$4,1)+2))/7+1 -> Week 59 | BA4: ="Week "&(BA6-($C$4-WEEKDAY($C$4,1)+2))/7+1 -> Week 60 | BH4: ="Week "&(BH6-($C$4-WEEKDAY($C$4,1)+2))/7+1 -> Week 61 | BO4: ="Week "&(BO6-($C$4-WEEKDAY($C$4,1)+2))/7+1 -> Week 62
B5: Project Lead | K5: =K6 -> 45600 | R5: =R6 -> 45607 | Y5: =Y6 -> 45614 | AF5: =AF6 -> 45621 | AM5: =AM6 -> 45628 | AT5: =AT6 -> 45635 | BA5: =BA6 -> 45642 | BH5: =BH6 -> 45649 | BO5: =BO6 -> 45656
K6: =C4-WEEKDAY(C4,1)+2+7*(H4-1) -> 45600 | L6: =K6+1 -> 45601 | M6: =L6+1 -> 45602 | N6: =M6+1 -> 45603 | O6: =N6+1 -> 45604 | P6: =O6+1 -> 45605 | Q6: =P6+1 -> 45606 | R6: =Q6+1 -> 45607 | S6: =R6+1 -> 45608 | ... BU6: =BT6+1 -> 45662
A7: WBS | B7: TASK | C7: LEAD | D7: PREDECESSORI | E7: INIZIO | F7: FINE | G7: Durata gg | H7: % COMPLETAMENTO | I7: GIORNI Lavorativi | K7: =CHOOSE(WEEKDAY(K6,1),"S","M","T","W","T","F","S") -> M | L7: =CHOOSE(WEEKDAY(L6,1),"S","M","T","W","T","F","S") -> T | M7: =CHOOSE(WEEKDAY(M6,1),"S","M","T","W","T","F","S") -> W | N7: =CHOOSE(WEEKDAY(N6,1),"S","M","T","W","T","F","S") -> T | O7: =CHOOSE(WEEKDAY(O6,1),"S","M","T","W","T","F","S") -> F | P7: =CHOOSE(WEEKDAY(P6,1),"S","M","T","W","T","F","S") -> S | Q7: =CHOOSE(WEEKDAY(Q6,1),"S","M","T","W","T","F","S") -> S | R7: =CHOOSE(WEEKDAY(R6,1),"S","M","T","W","T","F","S") -> M | ... BU7: =CHOOSE(WEEKDAY(BU6,1),"S","M","T","W","T","F","S") -> S
A8: =IF(ISERROR(VALUE(SUBSTITUTE(prevWBS,".",""))),"1",IF(ISERROR(FIND("`",SUBSTITUTE(prevWBS,".","`",1))),TEXT(VALUE(prevWBS)+1,"#"),TEXT(VALUE(LEFT(prevWBS,FIND("`",SUBSTITUTE(prevWBS,".","`",1))-1))+1,"#"))) -> 1 | B8: =Gantt!D10 -> SERVIZI APPLICATIVI - ATTIVITA' DI CARATTERE PROGETTUALE (Sviluppo SW + MEV+Supporto Specialistico Operativo) | F8: =IF(ISBLANK(E8)," - ",IF(G8=0,E8,E8+G8-1)) -> - | I8: =IF(OR(F8=0,E8=0)," - ",NETWORKDAYS(E8,F8)) -> -
A9: =Gantt!A11 -> 0 | B9: =Gantt!D11 -> MEV GARI-PA per porting (IV TRIM 23) su nuovo ambiente di tutti i moduli (BASE, PUA, QDCA, UMA) | E9: =Gantt!U11 -> 45231 | F9: =Gantt!X11 -> 45313 | G9: =F9-E9 -> 82 | H9: =Gantt!T11 -> 1 | I9: =IF(OR(F9=0,E9=0)," - ",NETWORKDAYS(E9,F9)) -> 59
A10: =Gantt!A12 -> 1 | B10: =Gantt!D12 -> GARI BASE
A11: =Gantt!A13 -> 1.1 | B11: =Gantt!D13 -> GARI-BASE Re-ingegnerizzazione della piattaforma GIAS per implementare la nuova piattaforma GARI su nuove tecnologie ( i.e tecnologia Angular) | E11: =Gantt!U13 -> 45299 | F11: =Gantt!X13 -> 45366 | G11: =F11-E11 -> 67 | H11: =Gantt!T13 -> 1 | I11: =IF(OR(F11=0,E11=0)," - ",NETWORKDAYS(E11,F11)) -> 50
A12: =Gantt!A14 -> 1.2 | B12: =Gantt!D14 -> Sviluppo funzionalità di Interlavoro con il sistema SIAN per importare il Piano colturale Grafico AGEA, compendiato dagli attributi catastali alfanumerici e altre informazioni legate alle consistenze aziendali funzionali alla gestione GARI Con acquisizione dei dati di fascicolo necessari ai procedimenti del GARI se e come esposti da AGEA. | E12: =Gantt!U14 -> 45536 | F12: =Gantt!X14 -> 45641 | G12: =F12-E12 -> 105 | H12: =Gantt!T14 -> 0.4 | I12: =IF(OR(F12=0,E12=0)," - ",NETWORKDAYS(E12,F12)) -> 75
A13: =Gantt!A15 -> 1.3 | B13: =Gantt!D15 -> Implementazione del modulo GARI-GIS per la gestione( nel contesto GIS) i dati importati dal SIAN relativi al PCG (nuovo sistema di riferimento wgs84) | E13: =Gantt!U15 -> 45536 | F13: =Gantt!X15 -> 45641 | G13: =F13-E13 -> 105 | H13: =Gantt!T15 -> 0.4 | I13: =IF(OR(F13=0,E13=0)," - ",NETWORKDAYS(E13,F13)) -> 75
A14: =Gantt!A16 -> 1.4 | B14: =Gantt!D16 -> Gestione delle Anagrafiche (risorse , macchine, analisi terreno etc) | E14: =Gantt!U16 -> 45488 | F14: =Gantt!X16 -> 45590 | G14: =F14-E14 -> 102 | H14: =Gantt!T16 -> 0.9 | I14: =IF(OR(F14=0,E14=0)," - ",NETWORKDAYS(E14,F14)) -> 75
A15: =Gantt!A17 -> 1.5 | B15: =Gantt!D17 -> Implementazione del Modulo di Gestione dei documenti funzionale ai moduli GARI (Evolutive, installazione, configurazione/setting e profilazione utenza) | E15: =Gantt!U17 -> 45355 | F15: =Gantt!X17 -> 45641 | G15: =F15-E15 -> 286 | H15: =Gantt!T17 -> 0.9 | I15: =IF(OR(F15=0,E15=0)," - ",NETWORKDAYS(E15,F15)) -> 205
A16: =Gantt!A18 -> 2 | B16: =Gantt!D18 -> GARI PA - UMA
A17: =Gantt!A19 -> 2.1 | B17: =Gantt!D19 -> RILASCIO 1 - Rif. Doc. fase unica PT000849TECH001 | E17: =Gantt!U19 -> 45246 | F17: =Gantt!X19 -> 45278 | G17: =F17-E17 -> 32 | H17: =Gantt!T19 -> 1 | I17: =IF(OR(F17=0,E17=0)," - ",NETWORKDAYS(E17,F17)) -> 23
A18: =Gantt!A20 -> 2.2 | B18: =Gantt!D20 -> RILASCIO 2 - Rif. Doc. fase unica PT000849TECH001 | E18: =Gantt!U20 -> 45297 | F18: =Gantt!X20 -> 45345 | G18: =F18-E18 -> 48 | H18: =Gantt!T20 -> 1 | I18: =IF(OR(F18=0,E18=0)," - ",NETWORKDAYS(E18,F18)) -> 35
A19: =Gantt!A21 -> 2.3 | B19: =Gantt!D21 -> RILASCIO 3 - Rif. Doc. fase unica PT000849TECH001 | E19: =Gantt!U21 -> 45357 | F19: =Gantt!X21 -> 45401 | G19: =F19-E19 -> 44 | H19: =Gantt!T21 -> 1 | I19: =IF(OR(F19=0,E19=0)," - ",NETWORKDAYS(E19,F19)) -> 33
A20: =Gantt!A22 -> 2.4 | B20: =Gantt!D22 -> RILASCIO 4 - Rif. Doc. fase unica PT000849TECH001 | E20: =Gantt!U22 -> 45388 | F20: =Gantt!X22 -> 45450 | G20: =F20-E20 -> 62 | H20: =Gantt!T22 -> 1 | I20: =IF(OR(F20=0,E20=0)," - ",NETWORKDAYS(E20,F20)) -> 45
A21: =Gantt!A23 -> 2.5 | B21: =Gantt!D23 -> RILASCIO 5 - Rif. Doc. fase unica PT000849TECH001 | E21: =Gantt!U23 -> 45449 | F21: =Gantt!X23 -> 45590 | G21: =F21-E21 -> 141 | H21: =Gantt!T23 -> 1 | I21: =IF(OR(F21=0,E21=0)," - ",NETWORKDAYS(E21,F21)) -> 102
A22: =Gantt!A24 -> 2.6 | B22: =Gantt!D24 -> UMA Re-ingegnerizzazione della piattaforma GIAS per implementare la nuova piattaforma GARI su nuove tecnologie introdotte con il paradigma PCG | E22: =Gantt!U24 -> 45566 | F22: =Gantt!X24 -> 45641 | G22: =F22-E22 -> 75 | H22: =Gantt!T24 -> 0.5 | I22: =IF(OR(F22=0,E22=0)," - ",NETWORKDAYS(E22,F22)) -> 54
A23: =Gantt!A25 -> 3 | B23: =Gantt!D25 -> GARI PUA
A24: =Gantt!A26 -> 3.1 | B24: =Gantt!D26 -> GARI-PUA Re-ingegnerizzazione della piattaforma GIAS per implementare la nuova piattaforma GARI su nuove tecnologie ( i.e tecnologia Angular) | E24: =Gantt!U26 -> 45352 | F24: =Gantt!X26 -> 45366 | G24: =F24-E24 -> 14 | H24: =Gantt!T26 -> 1 | I24: =IF(OR(F24=0,E24=0)," - ",NETWORKDAYS(E24,F24)) -> 11
A25: =Gantt!A27 -> 3.2 | B25: =Gantt!D27 -> Nuovo Modulo PUA incluso la interoperabilità con ACA per le 04 13 e 24 - Fase1 | E25: =Gantt!U27 -> 45454 | F25: =Gantt!X27 -> 45672 | G25: =F25-E25 -> 218 | H25: =Gantt!T27 -> 0.3 | I25: =IF(OR(F25=0,E25=0)," - ",NETWORKDAYS(E25,F25)) -> 157
A26: =Gantt!A28 -> 3.3 | B26: =Gantt!D28 -> Nuovo Modulo PUA collegamento e funzionamento su base PCG - Fase2 | E26: =Gantt!U28 -> 45454 | F26: =Gantt!X28 -> 45688 | G26: =F26-E26 -> 234 | H26: =Gantt!T28 -> 0.3 | I26: =IF(OR(F26=0,E26=0)," - ",NETWORKDAYS(E26,F26)) -> 169
A27: =Gantt!A29 -> 4 | B27: =Gantt!D29 -> GARI - QDCA
A28: =Gantt!A30 -> 4.1 | B28: =Gantt!D30 -> QCDA-Re-ingegnerizzazione della piattaforma GIAS per implementare la nuova piattaforma GARI su nuove tecnologie ( i.e tecnologia Angular) | E28: =Gantt!U30 -> 45352 | F28: =Gantt!X30 -> 45366 | G28: =F28-E28 -> 14 | H28: =Gantt!T30 -> 1 | I28: =IF(OR(F28=0,E28=0)," - ",NETWORKDAYS(E28,F28)) -> 11
A29: =Gantt!A31 -> 4.2 | B29: =Gantt!D31 -> Sviluppo SW GARI - Misure ACA | E29: =Gantt!U31 -> 45355 | F29: =Gantt!X31 -> 45641 | G29: =F29-E29 -> 286 | H29: =Gantt!T31 -> 0.4 | I29: =IF(OR(F29=0,E29=0)," - ",NETWORKDAYS(E29,F29)) -> 205
A30: =Gantt!A32 -> 4.3 | B30: =Gantt!D32 -> Sviluppo SW GARI - DSS per misure ACA | E30: =Gantt!U32 -> 45355 | F30: =Gantt!X32 -> 45641 | G30: =F30-E30 -> 286 | H30: =Gantt!T32 -> 0.4 | I30: =IF(OR(F30=0,E30=0)," - ",NETWORKDAYS(E30,F30)) -> 205
A31: =Gantt!A33 -> 4.4 | B31: =Gantt!D33 -> MEV - GARI QDCA - DSS - solo front-end (no algoritmi /API) + adeguamento salvataggio su GARI degli output relativi ai consigli dei Modelli Previsionali difesa e Irrigazione + Meteo (DSS) | E31: =Gantt!U33 -> 45355 | F31: =Gantt!X33 -> 45688 | G31: =F31-E31 -> 333 | H31: =Gantt!T33 -> 0.25 | I31: =IF(OR(F31=0,E31=0)," - ",NETWORKDAYS(E31,F31)) -> 240
A32: =Gantt!A34 -> 4.5 | B32: =Gantt!D34 -> Acquisizione, raccordo e verifica dei dati Meteo/DSS da sorgenti esterne | E32: =Gantt!U34 -> 45474 | F32: =Gantt!X34 -> 45747 | G32: =F32-E32 -> 273 | H32: =Gantt!T34 -> 0 | I32: =IF(OR(F32=0,E32=0)," - ",NETWORKDAYS(E32,F32)) -> 196
A33: =Gantt!A35 -> 4.6 | B33: =Gantt!D35 -> Acquisizione ,raccordo e verifica dei dati Meteo/DSS da sorgenti esterne | E33: =Gantt!U35 -> 45566 | F33: =Gantt!X35 -> 45838 | G33: =F33-E33 -> 272 | H33: =Gantt!T35 -> 0 | I33: =IF(OR(F33=0,E33=0)," - ",NETWORKDAYS(E33,F33)) -> 195
A34: =Gantt!A36 -> 4.7 | B34: =Gantt!D36 -> Report ARPA: dati di impiego dei prodotti fitosanitari | E34: =Gantt!U36 -> 45499 | F34: =Gantt!X36 -> 45657 | G34: =F34-E34 -> 158 | H34: =Gantt!T36 -> 0.4 | I34: =IF(OR(F34=0,E34=0)," - ",NETWORKDAYS(E34,F34)) -> 113
A35: =Gantt!A37 -> 4.8 | B35: =Gantt!D37 -> Revisione dei moduli QUADERNO SQNPI e BIO per essere utilizzabili e integrabili sulle nuove tecnologie introdotte con il paradigma PCG | E35: =Gantt!U37 -> 0 | F35: =Gantt!X37 -> 45703 | G35: =F35-E35 -> 45703 | H35: =Gantt!T37 -> 0.15 | I35: =IF(OR(F35=0,E35=0)," - ",NETWORKDAYS(E35,F35)) -> -
A36: =Gantt!A38 -> 4.9 | B36: =Gantt!D38 -> Attivazione registri bio nel contesto del QDCA GARI, setting, configurazioni, profilazioni utenti, ecc. | E36: =Gantt!U38 -> 45355 | F36: =Gantt!X38 -> 45641 | G36: =F36-E36 -> 286 | H36: =Gantt!T38 -> 0.8 | I36: =IF(OR(F36=0,E36=0)," - ",NETWORKDAYS(E36,F36)) -> 205
B37: =Gantt!D39 -> ATTIVITA' DI CARATTERE CONTINUATIVO (NON PROGETTUALE) | I37: =IF(OR(F37=0,E37=0)," - ",NETWORKDAYS(E37,F37)) -> -
A38: =Gantt!A40 -> 5 | B38: =Gantt!D40 -> SERVIZI DI SUPPORTO SPECIALISTICO APPLICATIVO | I38: =IF(OR(F38=0,E38=0)," - ",NETWORKDAYS(E38,F38)) -> -
A39: =Gantt!A41 -> 5.1 | B39: =Gantt!D41 -> Supporto Specialistico 2024
A40: =Gantt!A42 -> 5.1.1 | B40: =Gantt!D42 -> Supporto Specialistico - I TRIM 2024 | E40: =Gantt!U42 -> 45292 | F40: =Gantt!X42 -> 45382 | G40: =F40-E40 -> 90 | H40: =Gantt!T42 -> 1 | I40: =IF(OR(F40=0,E40=0)," - ",NETWORKDAYS(E40,F40)) -> 65
A41: =Gantt!A43 -> 5.1.2 | B41: =Gantt!D43 -> Supporto Specialistico - II TRIM 2024 | E41: =Gantt!U43 -> 45383 | F41: =Gantt!X43 -> 45473 | G41: =F41-E41 -> 90 | H41: =Gantt!T43 -> 1 | I41: =IF(OR(F41=0,E41=0)," - ",NETWORKDAYS(E41,F41)) -> 65
A42: =Gantt!A44 -> 5.1.3 | B42: =Gantt!D44 -> Supporto Specialistico - III TRIM 2024 | E42: =Gantt!U44 -> 45474 | F42: =Gantt!X44 -> 45565 | G42: =F42-E42 -> 91 | H42: =Gantt!T44 -> 1 | I42: =IF(OR(F42=0,E42=0)," - ",NETWORKDAYS(E42,F42)) -> 66
...

Sheet Sintesi Rendiconti
B1: LEONARDO | C1: DXC | D1: ABACO | E1: E-GEOS | F1: GREEN-AUS
A3: ANNO 2023 | J3: STATO
A4: IV Trimestre 2023
H5: TOTALE
A6: Servizi Applicativi | B6: 0 | C6: 0 | E6: 0 | F6: ='Riepilogo Contratto'!D4 -> 174540 | H6: =SUM(B6:F6) -> 174540
A7: Servzi Infrastrutturali | B7: 0 | C7: 0 | E7: 0 | F7: 0 | H7: =SUM(B7:F7) -> 0
A8: Servizi di supporto specialistico | B8: ='Riepilogo Contratto'!D8 -> 0 | C8: 0 | E8: 0 | F8: 0 | H8: =SUM(B8:F8) -> 0
A9: Call Center | B9: ='Riepilogo Contratto'!D9 -> 0 | C9: 0 | E9: 0 | F9: 0 | H9: 0
A11: TOTALI | B11: =SUM(B6:B9) -> 0 | C11: 0 | D11: =SUM(D6:D9) -> 0 | E11: =SUM(E6:E9) -> 0 | F11: =SUM(F6:F9) -> 174540 | H11: =SUM(H6:H9) -> 174540 | J11: Compilati
A13: TOTALE ANNO 2023 | B13: =B11 -> 0 | C13: =C11 -> 0 | D13: =D11 -> 0 | E13: =E11 -> 0 | F13: =F11 -> 174540 | H13: =H11 -> 174540 | J13: Compilati
A15: ANNO 2024
A16: I Trimestre 2024
H17: TOTALE
A18: Servizi Applicativi | B18: ='Riepilogo Contratto'!E29 -> 229483 | C18: 0 | D18: 0 | E18: 0 | F18: 0 | H18: 0
A19: Servzi Infrastrutturali | B19: 0 | C19: 0 | D19: 0 | E19: 0 | F19: 0 | H19: 0
A20: Servizi di supporto specialistico | B20: =Gantt!J42 -> 10729.5 | C20: 0 | D20: 0 | E20: 0 | F20: 0 | H20: 0
A21: Call Center | B21: =Gantt!J50 -> 8750 | C21: 0 | D21: 0 | E21: 0 | F21: 0 | H21: 0
A23: TOTALI | B23: =SUM(B18:B21) -> 248962.5 | C23: =SUM(C18:C21) -> 0 | D23: =SUM(D18:D21) -> 0 | E23: 0 | F23: 0 | H23: =SUM(B23:F23) -> 248962.5 | J23: Compilati
A24: II Trimestre 2024
H25: TOTALE
A26: Servizi Applicativi | B26: ='Riepilogo Contratto'!F29 -> 21074 | C26: 0 | E26: 0 | F26: 0 | H26: 0
A27: Servzi Infrastrutturali | B27: 0 | C27: 0 | E27: 0 | F27: 0 | H27: 0
A28: Servizi di supporto specialistico | B28: ='Riepilogo Contratto'!F33 -> 10729.5 | C28: 0 | E28: 0 | F28: 0 | H28: 0
A29: Call Center | B29: ='Riepilogo Contratto'!F34 -> 8750 | C29: 0 | D29: 0 | E29: 0 | F29: 0 | H29: 0
A31: TOTALI | B31: =SUM(B26:B29) -> 40553.5 | C31: =SUM(C26:C29) -> 0 | D31: =SUM(D26:D29) -> 0 | E31: =SUM(E26:E29) -> 0 | F31: =SUM(F26:F29) -> 0 | H31: =SUM(B31:F31) -> 40553.5 | J31: Compilati
A32: III Trimestre 2024
H33: TOTALE
A34: Servizi Applicativi | B34: ='Riepilogo Contratto'!G29 -> 0 | C34: 0 | D34: 0 | E34: 0 | F34: 0 | H34: 78296.75
A35: Servzi Infrastrutturali | B35: 0 | C35: 0 | D35: 0 | E35: 0 | F35: 0 | H35: 6406.2
A36: Servizi di supporto specialistico | B36: ='Riepilogo Contratto'!G33 -> 10729.5 | C36: 0 | D36: 0 | E36: 0 | F36: 0 | H36: 23550.75
A37: Call Center | B37: ='Riepilogo Contratto'!G34 -> 8750 | C37: 0 | D37: 0 | E37: 0 | F37: 0 | H37: 0
A39: TOTALI | B39: =SUM(B34:B37) -> 19479.5 | C39: =SUM(C34:C37) -> 0 | D39: =SUM(D34:D37) -> 0 | E39: =SUM(E34:E37) -> 0 | F39: =SUM(F34:F37) -> 0 | H39: =SUM(B39:F39) -> 19479.5
A40: IV Trimestre 2024
B41: LEONARDO | C41: DXC | D41: ABACO | E41: E-GEOS | F41: GREEN-AUS | H41: TOTALE
A42: Servizi Applicativi | B42: 0 | C42: 0 | D42: 0 | E42: 0 | F42: 0 | H42: =SUM(B42:F42) -> 0
A43: Servzi Infrastrutturali | B43: 0 | C43: 0 | E43: 0 | F43: 0 | H43: =SUM(B43:F43) -> 0
A44: Servizi di supporto specialistico | B44: 0 | C44: 0 | D44: 0 | E44: 0 | F44: 0 | H44: =SUM(B44:F44) -> 0
A45: Call Center | B45: 0 | C45: 0 | D45: 0 | E45: 0 | F45: 0 | H45: 0
A47: TOTALI | B47: 0 | C47: 0 | D47: 0 | E47: =SUM(E42:E45) -> 0 | F47: =SUM(F42:F45) -> 0 | H47: =SUM(H42:H45) -> 0
A49: TOTALE ANNO 2024 | B49: =SUM(B23,B31,B39,B47) -> 308995.5 | C49: =SUM(C23,C31,C39,C47) -> 0 | D49: =SUM(D23,D31,D39,D47) -> 0 | E49: =SUM(E23,E31,E39,E47) -> 0 | F49: =SUM(F23,F31,F39,F47) -> 0 | H49: =SUM(H23,H31,H39,H47) -> 308995.5

Sheet Gantt
D1: Non è possibile ripartire le economie o le poste economiche di cose non realizzate nelle altre Voci aumentando gli importi rispetto al Piano precedente a parità della attività indicate!!!!! Gli impegni economici non impiegati vanno un una sezione del piano "Residui di Progetto" che sono a discrezione del RUP per riposizionare nuove attività o sviluppare ulteriormente quelle già in corso ma non nuove cose rispetto a quelle già previste che mantegono la previsione indicata e approvata. Questo per ASSICURARE UN CRITERIO DI CONGRUITA' ESENZIALE IN QUESTO CONTESTO PERCHè NON ESISTONO DOCUMENTI DI DETTAGLIO CHE GIUSTIFICHINI LO STUDIO DEL VALORE E L'APPROVAZIONE. In pratica se io approvo una voce nel Piano ver. 1 e non la faccio nel Piano ver.2 non può combiare prezzo a parità di lavoro se no quella precedente non era congruità!!!!!
I2: Previsione di Spesa | M2: Riferimenti rendicontazione
A3: ID | B3: Predecessore /vincoli | D3: Titolo attività | E3: Obiettivo/Intervento | F3: Piano di lavoro obiettivo | G3: Deliverable Associato | I3: IV TRIM 2023 | J3: 2024 | K3: I SEM 2025 | L3: TOTALE | M3: Rendicontato effettivo (consuntivo) | N3: Servizio | O3: Trimestre riferimento rendicontazione | P3: Anno rendicontazione | Q3: Percentuale rendicontazione | R3: STATO | S3: Ownership | T3: % Completamento | U3: Data Ricezione Richiesta Intervento | V3: Data Consegna Documentazione da parte RTI | W3: Data Accettazione Documentazione | X3: Data di pronti al Collaudo | Y3: Data rilascio in Produzione | Z3: Note
D4: Definizione precondizioni operative | R4: DA RIPIANIFICARE
D5: Disponibilità Piattaforma GARI BASE | R5: COMPLETATO | S5: Leonardo | T5: 1 | U5: 45224
D6: PRESA IN CARICO | R6: COMPLETATO | S6: Leonardo | T6: 1
D7: Incontri con Amministrazione | R7: COMPLETATO | S7: Leonardo | T7: 1
D8: Knowledge Transfer | R8: COMPLETATO | S8: Leonardo | T8: 1
D9: Consegna e Convalida | R9: COMPLETATO | S9: Leonardo | T9: 1
D10: SERVIZI APPLICATIVI - ATTIVITA' DI CARATTERE PROGETTUALE (Sviluppo SW + MEV+Supporto Specialistico Operativo) | I10: =SUM(I11,I12,I18,I29,I25,I40) -> 174540 | J10: =SUM(J11,J12,J18,J29,J25) -> 873360 | K10: =SUM(K11,K12,K18,K29,K25) -> 370000 | L10: =SUM(I10,J10,K10) -> 1417900
A11: 0 | C11: Liquidabile a completamento note concordate | D11: MEV GARI-PA per porting (IV TRIM 23) su nuovo ambiente di tutti i moduli (BASE, PUA, QDCA, UMA) | G11: Specifiche Progettazione RU-9992150707-BASE-SP-01.01 del 31/12/2023 Specifiche Progettazione RU-9992150707-UMA-SP-01.01 del 31/12/2023 Specifiche Progettazione RU-9992150707-PUA-SP-01.01 del 31/12/2023 Specifiche Progettazione RU-9992150707-QUAD-SP-01.01 del 31/12/2023 | H11: Per chiudere questa operazione e accettare il punto 1.1 occorre: • la documentazione della ver.20.02 come messa a punto delle SOLE non conformità sollevate con il collaudo ufficiale del 22 gennaio 2024; • Risistemazione di tutti i documenti già trasmessi secondo le indicazioni ricevute dopo la lettura degli stessi da parte della Regione e delle indicazioni inviate; • rilascio nell’ambiente cloud test/collaudo e nel Repository del codice Sorgente, del codice compilato e della documentazione già prodotta e sistemata versionata come 01.01, come consegna del prodotto Open source commissionato da Regione ad RTI per la continuità di servizio dell’ex GIAS e collaudato il 22 gennaio 2024 con verbale registrato. Per i documenti vedi la nota già mandata nei giorni passati con i tipi di documenti previsti per i rilascio del software GARI; • Verbale della presa d’atto (probabilmente che faremo in questo mese) del rilascio della versione 01.01 con le no conformità non risolte | I11: 99852 | K11: 0 | L11: =SUM(I11:K11) -> 99852 | M11: =I11 -> 99852 | N11: MEV | O11: IV TRIMESTRE 2023 | P11: 2023 | Q11: =M11/L11 -> 1 | R11: RILASCIATO IN ESERCIZIO | S11: Abaco | T11: =M11/I11 -> 1 | U11: 45231 | W11: 45291 | X11: 45313 | Y11: 45330
A12: 1 | D12: GARI BASE | I12: =SUM(I13:I17) -> 0 | J12: =SUM(J13:J17) -> 450000 | K12: =SUM(K13:K17) -> 0 | L12: =SUM(I12:K12) -> 450000 | M12: =SUM(M13:M17) -> 70000
A13: 1.1 | C13: Autorizzato a seguiito della produziine del documeno di anlisi del'archiettura GARI/SIAN grafico con servizi di interoperabilità e presenza Fascicolo SIAN/GARI esteso | D13: GARI-BASE Re-ingegnerizzazione della piattaforma GIAS per implementare la nuova piattaforma GARI su nuove tecnologie ( i.e tecnologia Angular) | E13: Previsto da Progetto dei Fabbisogni | G13: Specifiche Progettazione RU-9992150707-BASE-SP-02.00 | H13: Manca documento archietturale Ver.02.00 modificato come concordato per valutare l'ambiente rilasciato e le caratteristiche di superamento dellle osservazioni presenti nel verbale del 22 gennaio, presa in carico del open source consegnato dal RTI a Regione Umbria | J13: 70000 | L13: =SUM(I13:K13) -> 70000 | M13: 70000 | N13: Conduzione applicativa(Consumo) | O13: I TRIMESTRE 2024 | P13: 2024 | Q13: =M13/L13 -> 1 | R13: RILASCIATO IN ESERCIZIO | S13: Abaco | T13: =M13/J13 -> 1 | U13: 45299 | V13: 45569 | W13: 45366 | X13: 45366 | Y13: 45382
A14: 1.2 | D14: Sviluppo funzionalità di Interlavoro con il sistema SIAN per importare il Piano colturale Grafico AGEA, compendiato dagli attributi catastali alfanumerici e altre informazioni legate alle consistenze aziendali funzionali alla gestione GARI Con acquisizione dei dati di fascicolo necessari ai procedimenti del GARI se e come esposti da AGEA. | E14: Previsto da Progetto dei Fabbisogni | F14: Documento in redazione | G14: Documento in redazione | H14: Manca il documento di specifiche tecniche GARI per la realizzazione di questa progettualità del GARI BAsE. Non è stato rilasciato dal RTI alcun documento tecnico a corredo che consente una approvazione a procedere da parte della Regione o comunque che ne testimonia la conoscenza. il documento rilasciato a "marzo" come ver.02 è lontano molto, troppo dal quello che è stato presentato nelle slide delle scorse settimane e in ogni caso non è documentato da alcun documento di cui la Regione è in possesso che può giustificare la frase "in corso" pertanto è ESSENZIALE che sia rilasciato entro questo mese per poter essere considerato con questo appellativo | J14: 95000 | L14: =SUM(I14:K14) -> 95000 | N14: Sviluppo software | O14: IV TRIMESTRE 2024 | P14: 2024 | Q14: =M14/L14 -> 0 | R14: IN CORSO | S14: Abaco | T14: 0.4 | U14: 45536 | X14: 45641
A15: 1.3 | D15: Implementazione del modulo GARI-GIS per la gestione( nel contesto GIS) i dati importati dal SIAN relativi al PCG (nuovo sistema di riferimento wgs84) | E15: Previsto da Progetto dei Fabbisogni | G15: Documento in redazione | J15: 185000 | L15: =SUM(I15:K15) -> 185000 | M15: 0 | N15: MEV | O15: IV TRIMESTRE 2024 | P15: 2024 | Q15: =M15/L15 -> 0 | R15: IN CORSO | S15: Abaco | T15: 0.4 | U15: 45536 | X15: 45641
A16: 1.4 | D16: Gestione delle Anagrafiche (risorse , macchine, analisi terreno etc) | E16: Previsto da Progetto dei Fabbisogni | G16: Documento in redazione | J16: 55000 | L16: =SUM(I16:K16) -> 55000 | M16: 0 | N16: Sviluppo software | O16: IV TRIMESTRE 2024 | P16: 2024 | Q16: =M16/L16 -> 0 | R16: IN CORSO | S16: Abaco | T16: 0.9 | U16: 45488 | X16: 45590
A17: 1.5 | D17: Implementazione del Modulo di Gestione dei documenti funzionale ai moduli GARI (Evolutive, installazione, configurazione/setting e profilazione utenza) | E17: Previsto da Progetto dei Fabbisogni | F17: Piano Lavoro Obiettivo -GARI Umbria - Interventi ACA Rev.01.00 | G17: Documento di FASE UNICA RU-9992150707-ACA-FU-01.02 del 01/08/2024 | J17: 45000 | L17: =SUM(I17:K17) -> 45000 | M17: 0 | N17: Sviluppo software | O17: IV TRIMESTRE 2024 | P17: 2024 | Q17: =M17/L17 -> 0 | R17: IN CORSO | S17: Abaco | T17: 0.9 | U17: 45355 | V17: 45574 | X17: 45641
A18: 2 | C18: Liquidabile a completamento note concordate | D18: GARI PA - UMA | I18: =SUM(I19:I24) -> 74688 | J18: =SUM(J19:J24) -> 90752 | K18: =SUM(K19:K24) -> 0 | L18: =SUM(I18:K18) -> 165440 | M18: 8750
A19: 2.1 | D19: RILASCIO 1 - Rif. Doc. fase unica PT000849TECH001 | E19: Scheda richiesta intervento 16_11_23 - GIAS-PA UMA-Rev.1.1 del 16/11/2023 | F19: Piano Lavoro Obiettivo- Gestione UMA 1 | G19: Nuovi Sviluppi UMA - DOCUMENTAZIONE FASE UNICA Rev. 2.1 del 15/01/2024 | H19: Per chiudere e liquidare questo: • Comunicazione e certificazione della installazione del modulo UMA 2024 finale nel Cloud di Esercizio; • Disponibilità del manuale uso utente rilasciato per gli utilizzatori; • inserimento nel Repository regionale della documentazione finale di rilascio prevista per i software posti in esercizio, con verbale congiunto di constatazione e presa in carico del gruppo di lavoro dell’Help Desk di primo livello; • Definizione e verifica dei documenti amministrativi di chiusura, presa in carico del prodotto per la liquidazione dell’importo complessivo UMA previsto dal progetto 2023/2024; • Predisposizione e rilascio del Piano di Assistenza per l’UMA in esercizio da rendicontare nell’assistenza applicativa prevista dal contratto. | I19: 74688 | J19: 0 | K19: 0 | L19: =SUM(I19:K19) -> 74688 | M19: =I19 -> 74688 | N19: Sviluppo software | O19: IV TRIMESTRE 2023 | P19: 2023 | Q19: =M19/L19 -> 1 | R19: RILASCIATO IN ESERCIZIO | S19: Abaco | T19: 1 | U19: 45246 | V19: 45569 | W19: 45306 | X19: 45278 | Y19: 45329
A20: 2.2 | D20: RILASCIO 2 - Rif. Doc. fase unica PT000849TECH001 | E20: Scheda richiesta intervento 16_11_23 - GIAS-PA UMA-Rev.1.1 del 16/11/2023 | F20: Piano Lavoro Obiettivo- Gestione UMA 2 | G20: Nuovi Sviluppi UMA - DOCUMENTAZIONE FASE UNICA Rev. 2.3 del 23/02/2024 | I20: 0 | J20: 29483 | L20: =SUM(I20:K20) -> 29483 | M20: =J20 -> 29483 | N20: Sviluppo software | O20: I TRIMESTRE 2024 | P20: =IF(Y20="-","-",TEXT(Y20,"aaaa")) -> 2024 | Q20: =M20/L20 -> 1 | R20: RILASCIATO IN ESERCIZIO | S20: Abaco | T20: 1 | U20: 45297 | V20: 45569 | W20: 45345 | X20: 45345 | Y20: 45359
A21: 2.3 | D21: RILASCIO 3 - Rif. Doc. fase unica PT000849TECH001 | E21: Scheda richiesta intervento 16_11_23 - GIAS-PA UMA-Rev.1.1 del 16/11/2023 | F21: Piano Lavoro Obiettivo- Gestione UMA 3 | G21: Nuovi Sviluppi UMA - DOCUMENTAZIONE FASE UNICA Rev. 2.4 del 19/04/2024 | I21: 0 | J21: 10002 | L21: =SUM(I21:K21) -> 10002 | M21: =J21 -> 10002 | N21: Sviluppo software | O21: II TRIMESTRE 2024 | P21: 2024 | Q21: =M21/L21 -> 1 | R21: RILASCIATO IN ESERCIZIO | S21: Abaco | T21: 1 | U21: 45357 | V21: 45569 | W21: 45401 | X21: 45401 | Y21: 45415
A22: 2.4 | D22: RILASCIO 4 - Rif. Doc. fase unica PT000849TECH001 | E22: Scheda richiesta intervento 16_11_23 - GIAS-PA UMA-Rev.1.1 del 16/11/2023 | F22: Piano Lavoro Obiettivo- Gestione UMA 4 | G22: Nuovi Sviluppi UMA - DOCUMENTAZIONE FASE UNICA Rev. 2.5 del 07/06/2024 | I22: 0 | J22: 11072 | L22: =SUM(I22:K22) -> 11072 | M22: =J22 -> 11072 | N22: Sviluppo software | O22: II TRIMESTRE 2024 | P22: 2024 | Q22: =M22/L22 -> 1 | R22: RILASCIATO IN ESERCIZIO | S22: Abaco | T22: 1 | U22: 45388 | V22: 45569 | W22: 45450 | X22: 45450 | Y22: 45460
A23: 2.5 | D23: RILASCIO 5 - Rif. Doc. fase unica PT000849TECH001 | E23: Scheda richiesta intervento 16_11_23 - GIAS-PA UMA-Rev.1.1 del 16/11/2023 | F23: Piano Lavoro Obiettivo - Gestione UMA 5 | G23: Nuovi Sviluppi UMA - DOCUMENTAZIONE FASE UNICA Rev. 2.6 | I23: 0 | J23: 5195 | L23: =SUM(I23:K23) -> 5195 | M23: 0 | N23: Sviluppo software | O23: IV TRIMESTRE 2024 | P23: 2024 | Q23: =M23/L23 -> 0 | R23: ESITO POSITIVO AL COLLAUDO | S23: Abaco | T23: 1 | U23: 45449 | V23: 45569 | X23: 45590 | Y23: 45596
A24: 2.6 | C24: Predisporre un docuimento ad hoc integrando anche esigenze gestionali 2025 | D24: UMA Re-ingegnerizzazione della piattaforma GIAS per implementare la nuova piattaforma GARI su nuove tecnologie introdotte con il paradigma PCG | E24: Previsto da Progetto dei Fabbisogni per quanto concerne il passaggio all'utilizzo del PCG. | G24: Documento in redazione | J24: 35000 | L24: =SUM(I24:K24) -> 35000 | M24: 0 | N24: Conduzione applicativa(Consumo) | O24: IV TRIMESTRE 2024 | P24: 2024 | Q24: =M24/L24 -> 0 | R24: IN CORSO | S24: Abaco | T24: 0.5 | U24: 45566 | X24: 45641 | Y24: 45657
A25: 3 | D25: GARI PUA | I25: =SUM(I26:I28) -> 0 | J25: =SUM(J26:J28) -> 30000 | K25: =SUM(K26:K28) -> 200000 | L25: =SUM(I25:K25) -> 230000 | M25: =SUM(M26:M28) -> 30000
A26: 3.1 | C26: Autorizzato dopo incontri e rilascio documento unico comprensivo porting UMA in GARI BASE grafico | D26: GARI-PUA Re-ingegnerizzazione della piattaforma GIAS per implementare la nuova piattaforma GARI su nuove tecnologie ( i.e tecnologia Angular) | E26: Previsto da Progetto dei Fabbisogni | G26: Specifiche Progettazione RU-9992150707-PUA-SP-02.00 | H26: NO! va tutto previsto nel documento di proposta del PUA come è stato prodotto dal RTI e va completato con quanto previsto al punto 3.1 Necessario perché esistono PEC della Regione che contestano la non autorizzazione del punto 3.1 | J26: 30000 | L26: =SUM(I26:K26) -> 30000 | M26: =J26 -> 30000 | N26: Conduzione applicativa(Consumo) | O26: I TRIMESTRE 2024 | P26: 2024 | Q26: =M26/L26 -> 1 | R26: RILASCIATO IN ESERCIZIO | S26: Abaco | T26: =M26/J26 -> 1 | U26: 45352 | V26: 45569 | X26: 45366 | Y26: 45382
A27: 3.2 | D27: Nuovo Modulo PUA incluso la interoperabilità con ACA per le 04 13 e 24 - Fase1 | E27: Scheda richiesta intervento GARI Umbria PUA-Rev.1.0 del 11/06/2024 | F27: Piano Lavoro Obiettivo - Sviluppi PUA | G27: Documento di FASE UNICA RU-9992150707-PUA-Sviluppi-FU-01.00 del 24/07/2024 | K27: 175000 | L27: =SUM(I27:K27) -> 175000 | M27: 0 | N27: Sviluppo software | O27: I TRIMESTRE 2025 | P27: 2025 | Q27: =M27/L27 -> 0 | R27: IN CORSO | S27: Abaco | T27: 0.3 | U27: 45454 | V27: 45574 | X27: 45672
A28: 3.3 | D28: Nuovo Modulo PUA collegamento e funzionamento su base PCG - Fase2 | E28: Scheda richiesta intervento GARI Umbria PUA-Rev.1.0 del 11/06/2024 | F28: Piano Lavoro Obiettivo - Sviluppi PUA | G28: Documento di FASE UNICA RU-9992150707-PUA-Sviluppi-FU-01.00 del 24/07/2024 | K28: 25000 | L28: =SUM(I28:K28) -> 25000 | M28: 0 | N28: MEV | O28: I TRIMESTRE 2025 | P28: 2025 | Q28: =M28/L28 -> 0 | R28: IN CORSO | S28: Abaco | T28: 0.3 | U28: 45454 | V28: 45574 | X28: 45688
A29: 4 | D29: GARI - QDCA | I29: =SUM(I30:I38) -> 0 | J29: =SUM(J30:J38) -> 302608 | K29: =SUM(K30:K38) -> 170000 | L29: =SUM(I29:K29) -> 472608 | M29: =SUM(M30:M38) -> 100000
A30: 4.1 | C30: Autorizzato dopo incontri e rilascio documento unico comprensivo porting QUAD (41. 4.8 4.9 ) comprensivo di Quade poriting in ambiente gaio grafico | D30: QCDA-Re-ingegnerizzazione della piattaforma GIAS per implementare la nuova piattaforma GARI su nuove tecnologie ( i.e tecnologia Angular) | E30: Previsto da Progetto dei Fabbisogni | G30: Specifiche Progettazione RU-9992150707-QUAD-SP-02.00 | H30: NO! va previsto come da avviare nel documento ACA (4.2. e 4.3) come ingegnerizzazione del modulo della var. 1 per gli sviluppi della ver 2 Necessario perché esistono PEC della Regione che contestano la non autorizzazione del punto 3.1 | J30: 100000 | L30: =SUM(I30:K30) -> 100000 | M30: 100000 | N30: Conduzione applicativa(Consumo) | O30: I TRIMESTRE 2024 | P30: 2024 | Q30: =M30/L30 -> 1 | R30: RILASCIATO IN ESERCIZIO | S30: Abaco | T30: =M30/J30 -> 1 | U30: 45352 | V30: 45569 | X30: 45366 | Y30: 45382
A31: 4.2 | D31: Sviluppo SW GARI - Misure ACA | E31: GARI Umbria Interventi ACA rev 01.00 ( ricevuta via pec del 04/03/2024) | F31: Piano Lavoro Obiettivo -GARI Umbria - Interventi ACA Rev.01.00 | G31: Documento di FASE UNICA RU-9992150707-ACA-FU-01.02 del 01/08/2024 | H31: Come da documento presentato e approvato tecnicamente e per cui occorre procedere con: • Piano degli interventi di sviluppo software e dei rilasci previsti per rispondere alle esigenze • Piano di installazione del modulo/servizi SQNPI nel cloud di esercizio del GARI, secondo il processo di attivazione dell’uso della funzionalità concordato nelle riunioni del 4 e del 5 novembre • Quadro del dettaglio dei costi gli interventi complessivi previsti per gli sviluppi e per l’attivazione del modulo/servizi • Piano di formazione degli utenti e di rilascio della documentazione d’uso del prodotto • Elenco degli output complessivi previsti dall’attività della proposta (sorgente, compilato, documenti) | J31: 142608 | L31: =SUM(I31:K31) -> 142608 | M31: 0 | N31: Sviluppo software | O31: IV TRIMESTRE 2024 | P31: 2024 | Q31: =M31/L31 -> 0 | R31: IN CORSO | S31: Abaco | T31: 0.4 | U31: 45355 | V31: 45574 | X31: 45641
A32: 4.3 | D32: Sviluppo SW GARI - DSS per misure ACA | E32: GARI Umbria Interventi ACA rev 01.00 ( ricevuta via pec del 04/03/2024) | F32: Piano Lavoro Obiettivo - Gestione ACA DSS | G32: Documento di FASE UNICA RU-9992150707-ACA_DSS-FU-01.00 del 14/06/2024 | J32: 22500 | L32: =SUM(I32:K32) -> 22500 | M32: 0 | N32: Sviluppo software | O32: IV TRIMESTRE 2024 | P32: 2024 | Q32: =M32/L32 -> 0 | R32: IN CORSO | S32: Abaco | T32: 0.4 | U32: 45355 | X32: 45641
A33: 4.4 | C33: Autorizzato | D33: MEV - GARI QDCA - DSS - solo front-end (no algoritmi /API) + adeguamento salvataggio su GARI degli output relativi ai consigli dei Modelli Previsionali difesa e Irrigazione + Meteo (DSS) | E33: GARI Umbria Interventi ACA rev 01.00 ( ricevuta via pec del 04/03/2024) | F33: Piano Lavoro Obiettivo - Gestione ACA DSS | G33: Documento di FASE UNICA RU-9992150707-ACA_DSS-FU-01.00 del 14/06/2024 | H33: DA PREVEDERE NEL PIANO LAVORO OBIETTIVO 1. documento tecniconell'ultima versione del RTI come valutazione tecnico funzionale del modello di servizio rilasciato nel GARI. A riguardo è essenziale che il GARI / DSS abbia strumenti e canali digitali di richiesta partendo dai dati delle Aziende, in grado di assumere, registrare e conservare elaborati/ documentali; 2. A compendio dovrà essere previsto un contesto professionale del RTI a supporto e in grado di assicurare il change management ad una struttura composta da personale di uffici regionale del fitosanitario e/o dei colleghi referenti ACA (fertilizzazione e irrigazione) sull'utilizzo dell'ambiente e dei relativi servizi in assistenza dell'utenza territoriale | K33: 60000 | L33: =SUM(I33:K33) -> 60000 | M33: =J33 -> 0 | N33: MEV | O33: I TRIMESTRE 2025 | P33: 2025 | Q33: =M33/L33 -> 0 | R33: IN CORSO | S33: Abaco | T33: 0.25 | U33: 45355 | X33: 45688
A34: 4.5 | D34: Acquisizione, raccordo e verifica dei dati Meteo/DSS da sorgenti esterne | E34: GARI Umbria Interventi ACA rev 01.00 ( ricevuta via pec del 04/03/2024) | G34: N.A. | J34: 0 | K34: 15000 | L34: =SUM(I34:K34) -> 15000 | M34: 0 | N34: Conduzione applicativa(Consumo) | O34: I TRIMESTRE 2025 | P34: 2025 | Q34: =M34/L34 -> 0 | R34: DA AVVIARE | S34: Abaco | T34: 0 | U34: 45474 | X34: 45747
A35: 4.6 | D35: Acquisizione ,raccordo e verifica dei dati Meteo/DSS da sorgenti esterne | E35: GARI Umbria Interventi ACA rev 01.00 ( ricevuta via pec del 04/03/2024) | G35: N.A. | J35: 0 | K35: 15000 | L35: =SUM(I35:K35) -> 15000 | M35: 0 | N35: Conduzione applicativa(Consumo) | O35: II TRIMESTRE 2025 | P35: 2025 | Q35: =M35/L35 -> 0 | R35: DA AVVIARE | S35: Abaco | T35: 0 | U35: 45566 | X35: 45838
A36: 4.7 | D36: Report ARPA: dati di impiego dei prodotti fitosanitari | E36: GARI Umbria - Intervento dati impiego fitosanitari - pec del 1/8/2024 | F36: Piano Lavoro Obiettivo - Report Fitosanitari | G36: Documento di FASE UNICA RU-9992150707-QUAD-Report_Fito-FU-01.00 del 28/08/2024 | H36: Da capire come procedere alla luce di quanto scritto dal DEC | J36: 17500 | L36: =SUM(I36:K36) -> 17500 | M36: 0 | N36: MEV | O36: IV TRIMESTRE 2024 | P36: 2024 | Q36: =M36/L36 -> 0 | R36: IN CORSO | S36: Abaco | T36: 0.4 | U36: 45499 | V36: 45574 | X36: 45657
A37: 4.8 | C37: vedi nota 4.1 | D37: Revisione dei moduli QUADERNO SQNPI e BIO per essere utilizzabili e integrabili sulle nuove tecnologie introdotte con il paradigma PCG | E37: Previsto da Progetto dei Fabbisogni per quanto concerne il passaggio all'utilizzo del PCG. | G37: Documento in redazione | H37: Questo va inserito ormai nel documento compelssivo SQNPI / ACA di cui ai punti 31. 3.2 3.3 | K37: 80000 | L37: =SUM(I37:K37) -> 80000 | M37: 0 | N37: MEV | O37: I TRIMESTRE 2025 | P37: 2025 | Q37: =M37/L37 -> 0 | R37: IN CORSO | S37: Abaco | T37: 0.15 | X37: 45703
A38: 4.9 | D38: Attivazione registri bio nel contesto del QDCA GARI, setting, configurazioni, profilazioni utenti, ecc. | E38: GARI Umbria Interventi ACA rev 01.00 ( ricevuta via pec del 04/03/2024) | F38: Piano Lavoro Obiettivo - Gestione SRA ACA | G38: Documento di FASE UNICA RU-9992150707-ACA-FU-01.02 del 01/08/2024 | J38: 20000 | K38: 0 | L38: =SUM(I38:K38) -> 20000 | M38: =K38 -> 0 | N38: MEV | O38: IV TRIMESTRE 2024 | P38: 2024 | Q38: =M38/L38 -> 0 | R38: IN CORSO | S38: Abaco | T38: 0.8 | U38: 45355 | V38: 45574 | X38: 45641
C39: Predisporre un Piano di esercizio e produrre i SAL trimestrale delle attività sulla bsa della caratterizzazione dei profili professionali previsit | D39: ATTIVITA' DI CARATTERE CONTINUATIVO (NON PROGETTUALE) | H39: Per questa sezione di progetto deve essere previsto un vero e proprio PIANO di LAVORO OBIETTIVO in cui siano descritti e aggiornati, a seguito di rilasci del software incrementale, i servizi resi e le modalità di erogazione. Questo piano trimestralmente come indicato nelle righe sotto va rendicontato con un documento apposito che possiamo condividere ci sono modelli usati a riguardo in altri progetti, semplici ed efficaci. | I39: =SUM(I40,I49) -> 0 | J39: =SUM(J40,J49) -> 77918 | K39: =SUM(K40,K49) -> 83176 | L39: =SUM(L40,L49) -> 161094 | M39: =SUM(M40,M49) -> 69168
A40: 5 | D40: SERVIZI DI SUPPORTO SPECIALISTICO APPLICATIVO | I40: =SUM(I41,I46) -> 0 | J40: =SUM(J41,J46) -> 42918 | K40: =SUM(K41,K46) -> 48176 | L40: =SUM(I40:K40) -> 91094 | M40: =SUM(M41,M46) -> 42918
...

Sheet Valori per liste a discesa
C1: Stati | D1: Priorità | E1: Attori | F1: Referenti | G1: Tipologia attività | H1: Servizio
C2: PIANIFICATO | D2: 1-Alta | G2: Progettuale | H2: Supporto Specialistico (a consumo)
C3: IN CORSO | D3: 2-Media | G3: Continuativa
C4: COMPLETATO | D4: 3-Bassa
C5: CANCELLATO
C6: DA RIPIANIFICARE
C7: NECESSARI APPROFONDIMENTI PER AVVIO
C8: DA PIANIFICARE
C9: DA AVVIARE
C10: RILASCIATO IN COLLAUDO
C11: ESITO POSITIVO AL COLLAUDO
C12: RILASCIATO IN ESERCIZIO

Sheet Settore
A1: CODICE PIANO LDCSIN / CODICE COMPUTO | B1: denominazione Piano / descrizione computo
A2: 001 | B2: Fascicolo Aziendale OC
A3: 002 | B3: Fascicolo Aziendale OP
A4: 003 | B4: Condizionalità (SICC - Sistema integrato di controllo e condizionalità)
A5: 006 | B5: Miele
A6: 007 | B6: Domanda Unica
A7: 008 | B7: Tabacco
A8: 009 | B8: Latte
A9: 010 | B9: Aiuti nazionali filiere zootecniche
A10: 011 | B10: Ortofrutta fresca (programmi operativi)
A11: 012 | B11: PIANO PER LA RIGENERAZIONE OLIVICOLA DELLA PUGLIA DM 2484/2020 -INTERVENTI COMPENSATIVI A FAVORE DEI FRANTOI OLEARI
A12: 014 | B12: Registro titoli
... A89: CODICE PIANO LDCSIN / CODICE COMPUTO | B89: SETTORI AGGIUNTI

Sheet Legende
A1: PIANIFICATO
A2: IN CORSO
A3: COMPLETATO
A4: CANCELLATO
A5: NECESSARI APPROFONDIMENTI PER L'AVVIO
A6: RIPIANIFICATA
A10: Sviluppo software
A11: MEV
A12: Conduzione applicativa(Consumo)
A13: Supp. Spec. App. (Consumo)
A14: Servizi Desk(Canone)
A17: III TRIMESTRE 2023
... A26: IV TRIMESTRE 2025
