Workbook
Name CEUmbria: #REF!
Name Inizio_progetto: #REF!
Name Visualizza_settimana: #REF!

Sheet Riepilogo Contratto
B2: Pianificato | D2: IV TRIM 2023 | E2: 2024 | F2: I SEM 2025 | H2: TOTALE PIANIFICATO | J2: TOTALE PdF
B4: Servizi Applicativi | D4: =SUM(D5,D6:D7) -> 174540 | E4: =SUM(E5,E6:E7) -> 543370.73 | F4: =SUM(F5,F6:F7) -> 912996.61 | H4: =SUM(H5,H6:H7) -> 1630907.3 | J4: =SUM(J5:J7) -> 1500204.5
B5: Sviluppo Software gg/persona | D5: =SUMIF(Gantt!$L$10:$L$56,"Sviluppo software",Gantt!G10:G56) -> 74688 | E5: =SUMIF(Gantt!$L$10:$L$56,"Sviluppo software",Gantt!H10:H56) -> 293358 | F5: =SUMIF(Gantt!$L$10:$L$56,"Sviluppo software",Gantt!I10:I56) -> 297529.61 | H5: =SUM(D5:F5) -> 665575.61 | J5: 360008 | K5: =J5-H5 -> -305567.61
B6: MEV/MAD | D6: =SUMIF(Gantt!$L$10:$L$56,"MEV",Gantt!G10:G56) -> 99852 | E6: =SUMIF(Gantt!$L$10:$L$56,"MEV",Gantt!H10:H56) -> 80012.73 | F6: =SUMIF(Gantt!$L$10:$L$56,"MEV",Gantt!I10:I56) -> 310000 | H6: =SUM(D6:F6) -> 489864.73 | J6: 489486 | K6: =J6-H6 -> -378.73
B7: Conduzione Applicativa | D7: =SUMIF(Gantt!$L$10:$L$56,"Conduzione Applicativa(Consumo)",Gantt!G10:G56) -> 0 | E7: =SUMIF(Gantt!$L$10:$L$56,"Conduzione Applicativa(Consumo)",Gantt!H10:H56) -> 170000 | F7: =SUMIF(Gantt!$L$10:$L$56,"Conduzione Applicativa(Consumo)",Gantt!I10:I56) -> 305467 | H7: =SUM(D7:F7) -> 475467 | J7: =887592-236881.5 -> 650710.5 | K7: =J7-H7 -> 175243.5
B8: Supporto Specialistico Applicativo | D8: =SUMIF(Gantt!$L$10:$L$56,"Supp. Spec. App. (Consumo)",Gantt!G10:G56) -> 0 | E8: =SUMIF(Gantt!$L$10:$L$56,"Supp. Spec. App. (Consumo)",Gantt!H10:H56) -> 16740.75 | F8: =SUMIF(Gantt!$L$10:$L$56,"Supp. Spec. App. (Consumo)",Gantt!I10:I56) -> 48176 | H8: =SUM(D8:F8) -> 64916.75 | J8: 91094 | K8: =J8-H8 -> 26177.25
B9: Servizi di Call Center | D9: =SUMIF(Gantt!$L$10:$L$56,"Servizi Desk(Canone)",Gantt!G10:G56) -> 0 | E9: =SUMIF(Gantt!$L$10:$L$56,"Servizi Desk(Canone)",Gantt!H10:H56) -> 7164 | F9: =SUMIF(Gantt!$L$10:$L$56,"Servizi Desk(Canone)",Gantt!I10:I56) -> 10000 | H9: =SUM(D9:F9) -> 17164 | J9: 84997.5 | K9: =J9-H9 -> 67833.5
B11: Totale Pianificato | D11: =D4+D8+D9 -> 174540 | E11: =E4+E8+E9 -> 567275.48 | F11: =F4+F8+F9 -> 971172.61 | H11: =SUM(D11:F11) -> 1712988.1 | J11: =SUM(J5:J9) -> 1676296
J12: =H13-H11 -> -36692.09 | K12: Residuo da Allocare
B13: TOTALI DA PDF | D13: 484872 | E13: 788379 | F13: 403045 | H13: =SUM(D13:F13) -> 1676296
B17: PdF
B18: Sviluppo | D18: 180000 | E18: 150012 | F18: 29996 | H18: =SUM(D18:F18) -> 360008 | J18: =H18-H5 -> -305567.61
B19: MEV | D19: 200000 | E19: 209997 | F19: 79489 | H19: =SUM(D19:F19) -> 489486 | J19: =H19-H6 -> -378.73
B20: Conduzione Applicativa | D20: 104872 | E20: 350452 | F20: 220268 | H20: =SUM(D20:F20) -> 675592 | J20: =H20-H7 -> 200125
B21: Assistenza spec | D21: 0 | E21: 42918 | F21: 38292 | H21: =SUM(D21:F21) -> 81210 | J21: =H21-H8 -> 16293.25
B22: Call center | D22: 0 | E22: 35000 | F22: 35000 | H22: =SUM(D22:F22) -> 70000 | J22: =H22-H9 -> 52836
D24: =SUM(D18:D22) -> 484872 | E24: =SUM(E18:E22) -> 788379 | F24: =SUM(F18:F22) -> 403045 | H24: =SUM(D24:F24) -> 1676296
D27: IV TRIM 2023 | E27: I TRIM 2024 | F27: II TRIM 2024 | G27: III TRIM 2024 | H27: IV TRIM 2024 | I27: I TRIM 2025 | J27: II TRIM 2025
B29: Servizi Applicativi | D29: =SUM(D30,D31:D32) -> 174540 | E29: =SUM(E30,E31:E32) -> 99483 | F29: =SUM(F30,F31:F32) -> 21072 | G29: =SUM(G30,G31:G32) -> 0 | H29: =SUM(H30,H31:H32) -> 222815.73 | I29: =SUM(I30,I31:I32) -> 897996.61 | J29: =SUM(J30,J31:J32) -> 15000
B30: Sviluppo Software gg/persona | D30: =SUMIFS(Gantt!$G$10:$G$56,Gantt!$L$10:$L$56,"Sviluppo software",Gantt!$M$10:$M$56,"IV TRIMESTRE 2023") -> 74688 | E30: =SUMIFS(Gantt!$H$10:$H$56,Gantt!$L$10:$L$56,"Sviluppo software",Gantt!$M$10:$M$56,"I TRIMESTRE 2024") -> 29483 | F30: =SUMIFS(Gantt!$H$10:$H$56,Gantt!$L$10:$L$56,"Sviluppo software",Gantt!$M$10:$M$56,"II TRIMESTRE 2024") -> 21072 | G30: =SUMIFS(Gantt!$H$10:$H$56,Gantt!$L$10:$L$56,"Sviluppo software",Gantt!$M$10:$M$56,"III TRIMESTRE 2024") -> 0 | H30: =SUMIFS(Gantt!$H$10:$H$56,Gantt!$L$10:$L$56,"Sviluppo software",Gantt!$M$10:$M$56,"IV TRIMESTRE 2024") -> 192803 | I30: =SUMIFS(Gantt!$I$10:$I$56,Gantt!$L$10:$L$56,"Sviluppo software",Gantt!$M$10:$M$56,"I TRIMESTRE 2025") -> 297529.61 | J30: =SUMIFS(Gantt!$I$10:$I$56,Gantt!$L$10:$L$56,"Sviluppo software",Gantt!$M$10:$M$56,"II TRIMESTRE 2025") -> 0
B31: MEV/MAD | D31: =SUMIFS(Gantt!$G$10:$G$56,Gantt!$L$10:$L$56,"MEV",Gantt!$M$10:$M$56,"IV TRIMESTRE 2023") -> 99852 | E31: =SUMIFS(Gantt!$H$10:$H$56,Gantt!$L$10:$L$56,"MEV",Gantt!$M$10:$M$56,"I TRIMESTRE 2024") -> 0 | F31: =SUMIFS(Gantt!$H$10:$H$56,Gantt!$L$10:$L$56,"MEV",Gantt!$M$10:$M$56,"II TRIMESTRE 2024") -> 0 | G31: =SUMIFS(Gantt!$H$10:$H$56,Gantt!$L$10:$L$56,"MEV",Gantt!$M$10:$M$56,"III TRIMESTRE 2024") -> 0 | H31: =SUMIFS(Gantt!$H$10:$H$56,Gantt!$L$10:$L$56,"MEV",Gantt!$M$10:$M$56,"IV TRIMESTRE 2024") -> 30012.73 | I31: =SUMIFS(Gantt!$I$10:$I$56,Gantt!$L$10:$L$56,"MEV",Gantt!$M$10:$M$56,"I TRIMESTRE 2025") -> 310000 | J31: =SUMIFS(Gantt!$I$10:$I$56,Gantt!$L$10:$L$56,"MEV",Gantt!$M$10:$M$56,"II TRIMESTRE 2025") -> 0
B32: Conduzione Applicativa | D32: =SUMIFS(Gantt!$G$10:$G$56,Gantt!$L$10:$L$56,"Conduzione applicativa(consumo)",Gantt!$N$10:$N$56,"2023") -> 0 | E32: =SUMIFS(Gantt!$H$10:$H$56,Gantt!$L$10:$L$56,"Conduzione applicativa(consumo)",Gantt!$M$10:$M$56,"I TRIMESTRE 2024") -> 70000 | F32: =SUMIFS(Gantt!$H$10:$H$56,Gantt!$L$10:$L$56,"Conduzione applicativa(consumo)",Gantt!$M$10:$M$56,"II TRIMESTRE 2024") -> 0 | G32: =SUMIFS(Gantt!$H$10:$H$56,Gantt!$L$10:$L$56,"Conduzione applicativa(consumo)",Gantt!$M$10:$M$56,"III TRIMESTRE 2024") -> 0 | H32: =SUMIFS(Gantt!$H$10:$H$56,Gantt!$L$10:$L$56,"Conduzione applicativa(consumo)",Gantt!$M$10:$M$56,"IV TRIMESTRE 2024") -> 0 | I32: =SUMIFS(Gantt!$I$10:$I$56,Gantt!$L$10:$L$56,"Conduzione applicativa(consumo)",Gantt!$M$10:$M$56,"I TRIMESTRE 2025") -> 290467 | J32: =SUMIFS(Gantt!$I$10:$I$56,Gantt!$L$10:$L$56,"Conduzione applicativa(consumo)",Gantt!$M$10:$M$56,"II TRIMESTRE 2025") -> 15000
B33: Supporto specialistico Applicativo | D33: =SUMIFS(Gantt!$G$10:$G$56,Gantt!$L$10:$L$56,"Supp. Spec. App. (Consumo)",Gantt!$N$10:$N$56,"2023") -> 0 | E33: =SUMIFS(Gantt!$H$10:$H$56,Gantt!$L$10:$L$56,"Supp. Spec. App. (Consumo)",Gantt!$M$10:$M$56,"I TRIMESTRE 2024") -> 5803 | F33: =SUMIFS(Gantt!$H$10:$H$56,Gantt!$L$10:$L$56,"Supp. Spec. App. (Consumo)",Gantt!$M$10:$M$56,"II TRIMESTRE 2024") -> 1243.5 | G33: =SUMIFS(Gantt!$H$10:$H$56,Gantt!$L$10:$L$56,"Supp. Spec. App. (Consumo)",Gantt!$M$10:$M$56,"III TRIMESTRE 2024") -> 2694.25 | H33: =SUMIFS(Gantt!$H$10:$H$56,Gantt!$L$10:$L$56,"Supp. Spec. App. (Consumo)",Gantt!$M$10:$M$56,"IV TRIMESTRE 2024") -> 7000 | I33: =SUMIFS(Gantt!$I$10:$I$56,Gantt!$L$10:$L$56,"Supp. Spec. App. (Consumo)",Gantt!$M$10:$M$56,"I TRIMESTRE 2025") -> 24088 | J33: =SUMIFS(Gantt!$I$10:$I$56,Gantt!$L$10:$L$56,"Supp. Spec. App. (Consumo)",Gantt!$M$10:$M$56,"II TRIMESTRE 2025") -> 24088
B34: Servizi di Call Center | D34: =SUMIFS(Gantt!$G$10:$G$56,Gantt!$L$10:$L$56,"Servizi Desk(Canone)",Gantt!$M$10:$M$56,"IV TRIMESTRE 2023") -> 0 | E34: =SUMIFS(Gantt!$H$10:$H$56,Gantt!$L$10:$L$56,"Servizi Desk(Canone)",Gantt!$M$10:$M$56,"I TRIMESTRE 2024") -> 612 | F34: =SUMIFS(Gantt!$H$10:$H$56,Gantt!$L$10:$L$56,"Servizi Desk(Canone)",Gantt!$M$10:$M$56,"II TRIMESTRE 2024") -> 2188 | G34: =SUMIFS(Gantt!$H$10:$H$56,Gantt!$L$10:$L$56,"Servizi Desk(Canone)",Gantt!$M$10:$M$56,"III TRIMESTRE 2024") -> 1364 | H34: =SUMIFS(Gantt!$H$10:$H$56,Gantt!$L$10:$L$56,"Servizi Desk(Canone)",Gantt!$M$10:$M$56,"IV TRIMESTRE 2024") -> 3000 | I34: =SUMIFS(Gantt!$I$10:$I$56,Gantt!$L$10:$L$56,"Servizi Desk(Canone)",Gantt!$M$10:$M$56,"I TRIMESTRE 2025") -> 5000 | J34: =SUMIFS(Gantt!$I$10:$I$56,Gantt!$L$10:$L$56,"Servizi Desk(Canone)",Gantt!$M$10:$M$56,"II TRIMESTRE 2025") -> 5000
B36: Totale Collaudato | D36: =D29+D33+D34 -> 174540 | E36: =E29+E33+E34 -> 105898 | F36: =F29+F33+F34 -> 24503.5 | G36: =G29+G33+G34 -> 4058.25 | H36: =H29+H33+H34 -> 232815.73 | I36: =I29+I33+I34 -> 927084.61 | J36: =J29+J33+J34 -> 44088 | K36: TOTALE | L36: =SUM(D36:J36) -> 1512988.1

Sheet Sintesi Rendiconti
B1: LEONARDO | C1: DXC | D1: ABACO | E1: E-GEOS | F1: GREEN-AUS
A3: ANNO 2023 | J3: SAL | L3: FATTURA
A4: IV Trimestre 2023
H5: TOTALE
A6: Servizi Applicativi | B6: 0 | C6: 0 | E6: 0 | F6: ='Riepilogo Contratto'!D4 -> 174540 | H6: =SUM(B6:F6) -> 174540
A7: Servzi Infrastrutturali | B7: 0 | C7: 0 | E7: 0 | F7: 0 | H7: =SUM(B7:F7) -> 0
A8: Servizi di supporto specialistico | B8: ='Riepilogo Contratto'!D8 -> 0 | C8: 0 | E8: 0 | F8: 0 | H8: =SUM(B8:F8) -> 0
A9: Call Center | B9: ='Riepilogo Contratto'!D9 -> 0 | C9: 0 | E9: 0 | F9: 0 | H9: 0
A11: TOTALI | B11: =SUM(B6:B9) -> 0 | C11: 0 | D11: =SUM(D6:D9) -> 0 | E11: =SUM(E6:E9) -> 0 | F11: =SUM(F6:F9) -> 174540 | H11: =SUM(H6:H9) -> 174540
A13: TOTALE ANNO 2023 | B13: =B11 -> 0 | C13: =C11 -> 0 | D13: =D11 -> 0 | E13: =E11 -> 0 | F13: =F11 -> 174540 | H13: =H11 -> 174540 | J13: Fatturazione Autorizzata | L13: Da Fatturare
A15: ANNO 2024
A16: I Trimestre 2024
H17: TOTALE
A18: Servizi Applicativi | B18: ='Riepilogo Contratto'!E29 -> 99483 | C18: 0 | D18: 0 | E18: 0 | F18: 0 | H18: =SUM(B18:F18) -> 99483
A19: Servzi Infrastrutturali | B19: 0 | C19: 0 | D19: 0 | E19: 0 | F19: 0 | H19: =SUM(B19:F19) -> 0
A20: Servizi di supporto specialistico | B20: =Gantt!H43 -> 5803 | C20: 0 | D20: 0 | E20: 0 | F20: 0 | H20: =SUM(B20:F20) -> 5803
A21: Call Center | B21: =Gantt!H51 -> 612 | C21: 0 | D21: 0 | E21: 0 | F21: 0 | H21: =SUM(B21:F21) -> 612
A23: TOTALI | B23: =SUM(B18:B21) -> 105898 | C23: =SUM(C18:C21) -> 0 | D23: =SUM(D18:D21) -> 0 | E23: 0 | F23: 0 | H23: =SUM(B23:F23) -> 105898 | J23: Fatturazione Autorizzata | L23: Da Fatturare
A24: II Trimestre 2024
H25: TOTALE
A26: Servizi Applicativi | B26: ='Riepilogo Contratto'!F29 -> 21072 | C26: 0 | E26: 0 | F26: 0 | H26: =SUM(B26:F26) -> 21072
A27: Servzi Infrastrutturali | B27: 0 | C27: 0 | E27: 0 | F27: 0 | H27: =SUM(B27:F27) -> 0
A28: Servizi di supporto specialistico | B28: ='Riepilogo Contratto'!F33 -> 1243.5 | C28: 0 | E28: 0 | F28: 0 | H28: =SUM(B28:F28) -> 1243.5
A29: Call Center | B29: ='Riepilogo Contratto'!F34 -> 2188 | C29: 0 | D29: 0 | E29: 0 | F29: 0 | H29: =SUM(B29:F29) -> 2188
A31: TOTALI | B31: =SUM(B26:B29) -> 24503.5 | C31: =SUM(C26:C29) -> 0 | D31: =SUM(D26:D29) -> 0 | E31: =SUM(E26:E29) -> 0 | F31: =SUM(F26:F29) -> 0 | H31: =SUM(B31:F31) -> 24503.5 | J31: Fatturazione Autorizzata | L31: Da Fatturare
A32: III Trimestre 2024
H33: TOTALE
A34: Servizi Applicativi | B34: ='Riepilogo Contratto'!G29 -> 0 | C34: 0 | D34: 0 | E34: 0 | F34: 0 | H34: =SUM(B34:F34) -> 0
A35: Servzi Infrastrutturali | B35: 0 | C35: 0 | D35: 0 | E35: 0 | F35: 0 | H35: =SUM(B35:F35) -> 0
A36: Servizi di supporto specialistico | B36: ='Riepilogo Contratto'!G33 -> 2694.25 | C36: 0 | D36: 0 | E36: 0 | F36: 0 | H36: =SUM(B36:F36) -> 2694.25
A37: Call Center | B37: ='Riepilogo Contratto'!G34 -> 1364 | C37: 0 | D37: 0 | E37: 0 | F37: 0 | H37: =SUM(B37:F37) -> 1364
A39: TOTALI | B39: =SUM(B34:B37) -> 4058.25 | C39: =SUM(C34:C37) -> 0 | D39: =SUM(D34:D37) -> 0 | E39: =SUM(E34:E37) -> 0 | F39: =SUM(F34:F37) -> 0 | H39: =SUM(B39:F39) -> 4058.25 | J39: Fatturazione Autorizzata | L39: Da Fatturare
B41: LEONARDO | C41: DXC | D41: ABACO | E41: E-GEOS | F41: GREEN-AUS | H41: TOTALE
A42: Servizi Applicativi | B42: 50557 | C42: 0 | D42: 0 | E42: 0 | F42: =F6+200000 -> 374540 | H42: =SUM(B42:F42) -> 425097
A43: Servzi Infrastrutturali | B43: 0 | C43: 0 | E43: 0 | F43: 0 | H43: =SUM(B43:F43) -> 0
A44: Servizi di supporto specialistico | B44: 9740.75 | C44: 0 | D44: 0 | E44: 0 | F44: 0 | H44: =SUM(B44:F44) -> 9740.75
A45: Call Center | B45: 4164 | C45: 0 | D45: 0 | E45: 0 | F45: 0 | H45: =SUM(B45:F45) -> 4164
A47: TOTALI | B47: =SUM(B42:B45) -> 64461.75 | C47: =SUM(C42:C45) -> 0 | D47: =SUM(D42:D45) -> 0 | E47: =SUM(E42:E45) -> 0 | F47: =SUM(F42:F45) -> 374540 | H47: =SUM(H42:H45) -> 439001.75
A49: TOTALE ANNO 2024 | B49: =SUM(B23,B31,B39,B47) -> 198921.5 | C49: =SUM(C23,C31,C39,C47) -> 0 | D49: =SUM(D23,D31,D39,D47) -> 0 | E49: =SUM(E23,E31,E39,E47) -> 0 | F49: =SUM(F23,F31,F39,F47) -> 374540 | H49: =SUM(H23,H31,H39,H47) -> 573461.5

Sheet Gantt
G2: Previsione di Spesa | K2: Riferimenti rendicontazione
A3: ID | B3: Predecessore /vincoli | C3: Titolo attività | D3: Obiettivo/Intervento | E3: Piano di lavoro obiettivo | F3: Deliverable Associato | G3: IV TRIM 2023 | H3: 2024 | I3: I SEM 2025 | J3: TOTALE | K3: Rendicontato effettivo (consuntivo) | L3: Servizio | M3: Trimestre riferimento rendicontazione | N3: Anno rendicontazione | O3: Percentuale rendicontazione | P3: STATO | Q3: STATO | R3: Ownership | S3: % Completamento | T3: Data Ricezione Richiesta Intervento | U3: Data Consegna Documentazione da parte RTI | V3: Data Accettazione Documentazione | W3: Data di pronti al Collaudo | X3: Data rilascio in Produzione | Y3: Note
C4: Definizione precondizioni operative | Q4: DA RIPIANIFICARE
C5: Disponibilità Piattaforma GARI BASE | P5: =Q5 -> COMPLETATO | Q5: COMPLETATO | R5: Leonardo | S5: 1 | T5: 45224
C6: PRESA IN CARICO | P6: =Q6 -> COMPLETATO | Q6: COMPLETATO | R6: Leonardo | S6: 1
C7: Incontri con Amministrazione | P7: =Q7 -> COMPLETATO | Q7: COMPLETATO | R7: Leonardo | S7: 1
C8: Knowledge Transfer | P8: =Q8 -> COMPLETATO | Q8: COMPLETATO | R8: Leonardo | S8: 1
C9: Consegna e Convalida | P9: =Q9 -> COMPLETATO | Q9: COMPLETATO | R9: Leonardo | S9: 1
C10: SERVIZI APPLICATIVI - ATTIVITA' DI CARATTERE PROGETTUALE (Sviluppo SW + MEV+Supporto Specialistico Operativo) | G10: =SUM(G11,G12,G18,G30,G26,G41) -> 174540 | H10: =SUM(H11,H12,H18,H30,H26) -> 543370.73 | I10: =SUM(I11,I12,I18,I30,I26) -> 912996.61 | J10: =SUM(G10,H10,I10) -> 1630907.3
A11: 0 | C11: MEV GARI-PA per porting (IV TRIM 23) su nuovo ambiente di tutti i moduli (BASE, PUA, QDCA, UMA) | F11: Specifiche Progettazione RU-9992150707-BASE-SP-01.01 del 31/12/2023 Specifiche Progettazione RU-9992150707-UMA-SP-01.01 del 31/12/2023 Specifiche Progettazione RU-9992150707-PUA-SP-01.01 del 31/12/2023 Specifiche Progettazione RU-9992150707-QUAD-SP-01.01 del 31/12/2023 | G11: 99852 | I11: 0 | J11: =SUM(G11:I11) -> 99852 | K11: =G11 -> 99852 | L11: MEV | M11: IV TRIMESTRE 2023 | N11: 2023 | O11: =K11/J11 -> 1 | P11: =Q11 -> RILASCIATO IN ESERCIZIO | Q11: RILASCIATO IN ESERCIZIO | R11: Abaco | S11: =K11/G11 -> 1 | T11: 45231 | V11: 45291 | W11: 45313 | X11: 45330
A12: 1 | C12: GARI BASE | G12: =SUM(G13:G17) -> 0 | H12: =SUM(H13:H17) -> 215000 | I12: =SUM(I13:I17) -> 245000 | J12: =SUM(G12:I12) -> 460000 | K12: =SUM(K13:K17) -> 70000
A13: 1.1 | C13: GARI-BASE Re-ingegnerizzazione della piattaforma GIAS per implementare la nuova piattaforma GARI su nuove tecnologie ( i.e tecnologia Angular) | D13: Previsto da Progetto dei Fabbisogni | F13: Specifiche Progettazione RU-9992150707-BASE-SP-02.00 | H13: 70000 | J13: =SUM(G13:I13) -> 70000 | K13: 70000 | L13: Conduzione applicativa(Consumo) | M13: I TRIMESTRE 2024 | N13: 2024 | O13: =K13/J13 -> 1 | P13: RILASCIATO IN ESERCIZIO | Q13: DA AUTORIZZARE | R13: Abaco | S13: =K13/H13 -> 1 | T13: 45299 | U13: 45569 | V13: 45366 | W13: 45366 | X13: 45382
A14: 1.2 | C14: Sviluppo funzionalità di Interlavoro con il sistema SIAN per importare il Piano colturale Grafico AGEA, compendiato dagli attributi catastali alfanumerici e altre informazioni legate alle consistenze aziendali funzionali alla gestione GARI Con acquisizione dei dati di fascicolo necessari ai procedimenti del GARI se e come esposti da AGEA. | D14: Previsto da Progetto dei Fabbisogni | E14: Documento in redazione | F14: Documento in redazione | H14: 50000 | I14: 45000 | J14: =SUM(G14:I14) -> 95000 | L14: Sviluppo software | M14: I TRIMESTRE 2025 | N14: 2024 | O14: =K14/J14 -> 0 | P14: =Q14 -> DA AUTORIZZARE | Q14: DA AUTORIZZARE | R14: Abaco | S14: 0.4 | T14: 45536 | W14: 45641
A15: 1.3 | C15: Implementazione del modulo GARI-GIS per la gestione( nel contesto GIS) i dati importati dal SIAN relativi al PCG (nuovo sistema di riferimento wgs84) | D15: Previsto da Progetto dei Fabbisogni | F15: Documento in redazione | H15: 50000 | I15: 145000 | J15: =SUM(G15:I15) -> 195000 | K15: 0 | L15: MEV | M15: I TRIMESTRE 2025 | N15: 2024 | O15: =K15/J15 -> 0 | P15: =Q15 -> DA AUTORIZZARE | Q15: DA AUTORIZZARE | R15: Abaco | S15: 0.4 | T15: 45536 | W15: 45641
A16: 1.4 | C16: Gestione delle Anagrafiche (risorse , macchine, analisi terreno etc) | D16: Previsto da Progetto dei Fabbisogni | F16: Documento in redazione | I16: 55000 | J16: =SUM(G16:I16) -> 55000 | K16: 0 | L16: Sviluppo software | M16: I TRIMESTRE 2025 | N16: 2024 | O16: =K16/J16 -> 0 | P16: IN CORSO | Q16: DA AUTORIZZARE | R16: Abaco | S16: 0.9 | T16: 45488 | W16: 45590
A17: 1.5 | C17: Implementazione del Modulo di Gestione dei documenti funzionale ai moduli GARI (Evolutive, installazione, configurazione/setting e profilazione utenza) | D17: Previsto da Progetto dei Fabbisogni | E17: Piano Lavoro Obiettivo -GARI Umbria - Interventi ACA Rev.01.00 | F17: Documento di FASE UNICA RU-9992150707-ACA-FU-01.02 del 01/08/2024 | H17: 45000 | J17: =SUM(G17:I17) -> 45000 | K17: 0 | L17: Sviluppo software | M17: IV TRIMESTRE 2024 | N17: 2024 | O17: =K17/J17 -> 0 | P17: =Q17 -> IN CORSO | Q17: IN CORSO | R17: Abaco | S17: 0.9 | T17: 45355 | U17: 45574 | W17: 45641
A18: 2 | C18: GARI PA - UMA | G18: =SUM(G19:G25) -> 74688 | H18: =SUM(H19:H25) -> 55750 | I18: =SUM(I19:I25) -> 205467 | J18: =SUM(G18:I18) -> 335905
A19: 2.1 | C19: RILASCIO 1 - Rif. Doc. fase unica PT000849TECH001 | D19: Scheda richiesta intervento 16_11_23 - GIAS-PA UMA-Rev.1.1 del 16/11/2023 | E19: Piano Lavoro Obiettivo- Gestione UMA 1 | F19: Nuovi Sviluppi UMA - DOCUMENTAZIONE FASE UNICA Rev. 2.1 del 15/01/2024 | G19: 74688 | H19: 0 | I19: 0 | J19: =SUM(G19:I19) -> 74688 | K19: =G19 -> 74688 | L19: Sviluppo software | M19: IV TRIMESTRE 2023 | N19: 2023 | O19: =K19/J19 -> 1 | P19: =Q19 -> RILASCIATO IN ESERCIZIO | Q19: RILASCIATO IN ESERCIZIO | R19: Abaco | S19: 1 | T19: 45246 | U19: 45569 | V19: 45306 | W19: 45278 | X19: 45329
A20: 2.2 | C20: RILASCIO 2 - Rif. Doc. fase unica PT000849TECH001 | D20: Scheda richiesta intervento 16_11_23 - GIAS-PA UMA-Rev.1.1 del 16/11/2023 | E20: Piano Lavoro Obiettivo- Gestione UMA 2 | F20: Nuovi Sviluppi UMA - DOCUMENTAZIONE FASE UNICA Rev. 2.3 del 23/02/2024 | G20: 0 | H20: 29483 | J20: =SUM(G20:I20) -> 29483 | K20: =H20 -> 29483 | L20: Sviluppo software | M20: I TRIMESTRE 2024 | N20: =IF(X20="-","-",TEXT(X20,"aaaa")) -> 2024 | O20: =K20/J20 -> 1 | P20: =Q20 -> RILASCIATO IN ESERCIZIO | Q20: RILASCIATO IN ESERCIZIO | R20: Abaco | S20: 1 | T20: 45297 | U20: 45569 | V20: 45345 | W20: 45345 | X20: 45359
A21: 2.3 | C21: RILASCIO 3 - Rif. Doc. fase unica PT000849TECH001 | D21: Scheda richiesta intervento 16_11_23 - GIAS-PA UMA-Rev.1.1 del 16/11/2023 | E21: Piano Lavoro Obiettivo- Gestione UMA 3 | F21: Nuovi Sviluppi UMA - DOCUMENTAZIONE FASE UNICA Rev. 2.4 del 19/04/2024 | G21: 0 | H21: 10000 | J21: =SUM(G21:I21) -> 10000 | K21: =H21 -> 10000 | L21: Sviluppo software | M21: II TRIMESTRE 2024 | N21: 2024 | O21: =K21/J21 -> 1 | P21: =Q21 -> RILASCIATO IN ESERCIZIO | Q21: RILASCIATO IN ESERCIZIO | R21: Abaco | S21: 1 | T21: 45357 | U21: 45569 | V21: 45401 | W21: 45401 | X21: 45415
A22: 2.4 | C22: RILASCIO 4 - Rif. Doc. fase unica PT000849TECH001 | D22: Scheda richiesta intervento 16_11_23 - GIAS-PA UMA-Rev.1.1 del 16/11/2023 | E22: Piano Lavoro Obiettivo- Gestione UMA 4 | F22: Nuovi Sviluppi UMA - DOCUMENTAZIONE FASE UNICA Rev. 2.5 del 07/06/2024 | G22: 0 | H22: 11072 | J22: =SUM(G22:I22) -> 11072 | K22: =H22 -> 11072 | L22: Sviluppo software | M22: II TRIMESTRE 2024 | N22: 2024 | O22: =K22/J22 -> 1 | P22: =Q22 -> RILASCIATO IN ESERCIZIO | Q22: RILASCIATO IN ESERCIZIO | R22: Abaco | S22: 1 | T22: 45388 | U22: 45569 | V22: 45450 | W22: 45450 | X22: 45460
A23: 2.5 | C23: RILASCIO 5 - Rif. Doc. fase unica PT000849TECH001 | D23: Scheda richiesta intervento 16_11_23 - GIAS-PA UMA-Rev.1.1 del 16/11/2023 | E23: Piano Lavoro Obiettivo - Gestione UMA 5 | F23: Nuovi Sviluppi UMA - DOCUMENTAZIONE FASE UNICA Rev. 2.6 | G23: 0 | H23: 5195 | J23: =SUM(G23:I23) -> 5195 | K23: 0 | L23: Sviluppo software | M23: IV TRIMESTRE 2024 | N23: 2024 | O23: =K23/J23 -> 0 | P23: =Q23 -> RILASCIATO IN ESERCIZIO | Q23: RILASCIATO IN ESERCIZIO | R23: Abaco | S23: 1 | T23: 45449 | U23: 45569 | W23: 45590 | X23: 45596
A24: 2.6 | C24: UMA Re-ingegnerizzazione della piattaforma GIAS per implementare la nuova piattaforma GARI su nuove tecnologie introdotte con il paradigma PCG | D24: Previsto da Progetto dei Fabbisogni per quanto concerne il passaggio all'utilizzo del PCG. | F24: Documento in redazione | I24: 139194.68 | J24: =SUM(G24:I24) -> 139194.68 | K24: 0 | L24: Conduzione applicativa(Consumo) | M24: I TRIMESTRE 2025 | N24: 2024 | O24: =K24/J24 -> 0 | P24: DA RIVEDERE INTERVENTO PREVISTO Eventualmente rimodulare tra questa voce e quella del Gari BASE grafico (tolto 40.000 Euro sul valore totale proposto da RTI portato a 109.194,68 + 30.000 già previsti in precedenza) | Q24: IN CORSO | R24: Abaco | S24: 0.5 | T24: 45566 | W24: 45641 | X24: 45657
A25: 2.7 | C25: UMA MEV 2025 | D25: Scheda richiesta intervento evoluzioni UMA-Rev.1.0 - REGIONE UMBRIA (dic 2024) | E25: Piano di lavoro obiettivo-UMA MEV 1 v1.0 Piano di lavoro obiettivo-UMA MEV 2 v1.0 Piano di lavoro obiettivo-UMA MEV 3 v1.0 Piano di lavoro obiettivo-UMA MEV 4 v1.0 Piano di lavoro obiettivo-UMA MEV 5 v1.0 | I25: 66272.32 | J25: =SUM(G25:I25) -> 66272.32 | K25: 0 | L25: Conduzione applicativa(Consumo) | M25: I TRIMESTRE 2025 | N25: 2025 | O25: =K25/J25 -> 0 | P25: =Q25 -> DA AUTORIZZARE | Q25: DA AUTORIZZARE | R25: Abaco | S25: 0.1 | T25: 45583 | U25: 45672 | Y25: include il 2.6
A26: 3 | C26: GARI PUA | G26: =SUM(G27:G29) -> 0 | H26: =SUM(H27:H29) -> 0 | I26: =SUM(I27:I29) -> 270029.61 | J26: =SUM(G26:I26) -> 270029.61 | K26: =SUM(K27:K29) -> 0
A27: 3.1 | C27: GARI-PUA Re-ingegnerizzazione della piattaforma GIAS per implementare la nuova piattaforma GARI su nuove tecnologie ( i.e tecnologia Angular) | D27: Previsto da Progetto dei Fabbisogni | F27: Specifiche Progettazione RU-9992150707-PUA-SP-02.00 | H27: 0 | I27: 70000 | J27: =SUM(G27:I27) -> 70000 | K27: =H27 -> 0 | L27: Conduzione applicativa(Consumo) | M27: I TRIMESTRE 2025 | N27: 2025 | O27: =K27/J27 -> 0 | P27: DA AUTORIZZARE è da inserire come contenuto nel Documento soluzione evoluzione NUOVO MODULO PUA | Q27: RILASCIATO IN ESERCIZIO | R27: Abaco | S27: =K27/H27 -> #DIV/0! | T27: 45352 | U27: 45569 | W27: 45731 | X27: 45747
A28: 3.2 | C28: Nuovo Modulo PUA incluso la interoperabilità con ACA per le 04 13 e 24 - Fase1 | D28: Scheda richiesta intervento GARI Umbria PUA-Rev.1.0 del 11/06/2024 | E28: Piano Lavoro Obiettivo - Sviluppi PUA | F28: Documento di FASE UNICA RU-9992150707-PUA-Sviluppi-FU-01.00 del 24/07/2024 | I28: 175029.61 | J28: =SUM(G28:I28) -> 175029.61 | K28: 0 | L28: Sviluppo software | M28: I TRIMESTRE 2025 | N28: 2025 | O28: =K28/J28 -> 0 | P28: AUTORIZZATO | Q28: DA AUTORIZZARE | R28: Abaco | S28: 0.3 | T28: 45454 | U28: 45574 | W28: 45672
A29: 3.3 | C29: Nuovo Modulo PUA collegamento e funzionamento su base PCG - Fase2 | D29: Scheda richiesta intervento GARI Umbria PUA-Rev.1.0 del 11/06/2024 | E29: Piano Lavoro Obiettivo - Sviluppi PUA | F29: Documento di FASE UNICA RU-9992150707-PUA-Sviluppi-FU-01.00 del 24/07/2024 | I29: 25000 | J29: =SUM(G29:I29) -> 25000 | K29: 0 | L29: MEV | M29: I TRIMESTRE 2025 | N29: 2025 | O29: =K29/J29 -> 0 | P29: DA AUTORIZZARE va inserito nel documento del GARI grafico nella sezione di porting in grafica dei servizi verticali GARI | Q29: DA AUTORIZZARE | R29: Abaco | S29: 0.3 | T29: 45454 | U29: 45574 | W29: 45688
A30: 4 | C30: GARI - QDCA | G30: =SUM(G31:G39) -> 0 | H30: =SUM(H31:H39) -> 272620.73 | I30: =SUM(I31:I39) -> 192500 | J30: =SUM(G30:I30) -> 465120.73 | K30: =SUM(K31:K39) -> 0
A31: 4.1 | C31: QCDA-Re-ingegnerizzazione della piattaforma GIAS per implementare la nuova piattaforma GARI su nuove tecnologie ( i.e tecnologia Angular) | D31: Previsto da Progetto dei Fabbisogni | F31: Specifiche Progettazione RU-9992150707-QUAD-SP-02.00 | H31: 100000 | J31: =SUM(G31:I31) -> 100000 | K31: 0 | L31: Conduzione applicativa(Consumo) | M31: I TRIMESTRE 2025 | N31: 2025 | O31: =K31/J31 -> 0 | P31: DA AUTORIZZARE è da inserire come contenuto nel Documento soluzione Nuovo quaderno di campagna | Q31: DA AUTORIZZARE | R31: Abaco | S31: =K31/H31 -> 0 | T31: 45352 | U31: 45569 | W31: 45731 | X31: 45747
A32: 4.2 | C32: Sviluppo SW GARI - Misure ACA | D32: GARI Umbria Interventi ACA rev 01.00 ( ricevuta via pec del 04/03/2024) | E32: Piano Lavoro Obiettivo -GARI Umbria - Interventi ACA Rev.01.00 | F32: Documento di FASE UNICA RU-9992150707-ACA-FU-01.02 del 01/08/2024 | H32: 142608 | I32: 0 | J32: =SUM(G32:I32) -> 142608 | K32: 0 | L32: Sviluppo software | M32: IV TRIMESTRE 2024 | N32: 2024 | O32: =K32/J32 -> 0 | P32: =Q32 -> COMPLETATO | Q32: COMPLETATO | R32: Abaco | S32: 1 | T32: 45355 | U32: 45574 | W32: 45641
A33: 4.3 | C33: Sviluppo SW GARI - DSS per misure ACA | D33: GARI Umbria Interventi ACA rev 01.00 ( ricevuta via pec del 04/03/2024) | E33: Piano Lavoro Obiettivo - Gestione ACA DSS | F33: Documento di FASE UNICA RU-9992150707-ACA_DSS-FU-01.00 del 14/06/2024 | I33: 22500 | J33: =SUM(G33:I33) -> 22500 | K33: 0 | L33: Sviluppo software | M33: I TRIMESTRE 2025 | N33: 2024 | O33: =K33/J33 -> 0 | P33: =Q33 -> IN CORSO | Q33: IN CORSO | R33: Abaco | S33: 0.9 | T33: 45355 | W33: 45641 | Y33: in attesa dati accesso centraline da RU
A34: 4.4 | C34: MEV - GARI QDCA - DSS - solo front-end (no algoritmi /API) + adeguamento salvataggio su GARI degli output relativi ai consigli dei Modelli Previsionali difesa e Irrigazione + Meteo (DSS) | D34: GARI Umbria Interventi ACA rev 01.00 ( ricevuta via pec del 04/03/2024) | E34: Piano Lavoro Obiettivo - Gestione ACA DSS | F34: Documento di FASE UNICA RU-9992150707-ACA_DSS-FU-01.00 del 14/06/2024 | I34: 60000 | J34: =SUM(G34:I34) -> 60000 | K34: =H34 -> 0 | L34: MEV | M34: I TRIMESTRE 2025 | N34: 2025 | O34: =K34/J34 -> 0 | P34: =Q34 -> IN CORSO | Q34: IN CORSO | R34: Abaco | S34: 0.25 | T34: 45355 | W34: 45688 | Y34: in attesa dati accesso centraline da RU
A35: 4.5 | C35: Acquisizione, raccordo e verifica dei dati Meteo/DSS da sorgenti esterne | D35: GARI Umbria Interventi ACA rev 01.00 ( ricevuta via pec del 04/03/2024) | F35: N.A. | H35: 0 | I35: 15000 | J35: =SUM(G35:I35) -> 15000 | K35: 0 | L35: Conduzione applicativa(Consumo) | M35: I TRIMESTRE 2025 | N35: 2025 | O35: =K35/J35 -> 0 | P35: IN CORSO | Q35: DA AVVIARE | R35: Abaco | S35: 0 | T35: 45474 | W35: 45747
A36: 4.6 | C36: Acquisizione ,raccordo e verifica dei dati Meteo/DSS da sorgenti esterne | D36: GARI Umbria Interventi ACA rev 01.00 ( ricevuta via pec del 04/03/2024) | F36: N.A. | H36: 0 | I36: 15000 | J36: =SUM(G36:I36) -> 15000 | K36: 0 | L36: Conduzione applicativa(Consumo) | M36: II TRIMESTRE 2025 | N36: 2025 | O36: =K36/J36 -> 0 | P36: =Q36 -> DA AVVIARE | Q36: DA AVVIARE | R36: Abaco | S36: 0 | T36: 45566 | W36: 45838
A37: 4.7 | C37: Report ARPA: dati di impiego dei prodotti fitosanitari | D37: GARI Umbria - Intervento dati impiego fitosanitari - pec del 1/8/2024 | E37: Piano Lavoro Obiettivo - Report Fitosanitari | F37: Documento di FASE UNICA RU-9992150707-QUAD-Report_Fito-FU-01.00 del 28/08/2024 | H37: 10012.73 | J37: =SUM(G37:I37) -> 10012.73 | K37: 0 | L37: MEV | M37: IV TRIMESTRE 2024 | N37: 2024 | O37: =K37/J37 -> 0 | P37: =Q37 -> COMPLETATO | Q37: COMPLETATO | R37: Abaco | S37: 1 | T37: 45499 | U37: 45574 | W37: 45657
A38: 4.8 | C38: Revisione dei moduli QUADERNO SQNPI e BIO per essere utilizzabili e integrabili sulle nuove tecnologie introdotte con il paradigma PCG | D38: Previsto da Progetto dei Fabbisogni per quanto concerne il passaggio all'utilizzo del PCG. | F38: Documento in redazione | I38: 80000 | J38: =SUM(G38:I38) -> 80000 | K38: 0 | L38: MEV | M38: I TRIMESTRE 2025 | N38: 2025 | O38: =K38/J38 -> 0 | P38: DA AUTORIZZARE va inserito nel documento del GARI grafico nella sezione di porting in grafica dei servizi verticali GARI | Q38: IN CORSO | R38: Abaco | S38: 0.15 | W38: 45703
A39: 4.9 | C39: Attivazione registri bio nel contesto del QDCA GARI, setting, configurazioni, profilazioni utenti, ecc. | D39: GARI Umbria Interventi ACA rev 01.00 ( ricevuta via pec del 04/03/2024) | E39: Piano Lavoro Obiettivo - Gestione SRA ACA | F39: Documento di FASE UNICA RU-9992150707-ACA-FU-01.02 del 01/08/2024 | H39: 20000 | I39: 0 | J39: =SUM(G39:I39) -> 20000 | K39: =I39 -> 0 | L39: MEV | M39: IV TRIMESTRE 2024 | N39: 2024 | O39: =K39/J39 -> 0 | P39: =Q39 -> COMPLETATO | Q39: COMPLETATO | R39: Abaco | S39: 1 | T39: 45355 | U39: 45574 | W39: 45641
C40: ATTIVITA' DI CARATTERE CONTINUATIVO (NON PROGETTUALE) | G40: =SUM(G41,G50) -> 0 | H40: =SUM(H41,H50) -> 23904.75 | I40: =SUM(I41,I50) -> 58176 | J40: =SUM(J41,J50) -> 82080.75 | K40: =SUM(K41,K50) -> 20904.75
A41: 5 | C41: SERVIZI DI SUPPORTO SPECIALISTICO APPLICATIVO | G41: =SUM(G42,G47) -> 0 | H41: =SUM(H42,H47) -> 16740.75 | I41: =SUM(I42,I47) -> 48176 | J41: =SUM(G41:I41) -> 64916.75 | K41: =SUM(K42,K47) -> 16740.75
...

Sheet Valori per liste a discesa
C1: Stati | D1: Priorità | E1: Attori | F1: Referenti | G1: Tipologia attività | H1: Servizio
C2: PIANIFICATO | D2: 1-Alta | G2: Progettuale | H2: Supporto Specialistico (a consumo)
C3: IN CORSO | D3: 2-Media | G3: Continuativa
C4: COMPLETATO | D4: 3-Bassa
C5: CANCELLATO
C6: DA RIPIANIFICARE
C7: NECESSARI APPROFONDIMENTI PER AVVIO
C8: DA PIANIFICARE
C9: DA AVVIARE
C10: RILASCIATO IN COLLAUDO
C11: ESITO POSITIVO AL COLLAUDO
C12: RILASCIATO IN ESERCIZIO

Sheet Settore
A1: CODICE PIANO LDCSIN / CODICE COMPUTO | B1: denominazione Piano / descrizione computo
A2: 001 | B2: Fascicolo Aziendale OC
A3: 002 | B3: Fascicolo Aziendale OP
A4: 003 | B4: Condizionalità (SICC - Sistema integrato di controllo e condizionalità)
A5: 006 | B5: Miele
A6: 007 | B6: Domanda Unica
A7: 008 | B7: Tabacco
A8: 009 | B8: Latte
A9: 010 | B9: Aiuti nazionali filiere zootecniche
A10: 011 | B10: Ortofrutta fresca (programmi operativi)
A11: 012 | B11: PIANO PER LA RIGENERAZIONE OLIVICOLA DELLA PUGLIA DM 2484/2020 -INTERVENTI COMPENSATIVI A FAVORE DEI FRANTOI OLEARI
A12: 014 | B12: Registro titoli
... A89: CODICE PIANO LDCSIN / CODICE COMPUTO | B89: SETTORI AGGIUNTI

Sheet Legende
A1: DA AUTORIZZARE
A2: PIANIFICATO
A3: IN CORSO
A4: COMPLETATO
A5: CANCELLATO
A6: NECESSARI APPROFONDIMENTI PER L'AVVIO
A7: RIPIANIFICATA
A11: Sviluppo software
A12: MEV
A13: Conduzione applicativa(Consumo)
A14: Supp. Spec. App. (Consumo)
A15: Servizi Desk(Canone)
... A27: IV TRIMESTRE 2025

Sheet Richieste da Allocare
B2: ID | C2: Titolo attività | D2: Scheda Intervento | E2: Importo Stimato
B3: RA_1 | C3: Evolutive UMA Dicembre 2024 | D3: Evoluzioni UMA -Rev.x.0 - REGIONE UMBRIA | E3: 245467.92
B4: RA_2
