Workbook
Name CEUmbria: #REF!
Name Inizio_progetto: #REF!
Name prevWBS: 'Project Plan'!$A1048576
Name Visualizza_settimana: #REF!

Sheet Riepilogo Contratto
B2: Pianificato | D2: IV TRIM 2023 | E2: 2024 | F2: I SEM 2025 | H2: TOTALE PIANIFICATO | J2: TOTALE PdF
B4: Servizi Applicativi | D4: =SUM(D5,D6:D7) -> #REF! | E4: =SUM(E5,E6:E7) -> #REF! | F4: =SUM(F5,F6:F7) -> 1190108 | H4: =SUM(H5,H6:H7) -> #REF! | J4: =SUM(J5:J7) -> 1500204.5
B5: Sviluppo Software gg/persona | D5: =SUMIF(Gantt!$H$4:$H$34,"Sviluppo software",Gantt!#REF!) -> #REF! | E5: =SUMIF(Gantt!$H$4:$H$34,"Sviluppo software",Gantt!#REF!) -> #REF! | F5: =SUMIF(Gantt!$H$4:$H$34,"Sviluppo software",Gantt!G4:G34) -> 535108 | H5: =SUM(D5:F5) -> #REF! | J5: 360008 | K5: =J5-H5 -> #REF!
B6: MEV/MAD | D6: =SUMIF(Gantt!$H$4:$H$34,"MEV",Gantt!#REF!) -> #REF! | E6: =SUMIF(Gantt!$H$4:$H$34,"MEV",Gantt!#REF!) -> #REF! | F6: =SUMIF(Gantt!$H$4:$H$34,"MEV",Gantt!G4:G34) -> 380000 | H6: =SUM(D6:F6) -> #REF! | J6: 489486 | K6: =J6-H6 -> #REF!
B7: Conduzione Applicativa | D7: =SUMIF(Gantt!$H$4:$H$34,"Conduzione Applicativa(Consumo)",Gantt!#REF!) -> #REF! | E7: =SUMIF(Gantt!$H$4:$H$34,"Conduzione Applicativa(Consumo)",Gantt!#REF!) -> #REF! | F7: =SUMIF(Gantt!$H$4:$H$34,"Conduzione Applicativa(Consumo)",Gantt!G4:G34) -> 275000 | H7: =SUM(D7:F7) -> #REF! | J7: =887592-236881.5 -> 650710.5 | K7: =J7-H7 -> #REF!
B8: Supporto Specialistico Applicativo | D8: =SUMIF(Gantt!$H$4:$H$34,"Supp. Spec. App. (Consumo)",Gantt!#REF!) -> #REF! | E8: =SUMIF(Gantt!$H$4:$H$34,"Supp. Spec. App. (Consumo)",Gantt!#REF!) -> #REF! | F8: =SUMIF(Gantt!$H$4:$H$34,"Supp. Spec. App. (Consumo)",Gantt!G4:G34) -> 48176 | H8: =SUM(D8:F8) -> #REF! | J8: 91094 | K8: =J8-H8 -> #REF!
B9: Servizi di Call Center | D9: =SUMIF(Gantt!$H$4:$H$34,"Servizi Desk(Canone)",Gantt!#REF!) -> #REF! | E9: =SUMIF(Gantt!$H$4:$H$34,"Servizi Desk(Canone)",Gantt!#REF!) -> #REF! | F9: =SUMIF(Gantt!$H$4:$H$34,"Servizi Desk(Canone)",Gantt!G4:G34) -> 35000 | H9: =SUM(D9:F9) -> #REF! | J9: 84997.5 | K9: =J9-H9 -> #REF!
B11: Totale Pianificato | D11: =D4+D8+D9 -> #REF! | E11: =E4+E8+E9 -> #REF! | F11: =F4+F8+F9 -> 1273284 | H11: =SUM(D11:F11) -> #REF! | J11: =SUM(J5:J9) -> 1676296
J12: =H13-H11 -> #REF! | K12: Residuo da Pianificare
B13: TOTALI DA PDF | D13: 484872 | E13: 788379 | F13: 403045 | H13: =SUM(D13:F13) -> 1676296
B17: PdF
B18: Sviluppo | D18: 180000 | E18: 150012 | F18: 29996 | H18: =SUM(D18:F18) -> 360008 | J18: =H18-H5 -> #REF!
B19: MEV | D19: 200000 | E19: 209997 | F19: 79489 | H19: =SUM(D19:F19) -> 489486 | J19: =H19-H6 -> #REF!
B20: Conduzione Applicativa | D20: 104872 | E20: 350452 | F20: 220268 | H20: =SUM(D20:F20) -> 675592 | J20: =H20-H7 -> #REF!
B21: Assistenza spec | D21: 0 | E21: 42918 | F21: 38292 | H21: =SUM(D21:F21) -> 81210 | J21: =H21-H8 -> #REF!
B22: Call center | D22: 0 | E22: 35000 | F22: 35000 | H22: =SUM(D22:F22) -> 70000 | J22: =H22-H9 -> #REF!
D24: =SUM(D18:D22) -> 484872 | E24: =SUM(E18:E22) -> 788379 | F24: =SUM(F18:F22) -> 403045 | H24: =SUM(D24:F24) -> 1676296
D27: IV TRIM 2023 | E27: I TRIM 2024 | F27: II TRIM 2024 | G27: III TRIM 2024 | H27: IV TRIM 2024 | I27: I TRIM 2025 | J27: II TRIM 2025
B29: Servizi Applicativi | D29: =SUM(D30,D31:D32) -> #REF! | E29: =SUM(E30,E31:E32) -> #REF! | F29: =SUM(F30,F31:F32) -> #REF! | G29: =SUM(G30,G31:G32) -> #REF! | H29: =SUM(H30,H31:H32) -> #REF! | I29: =SUM(I30,I31:I32) -> #REF! | J29: =SUM(J30,J31:J32) -> #REF!
B30: Sviluppo Software gg/persona | D30: =SUMIFS(Gantt!#REF!,Gantt!$H$4:$H$34,"Sviluppo software",Gantt!#REF!,"IV TRIMESTRE 2023") -> #REF! | E30: =SUMIFS(Gantt!#REF!,Gantt!$H$4:$H$34,"Sviluppo software",Gantt!#REF!,"I TRIMESTRE 2024") -> #REF! | F30: =SUMIFS(Gantt!#REF!,Gantt!$H$4:$H$34,"Sviluppo software",Gantt!#REF!,"II TRIMESTRE 2024") -> #REF! | G30: =SUMIFS(Gantt!#REF!,Gantt!$H$4:$H$34,"Sviluppo software",Gantt!#REF!,"III TRIMESTRE 2024") -> #REF! | H30: =SUMIFS(Gantt!#REF!,Gantt!$H$4:$H$34,"Sviluppo software",Gantt!#REF!,"IV TRIMESTRE 2024") -> #REF! | I30: =SUMIFS(Gantt!$G$4:$G$34,Gantt!$H$4:$H$34,"Sviluppo software",Gantt!#REF!,"I TRIMESTRE 2025") -> #REF! | J30: =SUMIFS(Gantt!$G$4:$G$34,Gantt!$H$4:$H$34,"Sviluppo software",Gantt!#REF!,"II TRIMESTRE 2025") -> #REF!
B31: MEV/MAD | D31: =SUMIFS(Gantt!#REF!,Gantt!$H$4:$H$34,"MEV",Gantt!#REF!,"IV TRIMESTRE 2023") -> #REF! | E31: =SUMIFS(Gantt!#REF!,Gantt!$H$4:$H$34,"MEV",Gantt!#REF!,"I TRIMESTRE 2024") -> #REF! | F31: =SUMIFS(Gantt!#REF!,Gantt!$H$4:$H$34,"MEV",Gantt!#REF!,"II TRIMESTRE 2024") -> #REF! | G31: =SUMIFS(Gantt!#REF!,Gantt!$H$4:$H$34,"MEV",Gantt!#REF!,"III TRIMESTRE 2024") -> #REF! | H31: =SUMIFS(Gantt!#REF!,Gantt!$H$4:$H$34,"MEV",Gantt!#REF!,"IV TRIMESTRE 2024") -> #REF! | I31: =SUMIFS(Gantt!$G$4:$G$34,Gantt!$H$4:$H$34,"MEV",Gantt!#REF!,"I TRIMESTRE 2025") -> #REF! | J31: =SUMIFS(Gantt!$G$4:$G$34,Gantt!$H$4:$H$34,"MEV",Gantt!#REF!,"II TRIMESTRE 2025") -> #REF!
B32: Conduzione Applicativa | D32: =SUMIFS(Gantt!#REF!,Gantt!$H$4:$H$34,"Conduzione applicativa(consumo)",Gantt!#REF!,"2023") -> #REF! | E32: =SUMIFS(Gantt!#REF!,Gantt!$H$4:$H$34,"Conduzione applicativa(consumo)",Gantt!#REF!,"I TRIMESTRE 2024") -> #REF! | F32: =SUMIFS(Gantt!#REF!,Gantt!$H$4:$H$34,"Conduzione applicativa(consumo)",Gantt!#REF!,"II TRIMESTRE 2024") -> #REF! | G32: =SUMIFS(Gantt!#REF!,Gantt!$H$4:$H$34,"Conduzione applicativa(consumo)",Gantt!#REF!,"III TRIMESTRE 2024") -> #REF! | H32: =SUMIFS(Gantt!#REF!,Gantt!$H$4:$H$34,"Conduzione applicativa(consumo)",Gantt!#REF!,"IV TRIMESTRE 2024") -> #REF! | I32: =SUMIFS(Gantt!$G$4:$G$34,Gantt!$H$4:$H$34,"Conduzione applicativa(consumo)",Gantt!#REF!,"I TRIMESTRE 2025") -> #REF! | J32: =SUMIFS(Gantt!$G$4:$G$34,Gantt!$H$4:$H$34,"Conduzione applicativa(consumo)",Gantt!#REF!,"II TRIMESTRE 2025") -> #REF!
B33: Supporto specialistico Applicativo | D33: =SUMIFS(Gantt!#REF!,Gantt!$H$4:$H$34,"Supp. Spec. App. (Consumo)",Gantt!#REF!,"2023") -> #REF! | E33: =SUMIFS(Gantt!#REF!,Gantt!$H$4:$H$34,"Supp. Spec. App. (Consumo)",Gantt!#REF!,"I TRIMESTRE 2024") -> #REF! | F33: =SUMIFS(Gantt!#REF!,Gantt!$H$4:$H$34,"Supp. Spec. App. (Consumo)",Gantt!#REF!,"II TRIMESTRE 2024") -> #REF! | G33: =SUMIFS(Gantt!#REF!,Gantt!$H$4:$H$34,"Supp. Spec. App. (Consumo)",Gantt!#REF!,"III TRIMESTRE 2024") -> #REF! | H33: =SUMIFS(Gantt!#REF!,Gantt!$H$4:$H$34,"Supp. Spec. App. (Consumo)",Gantt!#REF!,"IV TRIMESTRE 2024") -> #REF! | I33: =SUMIFS(Gantt!$G$4:$G$34,Gantt!$H$4:$H$34,"Supp. Spec. App. (Consumo)",Gantt!#REF!,"I TRIMESTRE 2025") -> #REF! | J33: =SUMIFS(Gantt!$G$4:$G$34,Gantt!$H$4:$H$34,"Supp. Spec. App. (Consumo)",Gantt!#REF!,"II TRIMESTRE 2025") -> #REF!
B34: Servizi di Call Center | D34: =SUMIFS(Gantt!#REF!,Gantt!$H$4:$H$34,"Servizi Desk(Canone)",Gantt!#REF!,"IV TRIMESTRE 2023") -> #REF! | E34: =SUMIFS(Gantt!#REF!,Gantt!$H$4:$H$34,"Servizi Desk(Canone)",Gantt!#REF!,"I TRIMESTRE 2024") -> #REF! | F34: =SUMIFS(Gantt!#REF!,Gantt!$H$4:$H$34,"Servizi Desk(Canone)",Gantt!#REF!,"II TRIMESTRE 2024") -> #REF! | G34: =SUMIFS(Gantt!#REF!,Gantt!$H$4:$H$34,"Servizi Desk(Canone)",Gantt!#REF!,"III TRIMESTRE 2024") -> #REF! | H34: =SUMIFS(Gantt!#REF!,Gantt!$H$4:$H$34,"Servizi Desk(Canone)",Gantt!#REF!,"IV TRIMESTRE 2024") -> #REF! | I34: =SUMIFS(Gantt!$G$4:$G$34,Gantt!$H$4:$H$34,"Servizi Desk(Canone)",Gantt!#REF!,"I TRIMESTRE 2025") -> #REF! | J34: =SUMIFS(Gantt!$G$4:$G$34,Gantt!$H$4:$H$34,"Servizi Desk(Canone)",Gantt!#REF!,"II TRIMESTRE 2025") -> #REF!
B36: Totale Collaudato | D36: =D29+D33+D34 -> #REF! | E36: =E29+E33+E34 -> #REF! | F36: =F29+F33+F34 -> #REF! | G36: =G29+G33+G34 -> #REF! | H36: =H29+H33+H34 -> #REF! | I36: =I29+I33+I34 -> #REF! | J36: =J29+J33+J34 -> #REF! | K36: TOTALE | L36: =SUM(D36:J36) -> #REF!
D39: =D29 -> #REF! | E39: =E29 -> #REF!
B40: =SUM(D40:E40) -> #REF! | C40: Greenaus | D40: =D39 -> #REF! | E40: =E32 -> #REF!
C41: Leonardo | E41: =E30 -> #REF! | F41: =F29 -> #REF! | G41: =G29 -> #REF! | H41: =H29 -> #REF! | I41: =I29 -> #REF! | J41: =J29 -> #REF!

Sheet Project Plan
A1: Regione Umbria - GARI | K1: Gantt Chart Template © 2006-2018 by Vertex42.com.
B4: Data Inizio Progetto | C4: 45231 | G4: Display Week | H4: 54 | K4: ="Week "&(K6-($C$4-WEEKDAY($C$4,1)+2))/7+1 -> Week 54 | R4: ="Week "&(R6-($C$4-WEEKDAY($C$4,1)+2))/7+1 -> Week 55 | Y4: ="Week "&(Y6-($C$4-WEEKDAY($C$4,1)+2))/7+1 -> Week 56 | AF4: ="Week "&(AF6-($C$4-WEEKDAY($C$4,1)+2))/7+1 -> Week 57 | AM4: ="Week "&(AM6-($C$4-WEEKDAY($C$4,1)+2))/7+1 -> Week 58 | AT4: ="Week "&(AT6-($C$4-WEEKDAY($C$4,1)+2))/7+1 -> Week 59 | BA4: ="Week "&(BA6-($C$4-WEEKDAY($C$4,1)+2))/7+1 -> Week 60 | BH4: ="Week "&(BH6-($C$4-WEEKDAY($C$4,1)+2))/7+1 -> Week 61 | BO4: ="Week "&(BO6-($C$4-WEEKDAY($C$4,1)+2))/7+1 -> Week 62
B5: Project Lead | K5: =K6 -> 45600 | R5: =R6 -> 45607 | Y5: =Y6 -> 45614 | AF5: =AF6 -> 45621 | AM5: =AM6 -> 45628 | AT5: =AT6 -> 45635 | BA5: =BA6 -> 45642 | BH5: =BH6 -> 45649 | BO5: =BO6 -> 45656
K6: =C4-WEEKDAY(C4,1)+2+7*(H4-1) -> 45600 | L6: =K6+1 -> 45601 | M6: =L6+1 -> 45602 | N6: =M6+1 -> 45603 | O6: =N6+1 -> 45604 | P6: =O6+1 -> 45605 | Q6: =P6+1 -> 45606 | R6: =Q6+1 -> 45607 | S6: =R6+1 -> 45608 | ... BU6: =BT6+1 -> 45662
A7: WBS | B7: TASK | C7: LEAD | D7: PREDECESSORI | E7: INIZIO | F7: FINE | G7: Durata gg | H7: % COMPLETAMENTO | I7: GIORNI Lavorativi | K7: =CHOOSE(WEEKDAY(K6,1),"S","M","T","W","T","F","S") -> M | L7: =CHOOSE(WEEKDAY(L6,1),"S","M","T","W","T","F","S") -> T | M7: =CHOOSE(WEEKDAY(M6,1),"S","M","T","W","T","F","S") -> W | N7: =CHOOSE(WEEKDAY(N6,1),"S","M","T","W","T","F","S") -> T | O7: =CHOOSE(WEEKDAY(O6,1),"S","M","T","W","T","F","S") -> F | P7: =CHOOSE(WEEKDAY(P6,1),"S","M","T","W","T","F","S") -> S | Q7: =CHOOSE(WEEKDAY(Q6,1),"S","M","T","W","T","F","S") -> S | R7: =CHOOSE(WEEKDAY(R6,1),"S","M","T","W","T","F","S") -> M | ... BU7: =CHOOSE(WEEKDAY(BU6,1),"S","M","T","W","T","F","S") -> S
A8: =IF(ISERROR(VALUE(SUBSTITUTE(prevWBS,".",""))),"1",IF(ISERROR(FIND("`",SUBSTITUTE(prevWBS,".","`",1))),TEXT(VALUE(prevWBS)+1,"#"),TEXT(VALUE(LEFT(prevWBS,FIND("`",SUBSTITUTE(prevWBS,".","`",1))-1))+1,"#"))) -> 1 | B8: =Gantt!C4 -> SERVIZI APPLICATIVI - ATTIVITA' DI CARATTERE PROGETTUALE (Sviluppo SW + MEV+Supporto Specialistico Operativo) | F8: =IF(ISBLANK(E8)," - ",IF(G8=0,E8,E8+G8-1)) -> - | I8: =IF(OR(F8=0,E8=0)," - ",NETWORKDAYS(E8,F8)) -> -
A9: =Gantt!#REF! -> #REF! | B9: =Gantt!#REF! -> #REF! | E9: =Gantt!#REF! -> #REF! | F9: =Gantt!#REF! -> #REF! | G9: =F9-E9 -> #REF! | H9: =Gantt!#REF! -> #REF! | I9: =IF(OR(F9=0,E9=0)," - ",NETWORKDAYS(E9,F9)) -> #REF!
A10: =Gantt!A5 -> 1 | B10: =Gantt!C5 -> GARI BASE
A11: =Gantt!#REF! -> #REF! | B11: =Gantt!#REF! -> #REF! | E11: =Gantt!#REF! -> #REF! | F11: =Gantt!#REF! -> #REF! | G11: =F11-E11 -> #REF! | H11: =Gantt!#REF! -> #REF! | I11: =IF(OR(F11=0,E11=0)," - ",NETWORKDAYS(E11,F11)) -> #REF!
A12: =Gantt!A6 -> 1.2 | B12: =Gantt!C6 -> Sviluppo funzionalità di Interlavoro con il sistema SIAN per importare il Piano colturale Grafico AGEA, compendiato dagli attributi catastali alfanumerici e altre informazioni legate alle consistenze aziendali funzionali alla gestione GARI Con acquisizione dei dati di fascicolo necessari ai procedimenti del GARI se e come esposti da AGEA. | E12: =Gantt!M6 -> 0 | F12: =Gantt!P6 -> 0 | G12: =F12-E12 -> 0 | H12: =Gantt!L6 -> 0 | I12: =IF(OR(F12=0,E12=0)," - ",NETWORKDAYS(E12,F12)) -> -
A13: =Gantt!A7 -> 1.3 | B13: =Gantt!C7 -> Implementazione del modulo GARI-GIS per la gestione( nel contesto GIS) i dati importati dal SIAN relativi al PCG (nuovo sistema di riferimento wgs84) | E13: =Gantt!M7 -> 0 | F13: =Gantt!P7 -> 0 | G13: =F13-E13 -> 0 | H13: =Gantt!L7 -> 0 | I13: =IF(OR(F13=0,E13=0)," - ",NETWORKDAYS(E13,F13)) -> -
A14: =Gantt!A8 -> 1.4 | B14: =Gantt!C8 -> Gestione delle Anagrafiche (risorse , macchine, analisi terreno etc) | E14: =Gantt!M8 -> 0 | F14: =Gantt!P8 -> 0 | G14: =F14-E14 -> 0 | H14: =Gantt!L8 -> 0 | I14: =IF(OR(F14=0,E14=0)," - ",NETWORKDAYS(E14,F14)) -> -
A15: =Gantt!A9 -> 1.5 | B15: =Gantt!C9 -> Implementazione del Modulo di Gestione dei documenti funzionale ai moduli GARI (Evolutive, installazione, configurazione/setting e profilazione utenza) | E15: =Gantt!M9 -> 0 | F15: =Gantt!P9 -> 0 | G15: =F15-E15 -> 0 | H15: =Gantt!L9 -> 0 | I15: =IF(OR(F15=0,E15=0)," - ",NETWORKDAYS(E15,F15)) -> -
A16: =Gantt!A10 -> 2 | B16: =Gantt!C10 -> GARI PA - UMA
A17: =Gantt!#REF! -> #REF! | B17: =Gantt!#REF! -> #REF! | E17: =Gantt!#REF! -> #REF! | F17: =Gantt!#REF! -> #REF! | G17: =F17-E17 -> #REF! | H17: =Gantt!#REF! -> #REF! | I17: =IF(OR(F17=0,E17=0)," - ",NETWORKDAYS(E17,F17)) -> #REF!
A18: =Gantt!#REF! -> #REF! | B18: =Gantt!#REF! -> #REF! | E18: =Gantt!#REF! -> #REF! | F18: =Gantt!#REF! -> #REF! | G18: =F18-E18 -> #REF! | H18: =Gantt!#REF! -> #REF! | I18: =IF(OR(F18=0,E18=0)," - ",NETWORKDAYS(E18,F18)) -> #REF!
A19: =Gantt!#REF! -> #REF! | B19: =Gantt!#REF! -> #REF! | E19: =Gantt!#REF! -> #REF! | F19: =Gantt!#REF! -> #REF! | G19: =F19-E19 -> #REF! | H19: =Gantt!#REF! -> #REF! | I19: =IF(OR(F19=0,E19=0)," - ",NETWORKDAYS(E19,F19)) -> #REF!
A20: =Gantt!#REF! -> #REF! | B20: =Gantt!#REF! -> #REF! | E20: =Gantt!#REF! -> #REF! | F20: =Gantt!#REF! -> #REF! | G20: =F20-E20 -> #REF! | H20: =Gantt!#REF! -> #REF! | I20: =IF(OR(F20=0,E20=0)," - ",NETWORKDAYS(E20,F20)) -> #REF!
A21: =Gantt!#REF! -> #REF! | B21: =Gantt!#REF! -> #REF! | E21: =Gantt!#REF! -> #REF! | F21: =Gantt!#REF! -> #REF! | G21: =F21-E21 -> #REF! | H21: =Gantt!#REF! -> #REF! | I21: =IF(OR(F21=0,E21=0)," - ",NETWORKDAYS(E21,F21)) -> #REF!
A22: =Gantt!A12 -> 2.7 | B22: =Gantt!C12 -> UMA Evolutive scheda intervento | E22: =Gantt!M12 -> 0 | F22: =Gantt!P12 -> 0 | G22: =F22-E22 -> 0 | H22: =Gantt!L12 -> 0 | I22: =IF(OR(F22=0,E22=0)," - ",NETWORKDAYS(E22,F22)) -> -
A23: =Gantt!A13 -> 3 | B23: =Gantt!C13 -> GARI PUA
A24: =Gantt!A14 -> 3.1 | B24: =Gantt!C14 -> GARI-PUA Re-ingegnerizzazione della piattaforma GIAS per implementare la nuova piattaforma GARI su nuove tecnologie ( i.e tecnologia Angular) | E24: =Gantt!M14 -> 0 | F24: =Gantt!P14 -> 0 | G24: =F24-E24 -> 0 | H24: =Gantt!L14 -> 0 | I24: =IF(OR(F24=0,E24=0)," - ",NETWORKDAYS(E24,F24)) -> -
A25: =Gantt!A15 -> 3.2 | B25: =Gantt!C15 -> Nuovo Modulo PUA incluso la interoperabilità con ACA per le 04 13 e 24 - Fase1 | E25: =Gantt!M15 -> 0 | F25: =Gantt!P15 -> 0 | G25: =F25-E25 -> 0 | H25: =Gantt!L15 -> 0 | I25: =IF(OR(F25=0,E25=0)," - ",NETWORKDAYS(E25,F25)) -> -
A26: =Gantt!A16 -> 3.3 | B26: =Gantt!C16 -> Nuovo Modulo PUA collegamento e funzionamento su base PCG - Fase2 | E26: =Gantt!M16 -> 0 | F26: =Gantt!P16 -> 0 | G26: =F26-E26 -> 0 | H26: =Gantt!L16 -> 0 | I26: =IF(OR(F26=0,E26=0)," - ",NETWORKDAYS(E26,F26)) -> -
A27: =Gantt!A17 -> 4 | B27: =Gantt!C17 -> GARI - QDCA
A28: =Gantt!A18 -> 4.1 | B28: =Gantt!C18 -> QCDA-Re-ingegnerizzazione della piattaforma GIAS per implementare la nuova piattaforma GARI su nuove tecnologie ( i.e tecnologia Angular) | E28: =Gantt!M18 -> 0 | F28: =Gantt!P18 -> 0 | G28: =F28-E28 -> 0 | H28: =Gantt!L18 -> 0 | I28: =IF(OR(F28=0,E28=0)," - ",NETWORKDAYS(E28,F28)) -> -
A29: =Gantt!A19 -> 4.2 | B29: =Gantt!C19 -> Sviluppo SW GARI - Misure ACA | E29: =Gantt!M19 -> 0 | F29: =Gantt!P19 -> 0 | G29: =F29-E29 -> 0 | H29: =Gantt!L19 -> 0 | I29: =IF(OR(F29=0,E29=0)," - ",NETWORKDAYS(E29,F29)) -> -
A30: =Gantt!A20 -> 4.3 | B30: =Gantt!C20 -> Sviluppo SW GARI - DSS per misure ACA | E30: =Gantt!M20 -> 0 | F30: =Gantt!P20 -> 0 | G30: =F30-E30 -> 0 | H30: =Gantt!L20 -> 0 | I30: =IF(OR(F30=0,E30=0)," - ",NETWORKDAYS(E30,F30)) -> -
A31: =Gantt!A21 -> 4.4 | B31: =Gantt!C21 -> MEV - GARI QDCA - DSS - solo front-end (no algoritmi /API) + adeguamento salvataggio su GARI degli output relativi ai consigli dei Modelli Previsionali difesa e Irrigazione + Meteo (DSS) | E31: =Gantt!M21 -> 0 | F31: =Gantt!P21 -> 0 | G31: =F31-E31 -> 0 | H31: =Gantt!L21 -> 0 | I31: =IF(OR(F31=0,E31=0)," - ",NETWORKDAYS(E31,F31)) -> -
A32: =Gantt!A22 -> 4.5 | B32: =Gantt!C22 -> Acquisizione, raccordo e verifica dei dati Meteo/DSS da sorgenti esterne | E32: =Gantt!M22 -> 0 | F32: =Gantt!P22 -> 0 | G32: =F32-E32 -> 0 | H32: =Gantt!L22 -> 0 | I32: =IF(OR(F32=0,E32=0)," - ",NETWORKDAYS(E32,F32)) -> -
A33: =Gantt!A23 -> 4.6 | B33: =Gantt!C23 -> Acquisizione ,raccordo e verifica dei dati Meteo/DSS da sorgenti esterne | E33: =Gantt!M23 -> 0 | F33: =Gantt!P23 -> 0 | G33: =F33-E33 -> 0 | H33: =Gantt!L23 -> 0 | I33: =IF(OR(F33=0,E33=0)," - ",NETWORKDAYS(E33,F33)) -> -
A34: =Gantt!A24 -> 4.7 | B34: =Gantt!C24 -> Report ARPA: dati di impiego dei prodotti fitosanitari | E34: =Gantt!M24 -> 0 | F34: =Gantt!P24 -> 0 | G34: =F34-E34 -> 0 | H34: =Gantt!L24 -> 0 | I34: =IF(OR(F34=0,E34=0)," - ",NETWORKDAYS(E34,F34)) -> -
A35: =Gantt!A25 -> 4.8 | B35: =Gantt!C25 -> Revisione dei moduli QUADERNO SQNPI e BIO per essere utilizzabili e integrabili sulle nuove tecnologie introdotte con il paradigma PCG | E35: =Gantt!M25 -> 0 | F35: =Gantt!P25 -> 0 | G35: =F35-E35 -> 0 | H35: =Gantt!L25 -> 0 | I35: =IF(OR(F35=0,E35=0)," - ",NETWORKDAYS(E35,F35)) -> -
A36: =Gantt!A26 -> 4.9 | B36: =Gantt!C26 -> Attivazione registri bio nel contesto del QDCA GARI, setting, configurazioni, profilazioni utenti, ecc. | E36: =Gantt!M26 -> 0 | F36: =Gantt!P26 -> 0 | G36: =F36-E36 -> 0 | H36: =Gantt!L26 -> 0 | I36: =IF(OR(F36=0,E36=0)," - ",NETWORKDAYS(E36,F36)) -> -
B37: =Gantt!C27 -> ATTIVITA' DI CARATTERE CONTINUATIVO (NON PROGETTUALE) | I37: =IF(OR(F37=0,E37=0)," - ",NETWORKDAYS(E37,F37)) -> -
A38: =Gantt!A28 -> 5 | B38: =Gantt!C28 -> SERVIZI DI SUPPORTO SPECIALISTICO APPLICATIVO | I38: =IF(OR(F38=0,E38=0)," - ",NETWORKDAYS(E38,F38)) -> -
A39: =Gantt!#REF! -> #REF! | B39: =Gantt!#REF! -> #REF!
A40: =Gantt!#REF! -> #REF! | B40: =Gantt!#REF! -> #REF! | E40: =Gantt!#REF! -> #REF! | F40: =Gantt!#REF! -> #REF! | G40: =F40-E40 -> #REF! | H40: =Gantt!#REF! -> #REF! | I40: =IF(OR(F40=0,E40=0)," - ",NETWORKDAYS(E40,F40)) -> #REF!
A41: =Gantt!#REF! -> #REF! | B41: =Gantt!#REF! -> #REF! | E41: =Gantt!#REF! -> #REF! | F41: =Gantt!#REF! -> #REF! | G41: =F41-E41 -> #REF! | H41: =Gantt!#REF! -> #REF! | I41: =IF(OR(F41=0,E41=0)," - ",NETWORKDAYS(E41,F41)) -> #REF!
A42: =Gantt!#REF! -> #REF! | B42: =Gantt!#REF! -> #REF! | E42: =Gantt!#REF! -> #REF! | F42: =Gantt!#REF! -> #REF! | G42: =F42-E42 -> #REF! | H42: =Gantt!#REF! -> #REF! | I42: =IF(OR(F42=0,E42=0)," - ",NETWORKDAYS(E42,F42)) -> #REF!
...

Sheet Sintesi Rendiconti
B1: LEONARDO | C1: DXC | D1: ABACO | E1: E-GEOS | F1: GREEN-AUS
A3: ANNO 2023 | J3: STATO
A4: IV Trimestre 2023
H5: TOTALE
A6: Servizi Applicativi | B6: 0 | C6: 0 | E6: 0 | F6: ='Riepilogo Contratto'!D4 -> #REF! | H6: =SUM(B6:F6) -> #REF!
A7: Servzi Infrastrutturali | B7: 0 | C7: 0 | E7: 0 | F7: 0 | H7: =SUM(B7:F7) -> 0
A8: Servizi di supporto specialistico | B8: ='Riepilogo Contratto'!D8 -> #REF! | C8: 0 | E8: 0 | F8: 0 | H8: =SUM(B8:F8) -> #REF!
A9: Call Center | B9: ='Riepilogo Contratto'!D9 -> #REF! | C9: 0 | E9: 0 | F9: 0 | H9: 0
A11: TOTALI | B11: =SUM(B6:B9) -> #REF! | C11: 0 | D11: =SUM(D6:D9) -> 0 | E11: =SUM(E6:E9) -> 0 | F11: =SUM(F6:F9) -> #REF! | H11: =SUM(H6:H9) -> #REF! | J11: Compilati
A13: TOTALE ANNO 2023 | B13: =B11 -> #REF! | C13: =C11 -> 0 | D13: =D11 -> 0 | E13: =E11 -> 0 | F13: =F11 -> #REF! | H13: =H11 -> #REF! | J13: Compilati
A15: ANNO 2024
A16: I Trimestre 2024
H17: TOTALE
A18: Servizi Applicativi | B18: ='Riepilogo Contratto'!E29 -> #REF! | C18: 0 | D18: 0 | E18: 0 | F18: 0 | H18: 0
A19: Servzi Infrastrutturali | B19: 0 | C19: 0 | D19: 0 | E19: 0 | F19: 0 | H19: 0
A20: Servizi di supporto specialistico | B20: =Gantt!#REF! -> #REF! | C20: 0 | D20: 0 | E20: 0 | F20: 0 | H20: 0
A21: Call Center | B21: =Gantt!#REF! -> #REF! | C21: 0 | D21: 0 | E21: 0 | F21: 0 | H21: 0
A23: TOTALI | B23: =SUM(B18:B21) -> #REF! | C23: =SUM(C18:C21) -> 0 | D23: =SUM(D18:D21) -> 0 | E23: 0 | F23: 0 | H23: =SUM(B23:F23) -> #REF! | J23: Compilati
A24: II Trimestre 2024
H25: TOTALE
A26: Servizi Applicativi | B26: ='Riepilogo Contratto'!F29 -> #REF! | C26: 0 | E26: 0 | F26: 0 | H26: 0
A27: Servzi Infrastrutturali | B27: 0 | C27: 0 | E27: 0 | F27: 0 | H27: 0
A28: Servizi di supporto specialistico | B28: ='Riepilogo Contratto'!F33 -> #REF! | C28: 0 | E28: 0 | F28: 0 | H28: 0
A29: Call Center | B29: ='Riepilogo Contratto'!F34 -> #REF! | C29: 0 | D29: 0 | E29: 0 | F29: 0 | H29: 0
A31: TOTALI | B31: =SUM(B26:B29) -> #REF! | C31: =SUM(C26:C29) -> 0 | D31: =SUM(D26:D29) -> 0 | E31: =SUM(E26:E29) -> 0 | F31: =SUM(F26:F29) -> 0 | H31: =SUM(B31:F31) -> #REF! | J31: Compilati
A32: III Trimestre 2024
H33: TOTALE
A34: Servizi Applicativi | B34: ='Riepilogo Contratto'!G29 -> #REF! | C34: 0 | D34: 0 | E34: 0 | F34: 0 | H34: 78296.75
A35: Servzi Infrastrutturali | B35: 0 | C35: 0 | D35: 0 | E35: 0 | F35: 0 | H35: 6406.2
A36: Servizi di supporto specialistico | B36: ='Riepilogo Contratto'!G33 -> #REF! | C36: 0 | D36: 0 | E36: 0 | F36: 0 | H36: 23550.75
A37: Call Center | B37: ='Riepilogo Contratto'!G34 -> #REF! | C37: 0 | D37: 0 | E37: 0 | F37: 0 | H37: 0
A39: TOTALI | B39: =SUM(B34:B37) -> #REF! | C39: =SUM(C34:C37) -> 0 | D39: =SUM(D34:D37) -> 0 | E39: =SUM(E34:E37) -> 0 | F39: =SUM(F34:F37) -> 0 | H39: =SUM(B39:F39) -> #REF!
B41: LEONARDO | C41: DXC | D41: ABACO | E41: E-GEOS | F41: GREEN-AUS | H41: TOTALE
A42: Servizi Applicativi | B42: 50557 | C42: 0 | D42: 0 | E42: 0 | F42: =F6+200000 -> #REF! | H42: =SUM(B42:F42) -> #REF!
A43: Servzi Infrastrutturali | B43: 0 | C43: 0 | E43: 0 | F43: 0 | H43: =SUM(B43:F43) -> 0
A44: Servizi di supporto specialistico | B44: 9740.75 | C44: 0 | D44: 0 | E44: 0 | F44: 0 | H44: =SUM(B44:F44) -> 9740.75
A45: Call Center | B45: 4164 | C45: 0 | D45: 0 | E45: 0 | F45: 0 | H45: =SUM(B45:F45) -> 4164
A47: TOTALI | B47: =SUM(B42:B45) -> 64461.75 | C47: =SUM(C42:C45) -> 0 | D47: =SUM(D42:D45) -> 0 | E47: =SUM(E42:E45) -> 0 | F47: =SUM(F42:F45) -> #REF! | H47: =SUM(H42:H45) -> #REF!
A49: TOTALE ANNO 2024 | B49: =SUM(B23,B31,B39,B47) -> #REF! | C49: =SUM(C23,C31,C39,C47) -> 0 | D49: =SUM(D23,D31,D39,D47) -> 0 | E49: =SUM(E23,E31,E39,E47) -> 0 | F49: =SUM(F23,F31,F39,F47) -> #REF! | H49: =SUM(H23,H31,H39,H47) -> #REF!

Sheet Gantt
A3: ID | B3: Predecessore /vincoli | C3: Titolo attività | D3: Obiettivo/Intervento | E3: Piano di lavoro obiettivo | F3: Deliverable Associato | G3: I SEM 2025 | H3: Servizio | I3: STATO | J3: Note operative di risultato da seguire per il corretto espletamento degli impegni | K3: Ownership | L3: % Completamento | M3: Data Ricezione Richiesta Intervento | N3: Data Consegna Documentazione da parte RTI | O3: Data Accettazione Documentazione | P3: Data di pronti al Collaudo | Q3: Data rilascio in Produzione | R3: Note
C4: SERVIZI APPLICATIVI - ATTIVITA' DI CARATTERE PROGETTUALE (Sviluppo SW + MEV+Supporto Specialistico Operativo) | G4: =SUM(G5,G10,G17,G13) -> 1190108
A5: 1 | C5: GARI BASE | G5: =SUM(G6:G9) -> 380000
A6: 1.2 | C6: Sviluppo funzionalità di Interlavoro con il sistema SIAN per importare il Piano colturale Grafico AGEA, compendiato dagli attributi catastali alfanumerici e altre informazioni legate alle consistenze aziendali funzionali alla gestione GARI Con acquisizione dei dati di fascicolo necessari ai procedimenti del GARI se e come esposti da AGEA. | D6: Previsto da Progetto dei Fabbisogni | E6: Documento in redazione | F6: Documento in redazione | G6: 95000 | H6: Sviluppo software | I6: NECESSARI APPROFONDIMENTI PER AVVIO | J6: 1. Produzione documento tecnico economico per approvazione attività, con descrizione dell'intera architettura modulra GARI. 1a. Inserire nel documento i capitoli di ingegnerizzazione servizi verticali GARI indicati nel piano con codici 2.6, 3.1, 3.3, 4.1, 4.8. Sia la migrazione in tecnologia Angular e altro a completamento del lavoro già fatto per il GARI Base come codice 1.1, che per risolvere le problematiche di interazione da utenza con questi servizi attraverso il modello grafico del GARI 2025 1b. Inserire nel documento i capitoli relativi al modello di interscambio e inteorperabilità per l'acquisizione Da SIAN in GARI dei Piani colturali grafici e della ulteriore cartografia SIPA resa disponibile da SIAN, della cartografia catastale AGEA (indicare anche possibilità di scarico mappe catastali Agenzia Entrate), Fascicolo SIAN completo (in sostituzione dell'attuale scarico della vista Fascicolo di Agea Coordinamento o del suo scarico parziale) 1c. definzione delle procedure amministrative, organizzative e tecnologiche per accedere ai Servizi di interoperabilità del SIA/AGEA,. Acquisizione del certificati e delle credenzialio necessarie, nonchè sottoscrizione documenti amministrativi previsti da Agea per l'accesso ai dati alle regole di privacy definite da Agea e a quelle relativa alla responsabilità derivante dal trattamento dei dati. 2. Produzione del documento tecnico di dettaglio dell'architettura dei Cataloghi dati GARI presenti negli RDBMA SQL Server e Oracle Spatial 3.Predisposizione Piani di lavoro obiettivo con il dettaglio di TUTTE le milestones di rilascio delle versioni del GARI 04.xx finalizzate all'attivazione dello stesso all'interno del sistema informativo regionale se previsti piani di convivenza tra GARI 02.xx 2024 (es. UMA) e quello 04.xx con le funzioni grafiche 4. approvazione dei documenti ai punti 1 e 2 5. avvio attività di sviluppo e produzione documentazione tecnica 6. Definire un PIANO di Test specifico considerata la valenza del processo di reingegnerizzazione 7. Definire un Piano di formazione del personale tecnico della Regione per il Change management nella gestione di questo architettura/tecnologia (attiivtà di formazione poi rendicontata nella sezione attività non progettuale di Assistenza) ULTERIORE Documentazione essenziale a corredo: - Definzione architettura cloud VM GARI 2025 (SQL Server + Oracle) - richiesta della Regione di revisioine e attivazione ambiente cloud 2025 - Predisporre Ambiente tecnologico cloud di esercizio e di test/collaudo da rendicontare tra le attività di carattere NON progettuale (Assistenza e supporto applicativo) - Manuale UTENTE inerente l'uso del GARI BASE e delle sue funzionalità - Documento descrittivo dei servizi di Assistenza necessari sul GARI 2025 in esercizio al fine di dare un testo di installazione/configurazione/gestione/parametrizzazione del GARI per l'assistenza regionale (coinvolta nel Change Managment). il testo sarà usato come base per dare parare di congruità alle rendicontazione trimestrali presentate dal RTI per la gestione GAri in esercizio fino a fine progetto | K6: Abaco
A7: 1.3 | C7: Implementazione del modulo GARI-GIS per la gestione( nel contesto GIS) i dati importati dal SIAN relativi al PCG (nuovo sistema di riferimento wgs84) | D7: Previsto da Progetto dei Fabbisogni | F7: Documento in redazione | G7: 185000 | H7: MEV | K7: Abaco
A8: 1.4 | C8: Gestione delle Anagrafiche (risorse , macchine, analisi terreno etc) | D8: Previsto da Progetto dei Fabbisogni | F8: Documento in redazione | G8: 55000 | H8: Sviluppo software | I8: IN CORSO | J8: 8. aggiornamento mensile del Piano Lavoro obiettivo con lo stato avanzamento lavoro 9.Documento appendice al Documento previsto al codice 2. in cui siano rappresentati le strutture dati delle anagrafiche. Mentre la descriizione dell'uso delle funzioni andranno che manuale utente GARI BASE (documentazione ulteriore attiivtà cod. 1.2) 10. Attività di gestione e aggiornamento di tutta la documentazione del Repository con una rubrica/elenco organizzato della documentazione presente e rilasciata,. Il Repoitory è l'area di collaudo dei documenti di Progetto e fa parte integrante degli output/deliverbles rilasciati dal fornitore, pertanto parte integrante dell'accettazione del Prodotto/fornitura in titolarità. 10. Inserimento e aggiornamento delle attiivtà di sviluppo nel Piano Lavoro Obiettivo per gli ACA/Registri SQNPI e per la parte del Fascicolo Aziendale GARI per le parti extradati SIAN 11. Sviluppi dei modulli di servizio come servizi GARI trasversali ai servizi verticali GARI. POssibilità, per questo motivo di essere inseriti nel capitolo "Servizi accessori di GARI Base" come descrizione dei prodotti/software tecnico funzionale nel documento al punto 1. dell'attività codice 1.2 | K8: Abaco
A9: 1.5 | C9: Implementazione del Modulo di Gestione dei documenti funzionale ai moduli GARI (Evolutive, installazione, configurazione/setting e profilazione utenza) | D9: Previsto da Progetto dei Fabbisogni | E9: Piano Lavoro Obiettivo -GARI Umbria - Interventi ACA Rev.01.00 | F9: Documento di FASE UNICA RU-9992150707-ACA-FU-01.02 del 01/08/2024 | G9: 45000 | H9: Sviluppo software | I9: IN CORSO | K9: Abaco
A10: 2 | C10: GARI PA - UMA | G10: =SUM(G11:G12) -> 115000
A11: 2.6 | C11: UMA Re-ingegnerizzazione della piattaforma GIAS per implementare la nuova piattaforma GARI su nuove tecnologie introdotte con il paradigma PCG | D11: Previsto da Progetto dei Fabbisogni per quanto concerne il passaggio all'utilizzo del PCG. | F11: Documento in redazione | G11: 35000 | H11: Conduzione applicativa(Consumo) | I11: NECESSARI APPROFONDIMENTI PER AVVIO | J11: 11. Sezione descrittiva tecnica economica da inserire nel documento al punto 1. dell'attività codice 1.2 O in alternativa, se prodotta una valutazione specifica per la reingegnerizzazione di UMA, un documento a se stante dove deve essere prevista una specifica sezione del modello/servizi e tecnologie di interazione e cooperazione con il GARI BASE grafico 12. Predisposizione Paino di lavoro obiettivo della attività di reingegnerizzazione UMA del GARI BAse grafico o in alternativa produrre un piano laoro ad hoc 13. Approvazione di Regione delle attività previa allocazione risorse da Residui di Progetto 2024 14. Esecuzione sviluppo software per integrazione nuove funzionalità 15. Produzione e Gestione documenti del prodotto realizzato nel Repository come previsto dal Progetto / Contratto 16. Piano di formazione dell'utenza per il nuovo servizio UMA. Attività di formazione da calendario deve essere rendicontata nelle attività si supporto Non porgettuali | K11: Abaco
A12: 2.7 | C12: UMA Evolutive scheda intervento | D12: Previsto da Progetto dei Fabbisogni per quanto concerne il passaggio all'utilizzo del PCG. | F12: Documento in redazione | G12: 80000 | H12: Conduzione applicativa(Consumo) | J12: 16. Documento tecnico economico in risposta alla scheda intervento Regione UMA 2025 17. Predisposizione Paino di lavoro obiettivo UMA 2025 18. Approvazione di Regione delle attività previa allocazione risorse da Residui di Progetto 2024 19. Esecuzione sviluppo software per integrazione nuove funzionalità 20. Predisposizioni Piani di formazione utenza dove previsto in accordo con uffici regionali 21. Pianificazione eventuali fermi servizio per aggiornamento release di servizio in esercizio | K12: Abaco
A13: 3 | C13: GARI PUA | G13: =SUM(G14:G16) -> 230000
A14: 3.1 | C14: GARI-PUA Re-ingegnerizzazione della piattaforma GIAS per implementare la nuova piattaforma GARI su nuove tecnologie ( i.e tecnologia Angular) | D14: Previsto da Progetto dei Fabbisogni | F14: Specifiche Progettazione RU-9992150707-PUA-SP-02.00 | G14: 30000 | H14: Conduzione applicativa(Consumo) | I14: NECESSARI APPROFONDIMENTI PER AVVIO | J14: 22. Documento tecnico economico del nuovo PUA grafico 2025. In questo caso il documento di risposta alla scheda intervento PUA DEVE essere già previsto tecnicamente e fuinzionalmente al'interno delGARI Grafico 2025. In questo caso il documento può essere nel capitolo dei servizi verticali speciaistici che si appogigano interoperano sul Gari Grafico Pipano Lavoro obiettivo del PUA 2025 23. approvazione realizzazione Regione 24. Attività di sviluppo del PUA 2025 25. Stato avanzamento mensile lavoro 26. Gestione documenti previsti nel Repository, vale la regole del collaudo nel Repo dei documenti parten integrante del rilascio del prodotto 27. Predisposizioni Piani di formazione utenza dove previsto in accordo con uffici regionali 28. Pianificazione eventuali fermi servizio per aggiornamento release di servizio in esercizio | K14: Abaco
A15: 3.2 | C15: Nuovo Modulo PUA incluso la interoperabilità con ACA per le 04 13 e 24 - Fase1 | D15: Scheda richiesta intervento GARI Umbria PUA-Rev.1.0 del 11/06/2024 | E15: Piano Lavoro Obiettivo - Sviluppi PUA | F15: Documento di FASE UNICA RU-9992150707-PUA-Sviluppi-FU-01.00 del 24/07/2024 | G15: 175000 | H15: Sviluppo software | I15: IN CORSO | J15: 29. modulo di servizio descritto nel documento PUA con riferimenti a quello degli ACA /SQNPI 30. Sviluppo software già autorizzato e in corso per riferimento alla compilazione a registro degli adempimenti ACA fertilizzazione a registro 31. Inserimento e gestione attiivtà sul Piano di lavoro ACa come rilascio del componente reperimento e verifica attività PUa per ACA con il semplice riferimento al PIano lacoro PUA 32. Inserimento della documentazione prevista nel documento ACA con riferimenti a quello PUA. Documentazione reperibile all'interno del Repository dove deve essere gestita | K15: Abaco
A16: 3.3 | C16: Nuovo Modulo PUA collegamento e funzionamento su base PCG - Fase2 | D16: Scheda richiesta intervento GARI Umbria PUA-Rev.1.0 del 11/06/2024 | E16: Piano Lavoro Obiettivo - Sviluppi PUA | F16: Documento di FASE UNICA RU-9992150707-PUA-Sviluppi-FU-01.00 del 24/07/2024 | G16: 25000 | H16: MEV | I16: NECESSARI APPROFONDIMENTI PER AVVIO | J16: 33. Documnetazioine dell'intervento all'interno del documento 1. dell'attività 1.2 inerente i servizi verticali che si appoggiano sul nuovo Gari Base grafico 34. Sviluppo del software effettuato a seguito appovazione documento proposta attività 1.2 | K16: Abaco
A17: 4 | C17: GARI - QDCA | G17: =SUM(G18:G26) -> 465108
A18: 4.1 | C18: QCDA-Re-ingegnerizzazione della piattaforma GIAS per implementare la nuova piattaforma GARI su nuove tecnologie ( i.e tecnologia Angular) | D18: Previsto da Progetto dei Fabbisogni | F18: Specifiche Progettazione RU-9992150707-QUAD-SP-02.00 | G18: 100000 | H18: Conduzione applicativa(Consumo) | I18: NECESSARI APPROFONDIMENTI PER AVVIO | J18: 35. Documento tecnico economico del nuovo Quaderno grafico 2025. In questo caso il documento di risposta alla scheda intervento QDCA DEVE essere già previsto tecnicamente e fuinzionalmente al'interno delGARI Grafico 2025. In questo caso il documento può essere nel capitolo dei servizi verticali speciaistici che si appogigano interoperano sul Gari Grafico Pipano Lavoro obiettivo del PUA 2025 36. approvazione realizzazione Regione 37. Attività di sviluppo del QDCA 2025 38. Stato avanzamento mensile lavoro 39. Gestione documenti previsti nel Repository, vale la regole del collaudo nel Repo dei documenti parten integrante del rilascio del prodotto 40. Predisposizioni Piani di formazione utenza dove previsto in accordo con uffici regionali 41. Pianificazione eventuali fermi servizio per aggiornamento release di servizio in esercizio | K18: Abaco
A19: 4.2 | C19: Sviluppo SW GARI - Misure ACA | D19: GARI Umbria Interventi ACA rev 01.00 ( ricevuta via pec del 04/03/2024) | E19: Piano Lavoro Obiettivo -GARI Umbria - Interventi ACA Rev.01.00 | F19: Documento di FASE UNICA RU-9992150707-ACA-FU-01.02 del 01/08/2024 | G19: 142608 | H19: Sviluppo software | I19: IN CORSO | J19: 42. Documenti tecnico economici prodotti e approvati novembre 2024 43. Attività di sviluppo in corso 43a. Definire con Regione le attività e le azioni amministrative da fare per entrare in possesso delle credenziali di acceso e d'uso dei dati delle centraline dei servizi idrometeo della Regione (Stelluti) e/o dei servizi irriframe attraverso Rti all'interno dei costi di Progetto 43b. Definire la configurazione dei servizi DSS del RTI (esterni alla Regione) per il collegamento alle centraline idrometeo 44. Rendcontazione attiivtà di ingegnerizzazione svolta nov/dic 2024 44a. predisposizioen dei verbali di collaudo attiivtà di rendicontazione nov/dic 2024 44.b. predisposizione dei documenti di prodotto allo stato dell'arte nel Rerpository necessari al collaudo, gestione degli stessi fino alla conclusione dell'attività (4.2) 45. predisposizione aggiornamento Piano di lavoro obiettivo per registri SQNPI 46. Pianificare attivazione in esercizio dei Registri SQNPI/BIO per attività CAA URGENTE 47. Piano di formazione dell'uso dei registri ai fini della documentazione impegni domande grafiche a premio 48. Verificare fermi di attiivtà sui registri in fase di sostituzione dei registri SQNPI adattati aCA verso l'lutenza e pianificare riattivazione e formazione di cui al punto 47. 49. Pianificare e effettuare l'attività di formazione/change mng al personale della Regione con definizione ed organizzazione servizi di Helop Desk di primo e secondo livello specialistici per la materia CSR/ACA, utilizzo dello strumento e errori, uso e interpretazione dei documenti e dei materiali/informazioni di archivi ed anagrafi da collegare agli adempimenti delle righe di registro | K19: Abaco
A20: 4.3 | C20: Sviluppo SW GARI - DSS per misure ACA | D20: GARI Umbria Interventi ACA rev 01.00 ( ricevuta via pec del 04/03/2024) | E20: Piano Lavoro Obiettivo - Gestione ACA DSS | F20: Documento di FASE UNICA RU-9992150707-ACA_DSS-FU-01.00 del 14/06/2024 | G20: 22500 | H20: Sviluppo software | I20: IN CORSO | J20: 50. Documenti tecnico economici prodotti e approvati novembre 2024 51. Attività di sviluppo in corso 52. Rendcontazione attiivtà di ingegnerizzazione svolta nov/dic 2024 52a.predisposizione dei verbali di collaudo attiivtà di rendicontazione nov/dic 2024 52b. predisposizione dei documenti di prodotto allo stato dell'arte nel Rerpository necessari al collaudo, gestione degli stessi fino alla conclusione dell'attività (4.3) 53. predisposizione aggiornamento Piano di lavoro obiettivo per i DSS 54. Pianificare attivazione in esercizio nei Registri SQNPI/BIO per l'ijterazione con il DSS 55. Piano di formazione dell'uso del servizio DSS 56. Pianificare e effettuare l'attività di formazione/change mng al personale della Regione con definizione ed organizzazione servizi di Helop Desk di primo e secondo livello specialistici per la materia DSS/fitiosanitaria, utilizzo dello strumento e errori, uso e interpretazione dei documenti e dei materiali/informazioni di archivi ed anagrafi da collegare agli adempimenti delle righe di registrontazione attiivtà di ingegnerizzazione svolta nov/dic 2024 57. Organizzazione e documentazione del servizio reso per la durata del contratto come assistenza RTI all'uso del servizio previsto dal Progetto (attiivtà 4.5 e .4.6) le attivitè a riguardo dovranno essere documentate come Servizi si assistenza e supporto alla fruizione dei dati DSS da parte delle Aziende, attraverso la produzione di registri delle prescrizioni e dei cosigli irrigui prodotti e rilasdciata negli archivi GAri previsti dall'attività 4.4 58. Valutare e correggere eventuali Servizi professionali presenti in questa sezioine nel PIano se introdurli come attività e costi nelle attività non si progettazione e documentarle con rendicontazione trimestrale nel Piano di esercizio. In questo caso va ripresentato un nuovo Piano Generale del lavoro. se resta come attività 4.5 e 4.6 invece deve essere comunque prodotto quanto previsto al punto 57. del presente PIano. | K20: Abaco
A21: 4.4 | C21: MEV - GARI QDCA - DSS - solo front-end (no algoritmi /API) + adeguamento salvataggio su GARI degli output relativi ai consigli dei Modelli Previsionali difesa e Irrigazione + Meteo (DSS) | D21: GARI Umbria Interventi ACA rev 01.00 ( ricevuta via pec del 04/03/2024) | E21: Piano Lavoro Obiettivo - Gestione ACA DSS | F21: Documento di FASE UNICA RU-9992150707-ACA_DSS-FU-01.00 del 14/06/2024 | G21: 60000 | H21: MEV | I21: IN CORSO | K21: Abaco
A22: 4.5 | C22: Acquisizione, raccordo e verifica dei dati Meteo/DSS da sorgenti esterne | D22: GARI Umbria Interventi ACA rev 01.00 ( ricevuta via pec del 04/03/2024) | F22: N.A. | G22: 15000 | H22: Conduzione applicativa(Consumo) | I22: IN CORSO | K22: Abaco
A23: 4.6 | C23: Acquisizione ,raccordo e verifica dei dati Meteo/DSS da sorgenti esterne | D23: GARI Umbria Interventi ACA rev 01.00 ( ricevuta via pec del 04/03/2024) | F23: N.A. | G23: 15000 | H23: Conduzione applicativa(Consumo) | I23: IN CORSO | K23: Abaco
A24: 4.7 | C24: Report ARPA: dati di impiego dei prodotti fitosanitari | D24: GARI Umbria - Intervento dati impiego fitosanitari - pec del 1/8/2024 | E24: Piano Lavoro Obiettivo - Report Fitosanitari | F24: Documento di FASE UNICA RU-9992150707-QUAD-Report_Fito-FU-01.00 del 28/08/2024 | G24: 10000 | H24: MEV | I24: IN CORSO | J24: 58. Documenti tecnico economici prodotti e approvati novembre 2024 58b. Piano di realizzazione del Servizio con indicazione del rilascioin esercizio 59. Attività di sviluppo 60. Rendcontazione attiivtà di ingegnerizzazione svolta nov/dic 2024 61. predisposizione dei documenti di prodotto allo stato dell'arte nel Rerpository necessari al collaudo, gestione degli stessi fino alla conclusione dell'attività 62. Piano di formazione utenza sull'uso del software di reportistica con rilascio manuale utente ad hoc. Ci sono utenti che non usano il GARI ma questo strumento 63. Colladuo del servizio e rilascio nel Gari esercizio | K24: Abaco
A25: 4.8 | C25: Revisione dei moduli QUADERNO SQNPI e BIO per essere utilizzabili e integrabili sulle nuove tecnologie introdotte con il paradigma PCG | D25: Previsto da Progetto dei Fabbisogni per quanto concerne il passaggio all'utilizzo del PCG. | F25: Documento in redazione | G25: 80000 | H25: MEV | I25: NECESSARI APPROFONDIMENTI PER AVVIO | J25: 64. Sezione descrittiva tecnica economica da inserire nel documento al punto 1. dell'attività codice 1.2 nella sezione del modello/servizi e tecnologie di interazione e cooperazione con il GARI BASE grafico 65. Predisposizione Piano di lavoro obiettivo della attività di rrevisione del servizio sul GARI BAse grafico o in alternativa produrre un piano lavoro ad hoc 66. Approvazione di Regione delle attività previa allocazione risorse da Residui di Progetto 2024 67. Esecuzione sviluppo software per integrazione nuove funzionalità 68. Produzione e Gestione documenti del prodotto realizzato nel Repository come previsto dal Progetto / Contratto 69. Piano di formazione dell'utenza per il nuovo servizio QDCA. Attività di formazione da calendario deve essere rendicontata nelle attività si supporto Non progettuali. 70. Definizione di un piano di test nella diffusione dell'uso dei servizi così moficati pressoi CAA qualificati e collaborativi secondo un modello di controllo e tutoraggio per verificare laqualità complessiva del servizio verso l'utenza rispetto alla usabilità di quello (quaderno) del SIAN 71. Collaudo finale con rilascio del servizio e controllo documentazione nel Repository. | K25: Abaco
A26: 4.9 | C26: Attivazione registri bio nel contesto del QDCA GARI, setting, configurazioni, profilazioni utenti, ecc. | D26: GARI Umbria Interventi ACA rev 01.00 ( ricevuta via pec del 04/03/2024) | E26: Piano Lavoro Obiettivo - Gestione SRA ACA | F26: Documento di FASE UNICA RU-9992150707-ACA-FU-01.02 del 01/08/2024 | G26: 20000 | H26: MEV | I26: IN CORSO | K26: Abaco
C27: ATTIVITA' DI CARATTERE CONTINUATIVO (NON PROGETTUALE) | G27: =SUM(G28,G32) -> 131352
A28: 5 | C28: SERVIZI DI SUPPORTO SPECIALISTICO APPLICATIVO | G28: =SUM(G29:G31) -> 96352
A29: 5.2 | C29: Supporto Specialistico 2025 | G29: =SUM(G30:G31) -> 48176
A30: 5.2.1 | C30: Supporto Specialistico - I TRIM 2025 | G30: 24088 | H30: Supp. Spec. App. (Consumo) | I30: PIANIFICATO | J30: A. Documento descrittivo delle attività in esercizio del GARI in cui è prevista l'attitivà di Assistenza e di supporto al Fornitore e la mauntenzione correttiva delGari. Nonché tutte le attività tecnico sistemistiche previste sull'ambiente applicativo cloud Umbria per il mantenimento a regione del GARI e per la manutenzione dell'Ambiente Test/collaudo B. Definizione di un format (documento) di rendicontazione trimestrale per tutto il tempo del progetto da gennaio 2025 relativo agli interventidi manutenzione delle piattaforme e degli RDBMS, di criticità affrontate e di interazioni aperte attraverso manutenzione diretta o su interlocuzione (chiamata/ticket) del primo livello, nonchè delle attività ti acquisizione e trssmissione dei dati verso il SIAN Bb. Descrizione attività di parametrizzazione, revisione e aggiornamento delle tabelle statiche a seguito di modifiche dei contenuti utilizzati dai menu di selezione dell'aplicativo a seguito di modifiche organizzative, di legge o di operatività del Gari richieste dalla Regione. analogamente per la gestione delle utenze (credenziali e profili) C. Documentazione dell'attività di formazione svolta con la presenza dei Piani di formazione e della rendicontazione dell'attività svolta con i giorni dedicati e gli argomenti trattati D. Documentazione attività di consulenza e di assistenza svolti verso il RUP, il DEC e i tavoli tematici con gli incontri tenuti e la documentazione prodotta. tutta la documentazione probante la nota prdotta deve essere inserita in una apposita sezione del Repository E. Rendicontazione dell'attiivtà di mautenzione aggiornamento della documentazione di Repository F. Rendicontazione dell'attività di gestione aggiornamento delle versioni di GARI presenti nell'ambiente di test/collaudo E7O repository. con dichiarazione di corretta manutenzione del prodotto attraverso gli interventi di risoluzione bug ed errori dell'applicativo poi trasferito in esercizio (menutenzione correttiva) | K30: Abaco | M30: 45658 | P30: 45747
A31: 5.2.2 | C31: Supporto Specialistico - II TRIM 2025 | G31: 24088 | H31: Supp. Spec. App. (Consumo) | I31: PIANIFICATO | K31: Abaco | M31: 45748 | P31: 45838
A32: 6 | C32: SERVIZI DI CALL CENTER | G32: =SUM(G33:G34) -> 35000
A33: 6.5 | C33: Servizi call center - I TRIM 2025 | G33: =35000/2 -> 17500 | H33: Servizi Desk(Canone) | I33: PIANIFICATO | K33: Leonardo | M33: 45658 | P33: 45747
A34: 6.6 | C34: Servizi call center - II TRIM 2025 | G34: =35000/2 -> 17500 | H34: Servizi Desk(Canone) | I34: PIANIFICATO | K34: Leonardo | M34: 45748 | P34: 45838

Sheet Valori per liste a discesa
C1: Stati | D1: Priorità | E1: Attori | F1: Referenti | G1: Tipologia attività | H1: Servizio
C2: PIANIFICATO | D2: 1-Alta | G2: Progettuale | H2: Supporto Specialistico (a consumo)
C3: IN CORSO | D3: 2-Media | G3: Continuativa
C4: COMPLETATO | D4: 3-Bassa
C5: CANCELLATO
C6: DA RIPIANIFICARE
C7: NECESSARI APPROFONDIMENTI PER AVVIO
C8: DA PIANIFICARE
C9: DA AVVIARE
C10: RILASCIATO IN COLLAUDO
C11: ESITO POSITIVO AL COLLAUDO
C12: RILASCIATO IN ESERCIZIO

Sheet Settore
A1: CODICE PIANO LDCSIN / CODICE COMPUTO | B1: denominazione Piano / descrizione computo
A2: 001 | B2: Fascicolo Aziendale OC
A3: 002 | B3: Fascicolo Aziendale OP
A4: 003 | B4: Condizionalità (SICC - Sistema integrato di controllo e condizionalità)
A5: 006 | B5: Miele
A6: 007 | B6: Domanda Unica
A7: 008 | B7: Tabacco
A8: 009 | B8: Latte
A9: 010 | B9: Aiuti nazionali filiere zootecniche
A10: 011 | B10: Ortofrutta fresca (programmi operativi)
A11: 012 | B11: PIANO PER LA RIGENERAZIONE OLIVICOLA DELLA PUGLIA DM 2484/2020 -INTERVENTI COMPENSATIVI A FAVORE DEI FRANTOI OLEARI
A12: 014 | B12: Registro titoli
... A89: CODICE PIANO LDCSIN / CODICE COMPUTO | B89: SETTORI AGGIUNTI

Sheet Legende
A1: PIANIFICATO
A2: IN CORSO
A3: COMPLETATO
A4: CANCELLATO
A5: NECESSARI APPROFONDIMENTI PER L'AVVIO
A6: RIPIANIFICATA
A10: Sviluppo software
A11: MEV
A12: Conduzione applicativa(Consumo)
A13: Supp. Spec. App. (Consumo)
A14: Servizi Desk(Canone)
A17: III TRIMESTRE 2023
... A26: IV TRIMESTRE 2025
